Workbook
Name ClearData: Key_Stats!$K$28:$M$52
Name FormatTable: Key_Stats!$U$15:$W$17
Name IQ_CH: 110000
Name IQ_CQ: 5000
Name IQ_CY: 10000
Name IQ_DAILY: 500000
Name IQ_FH: 100000
Name IQ_FQ: 500
Name IQ_FY: 1000
Name IQ_LTM: 2000
Name IQ_MONTH: 15000
Name IQ_NTM: 6000
Name IQ_WEEK: 50000
Name IQ_YTD: 3000
Name KI: IF(Key_Stats!$L$25="",Key_Stats!$E$25:$K$25,Key_Stats!$E$25:$M$25)
Name SKF: IF(Key_Stats!$L$26="",Key_Stats!$E$26:$K$26,Key_Stats!$E$26:$M$26)

Sheet __snloffice
A1: 允䅁䱁䤰䅁㡂䅁䅁睊扂䕁䄰兓時䕁䅍睢瑂䡁䅁兙畂䡁䅫睘䱂䝁䅕入呂䡁䅑兙あ䡁䅍睘㉂䑁䅅兌䑂䝁䄸䅣㕂䍁䄴䅥獂䡁䅍兢摂䕁䅉兙獂䝁䅅杢橂䝁䅕睘呂䝁䅧党求䡁䅑睊桁䍁䅑睑歁䑁䅫杏歁䕁䅍䅊硁䑁䅍兏䅁䡁䙯䅁䕃䅁䅁睊扂䕁䄰兓時䕁䅍睢瑂䡁䅁兙畂䡁䅫睘䱂䝁䅕入呂䡁䅑兙あ䡁䅍睘㉂䑁䅅䅉潁䑁䅍克畁䡁䅧䅢穂䝁䄰兘䑂䝁䅅䅣灂䡁䅑兙獂䙁䄸睕あ䡁䅉兤橂䡁䅑兤祂䝁䅕睘呂䡁䅕兢瑂䝁䅅杣㕂䍁䅣光歁䕁䅍䅊ぁ䅁䅁杙䅑䡁䅉䅁湁䙁䅳兔䩂䙁䄸睑療䝁䄰䅣桂䝁䄴入時䕁䅳党㕂䙁䅍䅤桂䡁䅑督時䡁䅙免瑁䍁䅁睔祂䝁䅫睚灂䝁䄴兙獂䍁䄴䅥獂䡁䅍兢摂䕁䅳党㕂䙁䄸睕あ䝁䅅䅤穂䍁䅣光歁䕁䅉䅊祁䑁䅍䅁捂兂䅁䅤䅁䙁䅳兔䩂䙁䄸睑療䝁䄰䅣桂䝁䄴入時䕁䅳党㕂䙁䅍䅤桂䡁䅑督時䡁䅙免時䍁䄴䅥獂䡁䅍兢摂䕁䅉兙獂䝁䅅杢橂䝁䅕睘呂䝁䅧党求䡁䅑光歁䕁䅕䅊硁䑁䅑䅎㙁䍁䅑䅕歁䑁䅅䅎ぁ䅁䅁䄴䅑䑁䅙䅁乂䝁䅅杣牂䝁䅕䅤杁䕁䅍兙睂䝁䅫䅤桂䝁䅷兡㙂䝁䅅䅤灂䝁䄸杢杁䍁䅧䅊乂䍁䅫䅁牃兂䅁䅤䅁䍁䅣睗乂䕁䅫睘䑂䝁䄸兢睂䝁䅅杢㕂䙁䄸睓求䡁䅫睕あ䝁䅅䅤穂䙁䄸杤硁䍁䄰睑療䡁䅁入畁䡁䅧䅢穂䝁䄰兘䱂䝁䅕入時䙁䅍䅤桂䡁䅑督湁䍁䅅䅊䕂䍁䅑杍㑁䑁䅯䅊䕂䍁䅑兎祁䅁䅁杉䅕䍁䅑䅁䩂䙁䅅睘佂䕁䅫睘佂䕁䄸杕乂䙁䄸兔䉂䙁䅉睒䩂䕁䄴䅁偁杁䅁杣䅁䙁䅳睕兂䕁䅣睘䑂䝁䄸兢睂䝁䅅杢㕂䙁䄸睓求䡁䅫睕あ䝁䅅䅤穂䙁䄸杤硁䍁䄴䅥獂䡁䅍兢摂䕁䅫杢橂䝁䄸兢求䙁䄸睕あ䝁䅅䅤求䝁䄰党畂䡁䅑光歁䕁䅕䅊㉁䑁䅯䅊兂䍁䅑李䅁佁䙕䅁浂䅁䅁睊扂䕁䅳党㕂䙁䅍䅤桂䡁䅑督時䡁䅑党穂䡁䅑杚灂䝁䅷党畁䡁䅧䅢穂䝁䄰兘兂䝁䅕杢穂䝁䅫睢畂䍁䄰睔兂䕁䅕村湁䍁䅅䅊䕂䍁䅑兏㙁䍁䅑䅒歁䑁䅅䅎㕁䅁䅁杵䅉䝁䅯䅁湁䙁䅳睕兂䕁䅣睘䑂䝁䄸兢睂䝁䅅杢㕂䙁䄸睓求䡁䅫睕あ䝁䅅䅤穂䙁䄸杤硁䍁䅁䅋祁䍁䅫杌㑂䝁䅷督瑂䙁䄰杕桂䡁䅑兡療䡁䅍睊桁䍁䅑䅒歁䑁䅙杏歁䕁䅫䅊㉁䅁䅁兒䅙䙁䅷䅁扂䕁䅳党㕂䙁䅍䅤桂䡁䅑督時䡁䅑党穂䡁䅑杚灂䝁䅷党畁䡁䅧䅢穂䝁䄰兘䱂䝁䅕入時䙁䅍䅤桂䡁䅑督桁䍁䅑睑歁䑁䅕䅎㙁䍁䅑睑歁䑁䅕兎䅁乁䅧䅁奂䅁䅁睊扂䕁䅳党㕂䙁䅍䅤桂䡁䅑督時䡁䅑党穂䡁䅑杚灂䝁䅷党畁䡁䅧䅢穂䝁䄰兘兂䝁䅕杢穂䝁䅫睢畂䍁䄰睔兂䕁䅕村湁䍁䅅䅊䑂䍁䅑䅎䅁䱁䍧䅁坂䅁䅁睗呂䙁䅁睒時䕁䅍睢瑂䡁䅁兙畂䡁䅫睘䱂䝁䅕入呂䡁䅑兙あ䡁䅍睘㉂䑁䅉杌㑂䝁䅷督瑂䙁䄰睕潂䝁䅕党あ䑁䅅光歁䕁䅳䅊硁䑁䅅䅁橃杂䅁来䅁䙁䅳睕兂䕁䅣睘䑂䝁䄸兢睂䝁䅅杢㕂䙁䄸睓求䡁䅫睕あ䝁䅅䅤穂䙁䄸杤硁䍁䄴䅥獂䡁䅍兢摂䕁䅍兙睂䝁䅫䅤桂䝁䅷睘呂䡁䅑杣ㅂ䝁䅍䅤ㅂ䡁䅉党時䙁䅍兤瑂䝁䄰兙祂䡁䅫光歁䕁䅍䅊㉁䅁䅁䄯䅕䑁䅧䅁䩂䙁䅅睘啂䕁䄸䅖䉂䕁䅷睘塂䕁䅅杕卂䕁䅅杔啂䙁䅍睘䑂䕁䅅杔䑂䕁䅕䅔䵂䕁䅕䅒䅁䕁䑑䅁睂䅁䅁睊扂䕁䄰兓時䕁䅍睢瑂䡁䅁兙畂䡁䅫睘䱂䝁䅕入呂䡁䅑兙あ䡁䅍睘㉂䑁䅅䅉潁䑁䅍克畁䡁䅧䅢穂䝁䄰兘䑂䝁䅅䅣灂䡁䅑兙獂䝁䅫来桂䡁䅑兡療䝁䄴睊桁䍁䅑睑歁䑁䅑睎䅁䙁䔴䅁煂䅁䅁睑ㅂ䡁䅉杣求䝁䄴䅤杁䕁䅷睢畂䝁䅣䅉啂䝁䅕杣瑂䍁䅁䅒求䝁䅉䅤杁䝁䅅杢歂䍁䅁睑桂䡁䅁兡あ䝁䅅䅢杁䕁䅷党桂䡁䅍党穂䍁䅁䅋卂䝁䅕䅣療䡁䅉䅤求䝁䅑克䅁䍁䈰䅁䝂䅁䅁䅒求䝁䅙党祂䡁䅉党歂䍁䅁䅒療䝁䄰党穂䡁䅑兡橂䍁䅁䅖桂䡁䅧党穂䍁䅁䅋卂䝁䅕䅣療䡁䅉䅤求䝁䅑克䅁䥁䐴䅁潁䅁䅁睉䩂䕁䄴杖䉂䕁䅷兓䕂䍁䅁睑偂䕁䄰䅕䉂䕁䄴兗杁䕁䅫䅒䅁䥁䝕䅁祂䅁䅁睊扂䕁䄰兓時䕁䅍睢瑂䡁䅁兙畂䡁䅫睘䱂䝁䅕入呂䡁䅑兙あ䡁䅍睘㉂䑁䅅兌䑂䝁䄸䅣㕂䍁䄴䅥獂䡁䅍兢摂䕁䅍兙穂䝁䅧睘䝂䝁䅷睢㍂䍁䅣光歁䕁䅍䅊㕁䑁䅯䅊䑂䍁䅑兏睁䅁䅁杦䅕䝁䅁䅁扂䙁䅍䅕䡂䙁䄸睑療䝁䄰䅣桂䝁䄴入時䕁䅳党㕂䙁䅍䅤桂䡁䅑督時䡁䅙杍畁䡁䅧䅢穂䝁䄰兘呂䡁䅕䅣睂䝁䅷党瑂䝁䅕杢あ䝁䅅䅢桁䍁䅑睑歁䑁䅙䅁佁䅃䅁䅎䅁䕁䅫兕時䕁䅷䅖時䕁䅑兒䍂䙁䅑睘䑂䕁䅅䅕䩂䙁䅑兑䵂䙁䄸䅔䙂䕁䅅睕䙂䙁䅍䅁畁允䅁杦䅁䍁䅣睗乂䕁䅫睘䑂䝁䄸兢睂䝁䅅杢㕂䙁䄸睓求䡁䅫睕あ䝁䅅䅤穂䙁䄸杤硁䍁䄰䅉偂䡁䅉兡湂䝁䅫杢桂䝁䅷杌㑂䝁䅷督瑂䙁䄰睓求䡁䅫睘呂䡁䅑兙あ䡁䅍睊桁䍁䅑兒歁䑁䅉杍㙁䍁䅑䅔歁䑁䅉杍䅁䝁䙧䅁畂䅁䅁睗乂䕁䅫睘䑂䝁䄸兢睂䝁䅅杢㕂䙁䄸睓求䡁䅫睕あ䝁䅅䅤穂䙁䄸杤硁䙁䄸杌㑂䝁䅷督瑂䙁䄰睑桂䡁䅁兡あ䝁䅅䅢灂䡁䅯兙あ䝁䅫睢畂䍁䅅䅊䙂䍁䅑䅎㙁䍁䅑杓歁䑁䅑䅁浄䅂䅁杁䅁䅁䅁光䅁䥁䅧䅁湁䙁䅳睕兂䕁䅣睘䑂䝁䄸兢睂䝁䅅杢㕂䙁䄸睓求䡁䅫睕あ䝁䅅䅤穂䙁䄸杤祁䍁䅁免畁䡁䅧䅢穂䝁䄰兘䑂䝁䅅䅣灂䡁䅑兙獂䙁䄸睕あ䡁䅉兤橂䡁䅑兤祂䝁䅕睘杁䕁䅑党あ䝁䅅兡獂䡁䅍䅉湁䍁䅅䅊䑂䍁䅑睎㉁䅁䅁兆䅣䝁䅁䅁扂䕁䅳党㕂䙁䅍䅤桂䡁䅑督時䡁䅑党穂䡁䅑杚灂䝁䅷党畁䡁䅧䅢穂䝁䄰兘䱂䝁䅕入時䙁䅍䅤桂䡁䅑督桁䍁䅑兒歁䑁䅅䅍睁䑁䅯䅊䡂䍁䅑免睁䑁䅁䅁牄䅁䅁䅨䅁䍁䅣睗呂䙁䅁睒時䕁䅍睢瑂䡁䅁兙畂䡁䅫睘䱂䝁䅕入呂䡁䅑兙あ䡁䅍睘㉂䑁䅉杌㑂䝁䅷督瑂䙁䄰睑桂䡁䅁兡あ䝁䅅䅢時䙁䅍䅤祂䡁䅕睙あ䡁䅕杣求䙁䄸䅉䕂䝁䅕䅤桂䝁䅫䅢穂䍁䅁睊桁䍁䅑䅓歁䑁䅅杍䅁䍁䥉䅁佁䅁䅁睉䙂䙁䅉杕偂䙁䅉䅁呄䅁䅁杆䅁䕁䅫兕時䙁䅁兒時䕁䄴睔卂䕁䄰䅁噂杂䅁䅚䅁䕁䄸䅣あ䝁䅫睢畂䡁䅍䅉䡂䡁䅉兙畂䡁䅑党歂䍁䅁䅒ㅂ䡁䅉兡畂䝁䅣䅉あ䝁䅧党杁䙁䅁党祂䝁䅫睢歂䍁䅷䅉啂䝁䄸䅤桂䝁䅷䅉潁䝁䅅睙あ䡁䅕兙獂䍁䅫䅁䉂睁䅁杋䅁䍁䅍兓佂䙁䅙兑䵂䕁䅫䅒杁䕁䄰兒啂䙁䅉兓䑂䍁䅁杔䉂䕁䄰兒䅁䡁䝳䅁㉁䅁䅁兓剂䙁䄸睕䙂䕁䅍睔佂䕁䅑睘䵂䕁䅫兒佂䙁䄸村偂䕁䄴䅒呂䙁䄸杔偂䙁䅑兒呂䅁䅁䅒䅅䍁䅙䅁䵂䙁䅑䅉䕂䝁䅕杙あ䍁䄸兒硂䡁䅕兡あ䡁䅫䅉潁䍁䅕克䅁䱁䍕䅁獁䅁䅁睑䩂䙁䅅䅉卂䝁䅕督あ䝁䅅䅤求䝁䄰党畂䡁䅑䅉啂䡁䅫䅣求䍁䅁䅁牁睁䅁䅪䅁䍁䅣睗䑂䝁䄸䅣㕂䍁䅁睢浂䍁䅁睕兂䕁䅣睘䑂䝁䄸兢睂䝁䅅杢㕂䙁䄸睓求䡁䅫睕あ䝁䅅䅤穂䙁䄸杤硁䙁䄸杒灂䝁䄴兙獂䍁䄴䅥獂䡁䅍兢摂䕁䅉兙獂䝁䅅杢橂䝁䅕睘呂䝁䅧党求䡁䅑睊桁䍁䅑兒歁䑁䅙杏歁䙁䅅䅊㉁䅁䅁䅘䅧䙁䅙䅁扂䕁䅳党㕂䙁䅍䅤桂䡁䅑督時䡁䅑党穂䡁䅑杚灂䝁䅷党畁䡁䅧䅢穂䡁䅧兘呂䝁䅧党求䡁䅑免桁䍁䅑兒歁䑁䅉免㙁䍁䅑睒歁䑁䅉免䅁䑁䅍䅁㑁䅁䅁睉䩂䕁䄴杖䉂䕁䅷兓䕂䍁䅁杒噂䕁䄴睑啂䕁䅫睔佂䍁䅁䅕䉂䙁䅉兑乂䕁䅕䅖䙂䙁䅉䅁牂杂䅁䅑䅁䙁䅑睢あ䝁䅅䅢杁䙁䅍兤楂䍁䄴䅉䕂䝁䅕杙あ䍁䄸䅉啂䝁䄸䅤桂䝁䅷䅉䕂䝁䅕杙あ䍁䅁䅋汁䍁䅫䅁橁允䅁䅧䅁䍁䅣睗䑂䝁䄸䅣㕂䍁䅁睢浂䍁䅁睕兂䕁䅣睘䑂䝁䄸兢睂䝁䅅杢㕂䙁䄸睓求䡁䅫睕あ䝁䅅䅤穂䙁䄸杤祁䙁䄸杢求䡁䅣杌㑂䝁䅷督瑂䙁䄰睑桂䡁䅍䅡時䕁䅙䅢療䡁䅣睊桁䍁䅑兒歁䑁䅙杏歁䙁䅁䅊㉁䅁䅁睒䅣䡁䅑䅁湁䙁䅳睕兂䕁䅣睘䑂䝁䄸兢睂䝁䅅杢㕂䙁䄸睓求䡁䅫睕あ䝁䅅䅤穂䙁䄸杤硁䍁䅁䅋祁䍁䅫杌㑂䝁䅷督瑂䙁䄰兓畂䝁䅍睢瑂䝁䅕睘呂䡁䅑兙あ䝁䅕兢求䝁䄴䅤湁䍁䅅䅊䑂䍁䅑李䅁䍁䝑䅁潁䅁䅁兓剂䙁䄸睕䙂䕁䅍兖卂䕁䅕䅒時䕁䅑兒䍂䙁䅑睘兂䕁䅍䅖䅁䙁䉷䅁⭂䅁䅁睊扂䙁䅍䅕䡂䙁䄸睑療䝁䄰䅣桂䝁䄴入時䕁䅳党㕂䙁䅍䅤桂䡁䅑督時䡁䅙免杁䍁䅧杍灁䍁䄴䅥獂䡁䅍兢摂䕁䅍兙睂䝁䅫䅤桂䝁䅷兡㙂䝁䅅䅤灂䝁䄸杢湁䍁䅅䅊䑂䍁䅑兎穁䑁䅯䅊䑂䍁䅑兎ぁ䅁䅁李䅙䕁䅑䅁啂䝁䄸䅤桂䝁䅷䅉卂䝁䅕杤求䝁䄴兤求䡁䅍䅌杁䑁䅅䅉婂䝁䅕兙祂䍁䅁睒祂䝁䄸睤あ䝁䅧䅉潁䍁䅕克䅁䅁䅑䅁捂䅁䅁睊扂䕁䄰兓時䕁䅳党㕂䙁䅍䅤桂䡁䅑督時䡁䅙免畁䡁䅧䅢穂䝁䄰兘兂䝁䅕杢穂䝁䅫睢畂䍁䄰睔兂䕁䅕村湁䍁䅅䅊䕂䍁䅑䅎㙁䍁䅑兓歁䑁䅑䅁ㅃ睁䅁杙䅁䙁䅳兔䩂䙁䄸睑療䝁䄰䅣桂䝁䄴入時䕁䅳党㕂䙁䅍䅤桂䡁䅑督時䡁䅙免時䍁䄴䅥獂䡁䅍兢摂䙁䅉兙あ䝁䅫睢穂䍁䅅䅊䑂䍁䅑兏㙁䍁䅑睑歁䑁䅅兎睁䅁䅁眫䅑䅁䅷䅁橁䙁䅁兒佂䕁䅑䅁桄睁䅁杦䅁䍁䅣睗乂䕁䅫睘䑂䝁䄸兢睂䝁䅅杢㕂䙁䄸睓求䡁䅫睕あ䝁䅅䅤穂䙁䄸杤硁䍁䄰睑療䡁䅁入畁䡁䅧䅢穂䝁䄰兘䩂䝁䄴睙療䝁䄰党時䙁䅍䅤桂䡁䅑党瑂䝁䅕杢あ䍁䅣光歁䕁䅕䅊ぁ䑁䅯䅊兂䍁䅑䅎䅁䕁䘸䅁楂䅁䅁睊扂䕁䅳党㕂䙁䅍䅤桂䡁䅑督時䡁䅑党穂䡁䅑杚灂䝁䅷党畁䡁䅧䅢穂䝁䄰兘兂䝁䅕杢穂䝁䅫睢畂䍁䄰睔兂䕁䅕村湁䍁䅅䅊䝂䍁䅑兎㙁䍁䅑睓歁䑁䅕䅁㝃杁䅁杚䅁䍁䅣睗䱂䝁䅕入呂䡁䅑兙あ䡁䅍睘あ䝁䅕督あ䝁䅙兡獂䝁䅕杌㑂䝁䅷督瑂䙁䄰䅕求䝁䄴督灂䝁䄸杢瑁䕁䄸䅕䙂䕁䅉睊桁䍁䅑䅒歁䑁䅫杏歁䕁䅑䅊ㅁ䑁䅙睎䅁䝁䑍䅁啁䅁䅁兓剂䙁䄸䅕䙂䙁䄸䅔啂䕁䄰䅁䥄睂䅁䅦䅁䍁䅣睗乂䕁䅫睘䑂䝁䄸兢睂䝁䅅杢㕂䙁䄸睓求䡁䅫睕あ䝁䅅䅤穂䙁䄸杤硁䍁䅁䅋穁䍁䅫杌㑂䝁䅷督瑂䙁䄰睑桂䡁䅁兡あ䝁䅅䅢灂䡁䅯兙あ䝁䅫睢畂䍁䅣光歁䕁䅕䅊ぁ䑁䅣杏歁䙁䅁䅊ぁ䑁䅣䅁扂䅂䅁村䅁䕁䄴睢祂䝁䄰兙獂䝁䅫来求䝁䅑䅉佂䝁䅕䅤杁䕁䅫杢橂䝁䄸兢求䍁䅁兔桂䡁䅉睚灂䝁䄴䅉潁䍁䅕克䅁䉁䍁䅁潂䅁䅁睗呂䙁䅁睒時䕁䅍睢瑂䡁䅁兙畂䡁䅫睘䱂䝁䅕入呂䡁䅑兙あ䡁䅍睘㉂䑁䅅杌㑂䝁䅷督瑂䙁䄰睓求䡁䅫睘呂䡁䅑兙あ䡁䅍光歁䙁䅍䅊ㅁ䑁䅧杏歁䙁䅍䅊㉁䑁䅅䅁桄兂䅁䅃䅁䕁䅙兗睁䅁䅁䅄䅁䕁䅑䅁啂䝁䄸䅤桂䝁䅷䅉呂䝁䅕杢灂䝁䄸杣杁䕁䅑党楂䡁䅑睌杁䙁䅑睢あ䝁䅅䅢杁䕁䅑党楂䡁䅑䅉潁䍁䅕克䅁䉁䈸䅁浂䅁䅁睊扂䕁䅳党㕂䙁䅍䅤桂䡁䅑督時䡁䅑党穂䡁䅑杚灂䝁䅷党畁䡁䅧䅢穂䝁䄰兘兂䝁䅕杢穂䝁䅫睢畂䍁䄰睔兂䕁䅕村湁䍁䅅䅊䕂䍁䅑兏㙁䍁䅑䅒歁䑁䅕李㑁䅁䅁䅚䅍䝁䅉䅁湁䙁䅳睓求䡁䅫睕あ䝁䅅䅤穂䙁䄸䅤求䡁䅍䅤浂䝁䅫䅢求䍁䄴䅥獂䡁䅍兢摂䙁䅁党畂䡁䅍兡療䝁䄴兌偂䙁䅁兒䍂䍁䅣光歁䕁䅙䅊ぁ䑁䅯䅊䱂䍁䅑䅎䅁䱁䍫䅁獂䅁䅁睊扂䙁䅍䅕䡂䙁䄸睑療䝁䄰䅣桂䝁䄴入時䕁䅳党㕂䙁䅍䅤桂䡁䅑督時䡁䅙杍杁䑁䅅杌㑂䝁䅷督瑂䙁䄰杕桂䡁䅑兡療䡁䅍睊桁䍁䅑睑歁䑁䅅免㙁䍁䅑睑歁䑁䅅兎㑁䅁䅁儫䅙䡁䅙䅁湁䙁䅳兔䩂䙁䄸睑療䝁䄰䅣桂䝁䄴入時䕁䅳党㕂䙁䅍䅤桂䡁䅑督時䡁䅙免杁䍁䅧睍灁䍁䄴䅥獂䡁䅍兢摂䕁䅉兙獂䝁䅅杢橂䝁䅕睘呂䝁䅧党求䡁䅑睊桁䍁䅑兒歁䑁䅕杏歁䙁䅁䅊ㅁ䅁䅁兕䅑䥁䅧䅁湁䙁䅳睑療䡁䅁入杁䝁䄸杚杁䙁䅍䅕䡂䙁䄸睑療䝁䄰䅣桂䝁䄴入時䕁䅳党㕂䙁䅍䅤桂䡁䅑督時䡁䅙免時䕁䅙兡畂䝁䅅䅢畁䡁䅧䅢穂䝁䄰兘䩂䝁䄴睙療䝁䄰党時䙁䅍䅤桂䡁䅑党瑂䝁䅕杢あ䍁䅣光歁䕁䅍䅊㉁䅁䅁睖䅧䕁䅙䅁䩂䙁䅅睘䝂䕁䅅兓卂䙁䄸杖䉂䕁䅷兖䙂䙁䄸睑䥂䕁䅅杔䡂䕁䅕睘䩂䕁䄴睑䵂䙁䄸兒䉂䙁䅉杔䩂䕁䄴睒呂䅁䅁䅋䅍䡁䅧䅁䩂䝁䄴䅤求䡁䅉党穂䡁䅑䅉桂䝁䄴䅚杁䙁䅁党畂䝁䅅䅢あ䝁䅫党穂䍁䅁杕求䝁䅍睢湂䍁䄴䅉療䝁䄴䅉䍂䙁䅍䅉瑁䍁䅁村求䝁䅙睢祂䝁䅕䅉啂䝁䅅䅥杁䍁䅧杕求䡁䅁睢祂䡁䅑党歂䍁䅫䅁呁睁䅁䅦䅁䍁䅣睗䑂䝁䄸䅣㕂䍁䅁睢浂䍁䅁睕兂䕁䅣睘䑂䝁䄸兢睂䝁䅅杢㕂䙁䄸睓求䡁䅫睕あ䝁䅅䅤穂䙁䄸杤硁䙁䄸杒灂䝁䄴兙獂䍁䄴䅥獂䡁䅍兢摂䕁䅳党㕂䙁䄸睕あ䝁䅅䅤穂䍁䅣光歁䕁䅉䅊祁䑁䅕䅁䉂䅃䅁杣䅁䍁䅣睗乂䕁䅫睘䑂䝁䄸兢睂䝁䅅杢㕂䙁䄸睓求䡁䅫睕あ䝁䅅䅤穂䙁䄸杤硁䍁䅁䅋穁䍁䅫杌㑂䝁䅷督瑂䙁䄰睓求䡁䅫睘呂䡁䅑兙あ䡁䅍睊桁䍁䅑睑歁䑁䅉兎㙁䍁䅑睑歁䑁䅑兏䅁䑁䕉䅁煁䅁䅁兓剂䙁䄸杔䩂䙁䄸免婂䙁䅉睘䉂䕁䄴杔時䕁䅣杕偂䙁䅣䅖䥂䅁䅁先䅉䥁䄴䅁湁䙁䅳睑療䡁䅁入杁䝁䄸杚杁䙁䅍䅕䡂䙁䄸睑療䝁䄰䅣桂䝁䄴入時䕁䅳党㕂䙁䅍䅤桂䡁䅑督時䡁䅙杍時䝁䄴党㍂䍁䄴䅥獂䡁䅍兢摂䕁䅫杢橂䝁䄸兢求䙁䄸睕あ䝁䅅䅤求䝁䄰党畂䡁䅑睊桁䍁䅑兒歁䑁䅣杏歁䙁䅅䅊㍁䅁䅁兰䅣䝁䅑䅁湁䙁䅳睕兂䕁䅣睘䑂䝁䄸兢睂䝁䅅杢㕂䙁䄸睓求䡁䅫睕あ䝁䅅䅤穂䙁䄸杤祁䍁䅁免畁䡁䅧䅢穂䝁䄰兘䱂䝁䅕入時䙁䅍䅤桂䡁䅑督湁䍁䅅䅊䙂䍁䅑李穁䅁䅁朰䅙䡁䅉䅁湁䙁䅳兔䩂䙁䄸睑療䝁䄰䅣桂䝁䄴入時䕁䅳党㕂䙁䅍䅤桂䡁䅑督時䡁䅙免瑁䕁䅍睢睂䡁䅫杌㑂䝁䅷督瑂䙁䄰睑桂䡁䅁兡あ䝁䅅䅢灂䡁䅯兙あ䝁䅫睢畂䍁䅣光歁䕁䅍䅊ㅁ䑁䅫䅁䝂兂䅁䅚䅁䙁䅳兔䩂䙁䄸睑療䝁䄰䅣桂䝁䄴入時䕁䅳党㕂䙁䅍䅤桂䡁䅑督時䡁䅙免畁䡁䅧䅢穂䝁䄰兘䑂䝁䅅䅣灂䡁䅑兙獂䝁䅫来桂䡁䅑兡療䝁䄴光歁䕁䅍䅊ぁ䑁䅧䅁啁䅂䅁䅢䅁䍁䅣睗乂䕁䅫睘䑂䝁䄸兢睂䝁䅅杢㕂䙁䄸睓求䡁䅫睕あ䝁䅅䅤穂䙁䄸杤硁䍁䅁䅋穁䍁䅫杌㑂䝁䅷督瑂䙁䄰村桂䝁䅷兙畂䝁䅍党時䙁䅍䅡求䝁䅕䅤湁䍁䅅䅊䑂䍁䅑䅎䅁䕁䔴䅁歂䅁䅁睗乂䕁䅫睘䑂䝁䄸兢睂䝁䅅杢㕂䙁䄸睓求䡁䅫睕あ䝁䅅䅤穂䙁䄸杤硁䍁䄴䅥獂䡁䅍兢摂䕁䅍兙睂䝁䅫䅤桂䝁䅷兡㙂䝁䅅䅤灂䝁䄸杢桁䍁䅑睑歁䑁䅑睎䅁䉁䕧䅁䕃䅁䅁睊扂䕁䅍睢睂䡁䅫䅉療䝁䅙䅉呂䙁䅁睒時䕁䅍睢瑂䡁䅁兙畂䡁䅫睘䱂䝁䅕入呂䡁䅑兙あ䡁䅍睘㉂䑁䅅睘䝂䝁䅫杢桂䝁䅷杌㑂䝁䅷督瑂䙁䄰睑桂䡁䅁兡あ䝁䅅䅢灂䡁䅯兙あ䝁䅫睢畂䍁䅣光歁䕁䅍䅊ぁ䅁䅁睙䅧䕁䅯䅁䑂䝁䅅䅣畁䍁䅁䅔求䝁䅅督求䍁䅁䅕桂䡁䅫兢求䝁䄴䅤杁䕁䅑兤求䍁䅁睋穁䍁䅁䅋卂䝁䅕䅣療䡁䅉䅤求䝁䅑克䅁䭁䈴䅁㙂䅁䅁睊扂䕁䄰兓時䕁䅍睢瑂䡁䅁兙畂䡁䅫睘䱂䝁䅕入呂䡁䅑兙あ䡁䅍睘㉂䑁䅅䅉潁䑁䅍克畁䡁䅧䅢穂䝁䄰兘䍂䝁䅅䅢桂䝁䄴睙求䙁䄸睕潂䝁䅕党あ䍁䅣光歁䕁䅍䅊㕁䑁䅯䅊䑂䍁䅑免穁䑁䅫䅁兂䅂䅁杤䅁䍁䅣睗乂䕁䅫睘䑂䝁䄸兢睂䝁䅅杢㕂䙁䄸睓求䡁䅫睕あ䝁䅅䅤穂䙁䄸杤硁䍁䅁䅋穁䍁䅫杌㑂䝁䅷督瑂䙁䄰睓求䡁䅫睘呂䡁䅑兙あ䡁䅍睊桁䍁䅑兒歁䑁䅅䅍ぁ䑁䅯䅊䡂䍁䅑免睁䑁䅑䅁䩂䅂䅁杖䅁䙁䅳睓求䡁䅫睕あ䝁䅅䅤穂䙁䄸䅤求䡁䅍䅤浂䝁䅫䅢求䍁䄴䅥獂䡁䅍䅥摂䙁䅍䅡求䝁䅕䅤硁䍁䅅䅊䭂䍁䅑杍祁䑁䅯䅊䵂䍁䅑杍祁䅁䅁杓䅁䍁䅯䅁䩂䙁䅅睘呂䙁䅕村時䕁䅷兒䉂䙁䅍兒時䕁䅫杔䑂䙁䄸睑婂䑁䅅䅁䡄允䅁杤䅁䍁䅣睗乂䕁䅫睘䑂䝁䄸兢睂䝁䅅杢㕂䙁䄸睓求䡁䅫睕あ䝁䅅䅤穂䙁䄸杤硁䍁䅁䅋穁䍁䅫杌㑂䝁䅷督瑂䙁䄰村桂䝁䅷兙畂䝁䅍党時䙁䅍䅡求䝁䅕䅤湁䍁䅅䅊䙂䍁䅑䅎㙁䍁䅑䅕歁䑁䅑䅁偂䅂䅁杣䅁䍁䅣睗呂䙁䅁睒時䕁䅍睢瑂䡁䅁兙畂䡁䅫睘䱂䝁䅕入呂䡁䅑兙あ䡁䅍睘㉂䑁䅉䅉硁䍁䄴䅥獂䡁䅍兢摂䙁䅍兤睂䡁䅁䅢求䝁䄰党畂䡁䅑兙獂䍁䅣光歁䕁䅑䅊㉁䑁䅯䅊䩂䍁䅑李䅁偁䝷䅁啃䅁䅁睊扂䕁䄰兓時䕁䅍睢瑂䡁䅁兙畂䡁䅫睘䱂䝁䅕入呂䡁䅑兙あ䡁䅍睘㉂䑁䅅䅉潁䑁䅍克畁䡁䅧䅢穂䝁䄰兘䑂䝁䅅䅣灂䡁䅑兙獂䙁䄸睕あ䡁䅉兤橂䡁䅑兤祂䝁䅕睘呂䡁䅕兢瑂䝁䅅杣㕂䍁䅣光歁䕁䅍䅊硁䑁䅍杏歁䕁䅍䅊硁䑁䅕䅍䅁䝁䕑䅁杁䅁䅁睕兂䙁䄸杕䙂䙁䅙睘䕂䕁䅅䅖䙂䙁䄸兒呂䙁䅑䅁䡂䅁䅁杆䅁䙁䅁杕䩂䕁䅍兒䑂䕁䅷睔呂䕁䅕䅁婃兂䅁杣䅁䍁䅣睗乂䕁䅫睘䑂䝁䄸兢睂䝁䅅杢㕂䙁䄸睓求䡁䅫睕あ䝁䅅䅤穂䙁䄸杤硁䍁䄰䅉偂䡁䅉兡湂䝁䅫杢桂䝁䅷杌㑂䝁䅷督瑂䙁䄰睓求䡁䅫睘呂䡁䅑兙あ䡁䅍睊桁䍁䅑村歁䑁䅉杍䅁䝁䙁䅁䕃䅁䅁睊扂䕁䄰兓時䕁䅍睢瑂䡁䅁兙畂䡁䅫睘䱂䝁䅕入呂䡁䅑兙あ䡁䅍睘㉂䑁䅅䅉潁䑁䅍克畁䡁䅧䅢穂䝁䄰兘䑂䝁䅅䅣灂䡁䅑兙獂䙁䄸睕あ䡁䅉兤橂䡁䅑兤祂䝁䅕睘呂䡁䅕兢瑂䝁䅅杣㕂䍁䅣光歁䕁䅍䅊ㅁ䅁䅁杚䅑䝁䄴䅁湁䙁䅳兔䩂䙁䄸睑療䝁䄰䅣桂䝁䄴入時䕁䅳党㕂䙁䅍䅤桂䡁䅑督時䡁䅙免杁䍁䅧睍灁䍁䄴䅥獂䡁䅍兢摂䕁䅍兙穂䝁䅧睘䝂䝁䅷睢㍂䍁䅣光歁䕁䅕䅊ㅁ䑁䅯䅊兂䍁䅑兎䅁䙁䕕䅁奂䅁䅁睖癁䕁䅅杤求䡁䅉兙湂䝁䅕䅉䩂䝁䄴䅤求䡁䅉党穂䡁䅑䅉卂䝁䅅䅤求䑁䅯䅉䵂䝁䄸杢湂䍁䄰䅤求䡁䅉兢杁䕁䅑党楂䡁䅑䅉潁䍁䅕克䅁佁䉉䅁奁䅁䅁兒䍂䕁䅫䅖杁䍁䅧䅊睁䑁䅁䅍灁䅁䅁睚䅁䝁䄴䅁湁䙁䅳兔䩂䙁䄸睑療䝁䄰䅣桂䝁䄴入時䕁䅳党㕂䙁䅍䅤桂䡁䅑督時䡁䅙免杁䍁䅧睍灁䍁䄴䅥獂䡁䅍兢摂䕁䅍兙睂䝁䅫䅤桂䝁䅷兡㙂䝁䅅䅤灂䝁䄸杢湁䍁䅅䅊䑂䍁䅑䅎䅁䙁䕙䅁楁䅁䅁兓剂䙁䄸䅕卂䕁䅕睘偂䙁䅁兒佂䙁䄸睑偂䙁䅍䅖䅁䭁䄴䅁浂䅁䅁睗乂䕁䅫睘䑂䝁䄸兢睂䝁䅅杢㕂䙁䄸睓求䡁䅫睕あ䝁䅅䅤穂䙁䄸杤硁䍁䄴䅥獂䡁䅍兢摂䕁䅳党㕂䙁䄸睕あ䝁䅅䅤穂䍁䅅䅊啂䍁䅑兎㑁䑁䅯䅊啂䍁䅑李硁䅁䅁杲䅕䩁䅉䅁湁䙁䅳兔䩂䙁䄸睑療䝁䄰䅣桂䝁䄴入時䕁䅳党㕂䙁䅍䅤桂䡁䅑督時䡁䅙免杁䍁䅧睍灁䍁䄴䅥獂䡁䅍兢摂䕁䅍兙睂䝁䅫䅤桂䝁䅷睘呂䡁䅑杣ㅂ䝁䅍䅤ㅂ䡁䅉党時䙁䅍兤瑂䝁䄰兙祂䡁䅫睊桁䍁䅑䅒歁䑁䅉睎㙁䍁䅑䅒歁䑁䅣䅏䅁䝁䕧䅁捃䅁䅁睊扂䕁䅍睢睂䡁䅫䅉療䝁䅙䅉呂䙁䅁睒時䕁䅍睢瑂䡁䅁兙畂䡁䅫睘䱂䝁䅕入呂䡁䅑兙あ䡁䅍睘㉂䑁䅉睘畂䝁䅕睤畁䡁䅧䅢穂䝁䄰兘䑂䝁䅅䅣灂䡁䅑兙獂䙁䄸睕あ䡁䅉兤橂䡁䅑兤祂䝁䅕睘杁䕁䅑党あ䝁䅅兡獂䡁䅍䅉湁䍁䅅䅊䱂䍁䅑免祁䅁䅁来䅣䥁䄴䅁湁䙁䅳兔䩂䙁䄸睑療䝁䄰䅣桂䝁䄴入時䕁䅳党㕂䙁䅍䅤桂䡁䅑督時䡁䅙免杁䍁䅧睍灁䍁䄴䅥獂䡁䅍兢摂䕁䅍兙睂䝁䅫䅤桂䝁䅷睘呂䡁䅑杣ㅂ䝁䅍䅤ㅂ䡁䅉党時䙁䅍兤瑂䝁䄰兙祂䡁䅫睊桁䍁䅑兒歁䑁䅑杏歁䕁䄸䅊ぁ䅁䅁睙䅑䡁䅙䅁湁䙁䅳睕兂䕁䅣睘䑂䝁䄸兢睂䝁䅅杢㕂䙁䄸睓求䡁䅫睕あ䝁䅅䅤穂䙁䄸杤硁䍁䅁䅋祁䍁䅫杌㑂䝁䅷督瑂䙁䄰䅕求䝁䄴督灂䝁䄸杢瑁䕁䄸䅕䙂䕁䅉睊桁䍁䅑䅒歁䑁䅙杏歁䕁䅫䅊㉁䅁䅁兔䅙䝁䅑䅁扂䙁䅍䅕䡂䙁䄸睑療䝁䄰䅣桂䝁䄴入時䕁䅳党㕂䙁䅍䅤桂䡁䅑督時䡁䅙杍畁䡁䅧䅢穂䝁䄰兘䑂䝁䅅督潂䙁䄸杒獂䝁䄸睤桁䍁䅑兒歁䑁䅙杏歁䙁䅅䅊㉁䅁䅁眳䅣䕁䅧䅁䭂䡁䅉杌杁䙁䅍兤楂䍁䅁䅒求䝁䅉䅤杁䍁䄸䅉潁䕁䅕村䩂䙁䅑䅒䉂䍁䅁兌杁䕁䅍兙睂䝁䅕䅥灁䍁䅁䅋㑂䍁䅫䅁慃允䅁䅨䅁䍁䅣睗䑂䝁䄸䅣㕂䍁䅁睢浂䍁䅁睕兂䕁䅣睘䑂䝁䄸兢睂䝁䅅杢㕂䙁䄸睓求䡁䅫睕あ䝁䅅䅤穂䙁䄸杤祁䙁䄸杢求䡁䅣杌㑂䝁䅷督瑂䙁䄰睓求䡁䅫睘呂䡁䅑兙あ䡁䅍睊桁䍁䅑兒歁䑁䅉兎㙁䍁䅑睓歁䑁䅉兎䅁䥁䠰䅁㙂䅁䅁睊扂䕁䄰兓時䕁䅍睢瑂䡁䅁兙畂䡁䅫睘䱂䝁䅕入呂䡁䅑兙あ䡁䅍睘㉂䑁䅅兌䑂䝁䄸䅣㕂䍁䄴䅥獂䡁䅍兢摂䕁䅍兙睂䝁䅫䅤桂䝁䅷兡㙂䝁䅅䅤灂䝁䄸杢湁䍁䅅䅊䙂䍁䅑兎㙁䍁䅑杓歁䑁䅕䅁㍁兂䅁䅨䅁䍁䅣睗䑂䝁䄸䅣㕂䍁䅁睢浂䍁䅁睕兂䕁䅣睘䑂䝁䄸兢睂䝁䅅杢㕂䙁䄸睓求䡁䅫睕あ䝁䅅䅤穂䙁䄸杤祁䙁䄸杢求䡁䅣杌㑂䝁䅷督瑂䙁䄰睓求䡁䅫睘呂䡁䅑兙あ䡁䅍睊桁䍁䅑兒歁䑁䅉李㙁䍁䅑睓歁䑁䅉李䅁䥁䠴䅁卂䅁䅁睕ㅂ䝁䅉兌䵂䝁䅕兙穂䝁䅕䅉䩂䝁䄴睙療䝁䄰党獁䍁䅁兑浂䡁䅑党祂䍁䅁兎杁䙁䅫杣穂䍁䅁䅋卂䝁䅕䅣療䡁䅉䅤求䝁䅑克䅁乁䉉䅁㉁䅁䅁兓剂䙁䄸䅖偂䙁䅑兑䵂䙁䄸睔兂䙁䅑兓偂䕁䄴睕時䕁䅕䅗䙂䙁䅉睑䩂䙁䅍兒䕂䅁䅁村䅍䡁䄴䅁湁䙁䅳兔䩂䙁䄸睑療䝁䄰䅣桂䝁䄴入時䕁䅳党㕂䙁䅍䅤桂䡁䅑督時䡁䅙免瑁䕁䅍睢睂䡁䅫杌㑂䝁䅷督瑂䙁䄰睑桂䡁䅁兡あ䝁䅅䅢灂䡁䅯兙あ䝁䅫睢畂䍁䅣光歁䕁䅕䅊ㅁ䑁䅧杏歁䕁䅯䅊ㅁ䑁䅧䅁䩂兂䅁䅩䅁䍁䅣睗呂䙁䅁睒時䕁䅍睢瑂䡁䅁兙畂䡁䅫睘䱂䝁䅕入呂䡁䅑兙あ䡁䅍睘㉂䑁䅉䅉硁䍁䄴䅥獂䡁䅍兢摂䕁䅍兙睂䝁䅫䅤桂䝁䅷睘呂䡁䅑杣ㅂ䝁䅍䅤ㅂ䡁䅉党時䍁䅁䅒求䡁䅑兙灂䝁䅷督杁䍁䅣光歁䕁䅣䅊㍁䑁䅙䅁楁睂䅁杆䅁䑁䅁兏癁䑁䅅睎癁䑁䅉䅍祁䑁䅁䅁湃兂䅁杚䅁䍁䅣睗乂䕁䅫睘䑂䝁䄸兢睂䝁䅅杢㕂䙁䄸睓求䡁䅫睕あ䝁䅅䅤穂䙁䄸杤硁䍁䅁䅋穁䍁䅫杌㑂䝁䅷督瑂䙁䄰睓求䡁䅫睘呂䡁䅑兙あ䡁䅍睊桁䍁䅑兒歁䑁䅕杍䅁䑁䔸䅁㙁䅁䅁睒求䝁䄴党祂䝁䅅䅢癁䕁䄸䅤潂䝁䅕杣杁䕁䅉睢祂䡁䅉睢㍂䝁䅫杢湂䡁䅍䅉潁䍁䅕克䅁偁䅅䅁䵃䅁䅁睊扂䙁䅍䅕䡂䙁䄸睑療䝁䄰䅣桂䝁䄴入時䕁䅳党㕂䙁䅍䅤桂䡁䅑督時䡁䅙杍杁䑁䅅杌㑂䝁䅷督瑂䙁䄰睑桂䡁䅁兡あ䝁䅅䅢時䙁䅍䅤祂䡁䅕睙あ䡁䅕杣求䙁䄸睕ㅂ䝁䄰兢桂䡁䅉入湁䍁䅅䅊䙂䍁䅑李㙁䍁䅑睔歁䑁䅙䅁睄杂䅁杒䅁䙁䅁杣療䡁䅙兡穂䝁䅫睢畂䍁䅁杚療䡁䅉䅉䍂䝁䅅䅚杁䕁䅑党楂䡁䅑督杁䍁䅧杕求䡁䅁睢祂䡁䅑党歂䍁䅫䅁牃䅁䅁杪䅁䍁䅣睗乂䕁䅫睘䑂䝁䄸兢睂䝁䅅杢㕂䙁䄸睓求䡁䅫睕あ䝁䅅䅤穂䙁䄸杤硁䍁䅁䅋穁䍁䅫杌㑂䝁䅷督瑂䙁䄰睑桂䡁䅁兡あ䝁䅅䅢時䙁䅍䅤祂䡁䅕睙あ䡁䅕杣求䙁䄸睕ㅂ䝁䄰兢桂䡁䅉入湁䍁䅅䅊䙂䍁䅑兎㙁䍁䅑睔歁䑁䅕䅁求䅂䅁䅤䅁䍁䅣睗呂䙁䅁睒時䕁䅍睢瑂䡁䅁兙畂䡁䅫睘䱂䝁䅕入呂䡁䅑兙あ䡁䅍睘㉂䑁䅅杌㑂䝁䅷督瑂䙁䄰䅕求䝁䄴督灂䝁䄸杢瑁䕁䄸䅕䙂䕁䅉睊桁䍁䅑睑歁䑁䅅免㙁䍁䅑睑歁䑁䅕睎睁䅁䅁杄䅙䥁䄴䅁湁䙁䅳兔䩂䙁䄸睑療䝁䄰䅣桂䝁䄴入時䕁䅳党㕂䙁䅍䅤桂䡁䅑督時䡁䅙免杁䍁䅧睍灁䍁䄴䅥獂䡁䅍兢摂䕁䅍兙睂䝁䅫䅤桂䝁䅷睘呂䡁䅑杣ㅂ䝁䅍䅤ㅂ䡁䅉党時䙁䅍兤瑂䝁䄰兙祂䡁䅫睊桁䍁䅑杒歁䑁䅧杏歁䙁䅁䅊㑁䅁䅁睚䅑䝁䅙䅁扂䕁䄰兓時䕁䅍睢瑂䡁䅁兙畂䡁䅫睘䱂䝁䅕入呂䡁䅑兙あ䡁䅍睘㉂䑁䅅杌㑂䝁䅷督瑂䙁䄰睓求䡁䅫睘呂䡁䅑兙あ䡁䅍光歁䕁䅯䅊祁䑁䅍杏歁䕁䅷䅊祁䑁䅍䅁㝄睁䅁杤䅁䍁䅣睗乂䕁䅫睘䑂䝁䄸兢睂䝁䅅杢㕂䙁䄸睓求䡁䅫睕あ䝁䅅䅤穂䙁䄸杤硁䍁䅁䅋穁䍁䅫杌㑂䝁䅷督瑂䙁䄰睓求䡁䅫睘呂䡁䅑兙あ䡁䅍睊桁䍁䅑睑歁䑁䅅䅍ㅁ䑁䅯䅊䑂䍁䅑免睁䑁䅫䅁䥂䅂䅁杢䅁䍁䅣睗乂䕁䅫睘䑂䝁䄸兢睂䝁䅅杢㕂䙁䄸睓求䡁䅫睕あ䝁䅅䅤穂䙁䄸杤硁䍁䅁兌獂䝁䅅䅤求䡁䅍䅤畁䡁䅧䅢穂䝁䄰兘䱂䝁䅕入時䙁䅍䅤桂䡁䅑督湁䍁䅅䅊䙂䍁䅑兎祁䅁䅁睇䅕䙁䅙䅁扂䕁䄰兓時䕁䅳党㕂䙁䅍䅤桂䡁䅑督時䡁䅙免畁䡁䅧䅢穂䝁䄰兘䱂䝁䅕入時䙁䅍䅤桂䡁䅑督桁䍁䅑睑歁䑁䅙免㙁䍁䅑睑歁䑁䅙睎䅁䡁䑍䅁煁䅁䅁兓剂䙁䄸睑䵂䙁䄸䅒噂䕁䅕睘䉂䕁䅙䅖䙂䙁䅉睘䝂䕁䅫杖䙂䅁䅁关䅅䥁䄴䅁湁䙁䅳兔䩂䙁䄸睑療䝁䄰䅣桂䝁䄴入時䕁䅳党㕂䙁䅍䅤桂䡁䅑督時䡁䅙免杁䍁䅧睍灁䍁䄴䅥獂䡁䅍兢摂䕁䅍兙睂䝁䅫䅤桂䝁䅷睘呂䡁䅑杣ㅂ䝁䅍䅤ㅂ䡁䅉党時䙁䅍兤瑂䝁䄰兙祂䡁䅫睊桁䍁䅑杒歁䑁䅫杏歁䙁䅁䅊㕁䅁䅁兡䅑䡁䅑䅁湁䙁䅳睕兂䕁䅣睘䑂䝁䄸兢睂䝁䅅杢㕂䙁䄸睓求䡁䅫睕あ䝁䅅䅤穂䙁䄸杤硁䍁䅁䅋祁䍁䅫杌㑂䝁䅷督瑂䙁䄰睓求䡁䅫睘呂䡁䅑兙あ䡁䅍睊桁䍁䅑睑歁䑁䅉䅏㙁䍁䅑睑歁䑁䅕杍䅁䉁䝉䅁啂䅁䅁䅖療䡁䅑兙獂䍁䅁兖畂䝁䅅兢療䡁䅉䅤灂䡁䅯党歂䍁䅁䅕祂䝁䅕兢灂䡁䅕兢癁䍁䅁䅖療䡁䅑兙獂䍁䅁䅒求䝁䅉䅤杁䍁䅧兊灁䅁䅁眯䅁䍁䄴䅁䩂䙁䅅睘䵂䕁䅙睑䝂䙁䄸睍婂䙁䅉睘䉂䕁䄴杔時䕁䅣杕偂䙁䅣䅖䥂䅁䅁睧䅉䝁䅙䅁湁䙁䅳兔䩂䙁䄸睑療䝁䄰䅣桂䝁䄴入時䕁䅳党㕂䙁䅍䅤桂䡁䅑督時䡁䅙免杁䍁䅧睍灁䍁䄴䅥獂䡁䅍兢摂䕁䅳党㕂䙁䄸睕あ䝁䅅䅤穂䍁䅣光歁䕁䅉䅊祁䑁䅉䅁睁䅂䅁䅯䅁䍁䅣睗䑂䝁䄸䅣㕂䍁䅁睢浂䍁䅁睕兂䕁䅣睘䑂䝁䄸兢睂䝁䅅杢㕂䙁䄸睓求䡁䅫睕あ䝁䅅䅤穂䙁䄸杤硁䙁䄸杒灂䝁䄴兙獂䍁䄴䅥獂䡁䅍兢摂䕁䅍兙睂䝁䅫䅤桂䝁䅷睘呂䡁䅑杣ㅂ䝁䅍䅤ㅂ䡁䅉党時䍁䅁䅒求䡁䅑兙灂䝁䅷督杁䍁䅣光歁䕁䅉䅊㍁䑁䅙䅁佃䅃䅁杢䅁䕁䄸䅣求䡁䅉兙あ䝁䅫杢湂䍁䅁䅔求䝁䅅督求䍁䅁睑療䝁䄰兢灂䡁䅑兢求䝁䄴䅤杁䕁䅑兤求䍁䅷䅉䉂䝁䅙䅤求䡁䅉䅉ㅁ䍁䅁兗祂䡁䅍䅉潁䙁䅉党睂䝁䄸杣あ䝁䅕䅚灁䅁䅁䅸䅅䝁䅷䅁扂䕁䄰兓時䕁䅍睢瑂䡁䅁兙畂䡁䅫睘䱂䝁䅕入呂䡁䅑兙あ䡁䅍睘㉂䑁䅅杌㑂䝁䅷督瑂䙁䄰睑桂䡁䅁兡あ䝁䅅䅢灂䡁䅯兙あ䝁䅫睢畂䍁䅅䅊䙂䍁䅑兎㙁䍁䅑杓歁䑁䅕䅁呁䅂䅁䅡䅁䙁䅳兔䩂䙁䄸睑療䝁䄰䅣桂䝁䄴入時䕁䅳党㕂䙁䅍䅤桂䡁䅑督時䡁䅙免時䍁䄴䅥獂䡁䅍兢摂䕁䅳党㕂䙁䄸睕あ䝁䅅䅤穂䍁䅅䅊䕂䍁䅑杍㑁䑁䅯䅊䕂䍁䅑兎祁䅁䅁睷䅑䑁䅧䅁䩂䝁䄴杤求䝁䄴䅤療䡁䅉入獁䍁䅁免杁䙁䅫杣畁䍁䅁睒祂䝁䄸睤あ䝁䅧䅉潁䍁䅕克䅁䍁䍧䅁歃䅁䅁睊扂䕁䅍睢睂䡁䅫䅉療䝁䅙䅉呂䙁䅁睒時䕁䅍睢瑂䡁䅁兙畂䡁䅫睘䱂䝁䅕入呂䡁䅑兙あ䡁䅍睘㉂䑁䅉睘畂䝁䅕睤畁䡁䅧䅢穂䝁䄰兘䑂䝁䅅䅣灂䡁䅑兙獂䙁䄸睕あ䡁䅉兤橂䡁䅑兤祂䝁䅕睘呂䡁䅕兢瑂䝁䅅杣㕂䍁䅣光歁䕁䅙䅊硁䑁䅅杏歁䙁䅉䅊硁䑁䅅䅁䕄睂䅁杍䅁䕁䅫兕時䙁䅑睔啂䕁䅅䅔時䙁䅣兑卂䙁䅉兑佂䙁䅑睕時䕁䅕杔䕂䙁䄸睔呂䅁䅁䅘䅍䡁䅷䅁湁䙁䅳兔䩂䙁䄸睑療䝁䄰䅣桂䝁䄴入時䕁䅳党㕂䙁䅍䅤桂䡁䅑督時䡁䅙免杁䍁䅧睍灁䍁䄴䅥獂䡁䅍兢摂䕁䅍兙睂䝁䅫䅤桂䝁䅷兡㙂䝁䅅䅤灂䝁䄸杢湁䍁䅅䅊䙂䍁䅑䅎㑁䑁䅯䅊兂䍁䅑䅎㑁䅁䅁兘䅑䡁䅧䅁湁䙁䅳兔䩂䙁䄸睑療䝁䄰䅣桂䝁䄴入時䕁䅳党㕂䙁䅍䅤桂䡁䅑督時䡁䅙免瑁䕁䅍睢睂䡁䅫杌㑂䝁䅷督瑂䙁䄰睓求䡁䅫睘呂䡁䅑兙あ䡁䅍睊桁䍁䅑兒歁䑁䅅䅍㑁䑁䅯䅊䡂䍁䅑免睁䑁䅧䅁湁兂䅁杋䅁䕁䅫兕時䕁䄴兓時䑁䅍兗卂䙁䄸兑佂䕁䄴睘䡂䙁䅉睔塂䙁䅑䅓䅁䝁䌸䅁睂䅁䅁睊扂䕁䄰兓時䕁䅍睢瑂䡁䅁兙畂䡁䅫睘䱂䝁䅕入呂䡁䅑兙あ䡁䅍睘㉂䑁䅅䅉潁䑁䅍克畁䡁䅧䅢穂䝁䄰兘䑂䝁䅅䅣灂䡁䅑兙獂䝁䅫来桂䡁䅑兡療䝁䄴睊桁䍁䅑睑歁䑁䅑䅏䅁䙁䕯䅁睂䅁䅁睊扂䕁䄰兓時䕁䅍睢瑂䡁䅁兙畂䡁䅫睘䱂䝁䅕入呂䡁䅑兙あ䡁䅍睘㉂䑁䅅䅉潁䑁䅍克畁䡁䅧䅢穂䝁䄰兘䑂䝁䅅䅣灂䡁䅑兙獂䝁䅫来桂䡁䅑兡療䝁䄴睊桁䍁䅑睑歁䑁䅕䅍䅁䙁䕷䅁㡂䅁䅁睊扂䕁䄰兓時䕁䅍睢瑂䡁䅁兙畂䡁䅫睘䱂䝁䅕入呂䡁䅑兙あ䡁䅍睘㉂䑁䅅䅉潁䑁䅍克畁䡁䅧䅢穂䝁䄰兘䑂䝁䅅䅣灂䡁䅑兙獂䝁䅫来桂䡁䅑兡療䝁䄴睊桁䍁䅑兒歁䑁䅕免㙁䍁䅑杓歁䑁䅕免䅁䙁䔸䅁㡁䅁䅁杖桂䡁䅉兡桂䝁䅉䅢求䍁䅁杕桂䡁䅑党杁䕁䅑党楂䡁䅑䅉潁䙁䅉党睂䝁䄸杣あ䝁䅕䅚灁䅁䅁兕䅅䥁䅙䅁扂䕁䄰兓時䕁䅍睢瑂䡁䅁兙畂䡁䅫睘䱂䝁䅕入呂䡁䅑兙あ䡁䅍睘㉂䑁䅅杌㑂䝁䅷督瑂䙁䄰睑桂䡁䅁兡あ䝁䅅䅢時䙁䅍䅤祂䡁䅕睙あ䡁䅕杣求䙁䄸睕ㅂ䝁䄰兢桂䡁䅉入桁䍁䅑䅒歁䑁䅉睎㙁䍁䅑䅒歁䑁䅣䅏䅁䍁䕉䅁㡂䅁䅁睊扂䕁䄰兓時䕁䅍睢瑂䡁䅁兙畂䡁䅫睘䱂䝁䅕入呂䡁䅑兙あ䡁䅍睘㉂䑁䅅䅉潁䑁䅍克畁䡁䅧䅢穂䝁䄰兘䑂䝁䅅䅣灂䡁䅑兙獂䝁䅫来桂䡁䅑兡療䝁䄴睊桁䍁䅑兒歁䑁䅕杍㙁䍁䅑杓歁䑁䅕杍䅁䝁䕅䅁䭂䅁䅁睑桂䡁䅁兡あ䝁䅅䅢杁䕁䅕䅥睂䝁䅕杢歂䝁䅫䅤ㅂ䡁䅉党穂䍁䅷䅉穁䍁䅁兗祂䍁䄴䅉䑂䕁䅅睒卂䍁䅁䅋汁䍁䅫䅁䍃杁䅁䅦䅁䍁䅣睗乂䕁䅫睘䑂䝁䄸兢睂䝁䅅杢㕂䙁䄸睓求䡁䅫睕あ䝁䅅䅤穂䙁䄸杤硁䍁䅁䅋穁䍁䅫杌㑂䝁䅷督瑂䙁䄰睑桂䡁䅁兡あ䝁䅅䅢灂䡁䅯兙あ䝁䅫睢畂䍁䅣光歁䕁䅍䅊ㅁ䑁䅍杏歁䕁䅍䅊ㅁ䑁䅑䅁杂䅂䅁杓䅁䙁䅳兔䩂䙁䄸睓求䡁䅫睕あ䝁䅅䅤穂䙁䄸杤硁䍁䄴䅥獂䡁䅍兢摂䕁䅳党㕂䙁䄸睕あ䝁䅅䅤穂䍁䅅䅊䙂䍁䅑兎祁䅁䅁杤䅍䝁䅧䅁湁䙁䅳睕兂䕁䅣睘䑂䝁䄸兢睂䝁䅅杢㕂䙁䄸睓求䡁䅫睕あ䝁䅅䅤穂䙁䄸杤硁䍁䅁䅋祁䍁䅫杌㑂䝁䅷督瑂䙁䄰睓求䡁䅫睘呂䡁䅑兙あ䡁䅍睊桁䍁䅑兒歁䑁䅙睍䅁䉁䜸䅁㙂䅁䅁睊扂䕁䄰兓時䕁䅍睢瑂䡁䅁兙畂䡁䅫睘䱂䝁䅕入呂䡁䅑兙あ䡁䅍睘㉂䑁䅅䅉潁䑁䅍克畁䡁䅧䅢穂䝁䄰兘䑂䝁䅅䅣灂䡁䅑兙獂䝁䅫来桂䡁䅑兡療䝁䄴睊桁䍁䅑睑歁䑁䅫杏歁䕁䅍䅊祁䑁䅕䅁奂䅂䅁杆䅁䙁䅍䅕時䙁䅁兒䡂䙁䄸杒塂䕁䅑䅁敂杂䅁杗䅁䙁䅳兔䩂䙁䄸睑療䝁䄰䅣桂䝁䄴入時䕁䅳党㕂䙁䅍䅤桂䡁䅑督時䡁䅙免畁䡁䅧䅢穂䝁䄰兘䱂䝁䅕入時䙁䅍䅤桂䡁䅑督桁䍁䅑村歁䑁䅕兎䅁䡁䙙䅁睁䅁䅁兓剂䙁䄸䅒䉂䕁䅫䅔婂䙁䄸兑坂䕁䅣睘卂䕁䅕杖時䙁䅑杕䉂䕁䅑兒呂䅁䅁䅩䅍䡁䅧䅁湁䙁䅳兔䩂䙁䄸睑療䝁䄰䅣桂䝁䄴入時䕁䅳党㕂䙁䅍䅤桂䡁䅑督時䡁䅙免杁䍁䅧睍灁䍁䄴䅥獂䡁䅍兢摂䕁䅍兙睂䝁䅫䅤桂䝁䅷兡㙂䝁䅅䅤灂䝁䄸杢湁䍁䅅䅊䙂䍁䅑䅎㙁䍁䅑杓歁䑁䅑䅁塂䅂䅁杋䅁䙁䅑睢あ䝁䅅䅢杁䙁䅉党㉂䝁䅕杢ㅂ䝁䅕䅉潁䍁䅑䅍睁䑁䅁克䅁䝁䅕䅁㉂䅁䅁睊扂䕁䄰兓時䕁䅍睢瑂䡁䅁兙畂䡁䅫睘䱂䝁䅕入呂䡁䅑兙あ䡁䅍睘㉂䑁䅅䅉潁䑁䅍克畁䡁䅧䅢穂䝁䄰兘䱂䝁䅕入時䙁䅍䅤桂䡁䅑督湁䍁䅅䅊䙂䍁䅑免睁䑁䅍杏歁䕁䅣䅊硁䑁䅁睍䅁䕁䕣䅁㙂䅁䅁睊扂䙁䅍䅕䡂䙁䄸睑療䝁䄰䅣桂䝁䄴入時䕁䅳党㕂䙁䅍䅤桂䡁䅑督時䡁䅙杍杁䑁䅅杌㑂䝁䅷督瑂䙁䄰睑桂䡁䅁兡あ䝁䅅䅢灂䡁䅯兙あ䝁䅫睢畂䍁䅣光歁䕁䅕䅊ぁ䑁䅙杏歁䕁䅯䅊ぁ䑁䅙䅁獄杂䅁䅗䅁䙁䅳兔䩂䙁䄸睑療䝁䄰䅣桂䝁䄴入時䕁䅳党㕂䙁䅍䅤桂䡁䅑督時䡁䅙免畁䡁䅧䅢穂䝁䄰兘䑂䝁䅅督潂䙁䄸杒獂䝁䄸睤桁䍁䅑睑歁䑁䅑䅁䵁䅂䅁杣䅁䍁䅣睗乂䕁䅫睘䑂䝁䄸兢睂䝁䅅杢㕂䙁䄸睓求䡁䅫睕あ䝁䅅䅤穂䙁䄸杤硁䍁䅁䅋穁䍁䅫杌㑂䝁䅷督瑂䙁䄰睓求䡁䅫睘呂䡁䅑兙あ䡁䅍睊桁䍁䅑䅒歁䑁䅉兎㙁䍁䅑䅒歁䑁䅑兏䅁䑁䕙䅁㑂䅁䅁睊扂䕁䄰兓時䕁䅍睢瑂䡁䅁兙畂䡁䅫睘䱂䝁䅕入呂䡁䅑兙あ䡁䅍睘㉂䑁䅅䅉潁䑁䅍克畁䡁䅧䅢穂䝁䄰兘䑂䝁䅅䅣灂䡁䅑兙獂䝁䅫来桂䡁䅑兡療䝁䄴睊桁䍁䅑兒歁䑁䅕杏歁䕁䅯䅊ㅁ䅁䅁兗䅑䡁䅑䅁湁䙁䅳睕兂䕁䅣睘䑂䝁䄸兢睂䝁䅅杢㕂䙁䄸睓求䡁䅫睕あ䝁䅅䅤穂䙁䄸杤祁䍁䅁免畁䡁䅧䅢穂䝁䄰兘䍂䝁䅅䅢桂䝁䄴睙求䙁䄸睕潂䝁䅕党あ䍁䅣光歁䕁䅕䅊㉁䑁䅯䅊兂䍁䅑李䅁乁䝷䅁歂䅁䅁睊扂䕁䄰兓時䕁䅍睢瑂䡁䅁兙畂䡁䅫睘䱂䝁䅕入呂䡁䅑兙あ䡁䅍睘㉂䑁䅅䅉潁䑁䅍克畁䡁䅧䅢穂䝁䄰兘䑂䝁䅅督潂䙁䄸杒獂䝁䄸睤湁䍁䅅䅊䑂䍁䅑䅎䅁䙁䕉䅁畂䅁䅁睊扂䕁䄰兓時䕁䅍睢瑂䡁䅁兙畂䡁䅫睘䱂䝁䅕入呂䡁䅑兙あ䡁䅍睘㉂䑁䅅䅉瑁䝁䅷兙あ䝁䅕督あ䍁䄴䅥獂䡁䅍兢摂䕁䅳党㕂䙁䄸睕あ䝁䅅䅤穂䍁䅣光歁䕁䅉䅊ㅁ䑁䅅䅁奁兂䅁䅦䅁䍁䅣睗乂䕁䅫睘䑂䝁䄸兢睂䝁䅅杢㕂䙁䄸睓求䡁䅫睕あ䝁䅅䅤穂䙁䄸杤硁䍁䅁䅋穁䍁䅫杌㑂䝁䅷督瑂䙁䄰兓畂䝁䅍睢瑂䝁䅕睘呂䡁䅑兙あ䝁䅕兢求䝁䄴䅤湁䍁䅅䅊䙂䍁䅑䅎㙁䍁䅑䅕歁䑁䅑䅁䱂䅂䅁杗䅁䙁䅳兔䩂䙁䄸睑療䝁䄰䅣桂䝁䄴入時䕁䅳党㕂䙁䅍䅤桂䡁䅑督時䡁䅙免畁䡁䅧䅢穂䝁䄰兘䱂䝁䅕入時䙁䅍䅤桂䡁䅑督桁䍁䅑村歁䑁䅉兎䅁䥁䕧䅁浂䅁䅁睗乂䕁䅫睘䑂䝁䄸兢睂䝁䅅杢㕂䙁䄸睓求䡁䅫睕あ䝁䅅䅤穂䙁䄸杤硁䍁䄴䅥獂䡁䅍兢摂䕁䅳党㕂䙁䄸睕あ䝁䅅䅤穂䍁䅅䅊䑂䍁䅑兎㍁䑁䅯䅊䑂䍁䅑兎㑁䅁䅁睲䅑䡁䅙䅁偂䡁䅁䅤灂䝁䄸杢穂䍁䅁睑桂䝁䄴睙求䝁䅷䅢求䝁䅑䅉䕂䡁䅕杣灂䝁䄴睚杁䡁䅑䅡求䍁䅁䅕求䡁䅉兡療䝁䅑䅌杁䕁䅍睢瑂䝁䄰睢畂䍁䅁睕あ䝁䄸睙牂䍁䅁䅋桂䝁䅍䅤ㅂ䝁䅅䅢灁䅁䅁兏䅍䡁䅁䅁湁䙁䅳兔䩂䙁䄸睑療䝁䄰䅣桂䝁䄴入時䕁䅳党㕂䙁䅍䅤桂䡁䅑督時䡁䅙免杁䍁䅧睍灁䍁䄴䅥獂䡁䅍兢摂䕁䅍兙穂䝁䅧睘䝂䝁䅷睢㍂䍁䅣光歁䕁䅍䅊㕁䑁䅯䅊䑂䍁䅑兏睁䅁䅁䅖䅑䥁䅙䅁湁䙁䅳睕兂䕁䅣睘䑂䝁䄸兢睂䝁䅅杢㕂䙁䄸睓求䡁䅫睕あ䝁䅅䅤穂䙁䄸杤硁䍁䅁䅋祁䍁䅫杌㑂䝁䅷督瑂䙁䄰睑桂䡁䅁兡あ䝁䅅䅢時䙁䅍䅤祂䡁䅕睙あ䡁䅕杣求䙁䄸睕ㅂ䝁䄰兢桂䡁䅉入湁䍁䅅䅊䑂䍁䅑睎䅁䕁䝁䅁ぁ䅁䅁䅕求䡁䅉兡療䝁䅑䅉䙂䝁䄴䅚求䝁䅑䅉潁䝁䄰兢癁䝁䅑䅚癁䡁䅫入㕂䡁䅫克䅁䙁䅉䅁杂䅁䅁睊扂䕁䄰兓時䕁䅳党㕂䙁䅍䅤桂䡁䅑督時䡁䅙免畁䡁䅧䅢穂䝁䄰兘兂䝁䅕杢穂䝁䅫睢畂䍁䄰睔兂䕁䅕村湁䍁䅅䅊䑂䍁䅑兏㙁䍁䅑睑歁䑁䅕李㕁䅁䅁睹䅍䡁䄴䅁湁䙁䅳兔䩂䙁䄸睑療䝁䄰䅣桂䝁䄴入時䕁䅳党㕂䙁䅍䅤桂䡁䅑督時䡁䅙免瑁䕁䅍睢睂䡁䅫杌㑂䝁䅷督瑂䙁䄰睑桂䡁䅁兡あ䝁䅅䅢灂䡁䅯兙あ䝁䅫睢畂䍁䅣光歁䕁䅕䅊㉁䑁䅉杏歁䕁䅯䅊㉁䑁䅉䅁䥂兂䅁䅤䅁䍁䅣睗乂䕁䅫睘䑂䝁䄸兢睂䝁䅅杢㕂䙁䄸睓求䡁䅫睕あ䝁䅅䅤穂䙁䄸杤硁䍁䄰睑療䡁䅁入畁䡁䅧䅢穂䝁䄰兘䱂䝁䅕入時䙁䅍䅤桂䡁䅑督湁䍁䅅䅊乂䍁䅑杍ㅁ䑁䅯䅊偂䍁䅑杍ㅁ䅁䅁光䅕䙁䅙䅁扂䙁䅍䅕䡂䙁䄸睑療䝁䄰䅣桂䝁䄴入時䕁䅳党㕂䙁䅍䅤桂䡁䅑督時䡁䅙杍畁䡁䅧䅢穂䝁䄰兘呂䝁䅧党求䡁䅑免桁䍁䅑䅒歁䑁䅅免䅁䥁䝷䅁䭃䅁䅁睗呂䙁䅁睒時䕁䅍睢瑂䡁䅁兙畂䡁䅫睘䱂䝁䅕入呂䡁䅑兙あ䡁䅍睘㉂䑁䅉杌㑂䝁䅷督瑂䙁䄰睑桂䡁䅁兡あ䝁䅅䅢時䙁䅍䅤祂䡁䅕睙あ䡁䅕杣求䙁䄸睕ㅂ䝁䄰兢桂䡁䅉入桁䍁䅑睑歁䑁䅅兎㙁䍁䅑睑歁䑁䅅睎硁䅁䅁䅂䅧䙁䅷䅁扂䙁䅍䅕䡂䙁䄸睑療䝁䄰䅣桂䝁䄴入時䕁䅳党㕂䙁䅍䅤桂䡁䅑督時䡁䅙免畁䡁䅧䅢穂䝁䄰兘䱂䝁䅕入時䙁䅍䅤桂䡁䅑督桁䍁䅑兒歁䑁䅙睍䅁乁䘸䅁畂䅁䅁睊扂䕁䄰兓時䕁䅍睢瑂䡁䅁兙畂䡁䅫睘䱂䝁䅕入呂䡁䅑兙あ䡁䅍睘㉂䑁䅅䅉潁䑁䅍克畁䡁䅧䅢穂䝁䄰兘䑂䝁䅅督潂䙁䄸杒獂䝁䄸睤湁䍁䅅䅊䙂䍁䅑䅎㙁䍁䅑䅕歁䑁䅑䅁呂䅂䅁䅏䅁䕁䅅䅚煂䡁䅕督あ䝁䄰党畂䡁䅑督癁䍁䅁䅖療䡁䅑兙獂䍁䅁䅒求䝁䅉䅤杁䍁䅧兊灁䅁䅁睁䅅䡁䅯䅁湁䙁䅳睕兂䕁䅣睘䑂䝁䄸兢睂䝁䅅杢㕂䙁䄸睓求䡁䅫睕あ䝁䅅䅤穂䙁䄸杤祁䍁䅁免畁䡁䅧䅢穂䝁䄰兘䩂䝁䄴睙療䝁䄰党時䙁䅍䅤桂䡁䅑党瑂䝁䅕杢あ䍁䅣光歁䕁䅕䅊㍁䑁䅯䅊兂䍁䅑睎䅁乁䝯䅁祂䅁䅁睊扂䕁䄰兓時䕁䅍睢瑂䡁䅁兙畂䡁䅫睘䱂䝁䅕入呂䡁䅑兙あ䡁䅍睘㉂䑁䅅䅉潁䑁䅍克畁䡁䅧䅢穂䝁䄰兘䩂䝁䄴睙療䝁䄰党時䙁䅍䅤桂䡁䅑党瑂䝁䅕杢あ䍁䅣光歁䕁䅍䅊ぁ䅁䅁杓䅑䡁䅙䅁扂䕁䄰兓時䕁䅳党㕂䙁䅍䅤桂䡁䅑督時䡁䅙免畁䡁䅧䅢穂䝁䄰兘䑂䝁䅅䅣灂䡁䅑兙獂䙁䄸睕あ䡁䅉兤橂䡁䅑兤祂䝁䅕睘呂䡁䅕兢瑂䝁䅅杣㕂䍁䅅䅊䙂䍁䅑杍㍁䑁䅯䅊䙂䍁䅑睎㉁䅁䅁內䅍䙁䅷䅁䵂䙁䅑䅉䕂䝁䅕杙あ䍁䅁䅋䩂䝁䄴睙獂䍁䄴䅉䑂䝁䅅䅣畁䍁䅁䅔求䝁䅅督求䡁䅍克杁䕁䅑兤求䍁䅁睋穁䍁䅁䅋卂䝁䅕䅣療䡁䅉䅤求䝁䅑克䅁䭁䉁䅁㉂䅁䅁睗乂䕁䅫睘䱂䝁䅕入呂䡁䅑兙あ䡁䅍睘㉂䑁䅅杌㑂䝁䅷督瑂䙁䄰睑桂䡁䅁兡あ䝁䅅䅢時䙁䅍䅤祂䡁䅕睙あ䡁䅕杣求䙁䄸睕ㅂ䝁䄰兢桂䡁䅉入桁䍁䅑䅒歁䑁䅉睎㙁䍁䅑䅒歁䑁䅣李䅁䭁䐴䅁䅃䅁䅁睊扂䕁䄰兓時䕁䅍睢瑂䡁䅁兙畂䡁䅫睘䱂䝁䅕入呂䡁䅑兙あ䡁䅍睘㉂䑁䅅䅉潁䑁䅍克畁䡁䅧䅢穂䝁䄰兘䩂䝁䄴睙療䝁䄰党時䙁䅍䅤桂䡁䅑党瑂䝁䅕杢あ䍁䅣光歁䕁䅍䅊㕁䑁䅯䅊䑂䍁䅑免㍁䑁䅍䅁䵂䅂䅁䅦䅁䍁䅣睗乂䕁䅫睘䑂䝁䄸兢睂䝁䅅杢㕂䙁䄸睓求䡁䅫睕あ䝁䅅䅤穂䙁䄸杤硁䍁䅁䅋穁䍁䅫杌㑂䝁䅷督瑂䙁䄰兓畂䝁䅍睢瑂䝁䅕睘呂䡁䅑兙あ䝁䅕兢求䝁䄴䅤湁䍁䅅䅊䙂䍁䅑兎㙁䍁䅑䅕歁䑁䅕䅁乂䅂䅁杧䅁䍁䅣睗呂䙁䅁睒時䕁䅍睢瑂䡁䅁兙畂䡁䅫睘䱂䝁䅕入呂䡁䅑兙あ䡁䅍睘㉂䑁䅉䅉硁䍁䄴䅥獂䡁䅍兢摂䕁䅍兙睂䝁䅫䅤桂䝁䅷睘呂䡁䅑杣ㅂ䝁䅍䅤ㅂ䡁䅉党時䙁䅍兤瑂䝁䄰兙祂䡁䅫睊桁䍁䅑睑歁䑁䅙䅁癄杂䅁䅌䅁䕁䅍兓剂䍁䅁睑桂䝁䅷睙ㅂ䝁䅷兙あ䝁䅫睢畂䍁䅁䅖㕂䡁䅁党杁䅁䅁兌䅍䡁䅑䅁湁䙁䅳睕兂䕁䅣睘䑂䝁䄸兢睂䝁䅅杢㕂䙁䄸睓求䡁䅫睕あ䝁䅅䅤穂䙁䄸杤硁䍁䅁䅋祁䍁䅫杌㑂䝁䅷督瑂䙁䄰睓求䡁䅫睘呂䡁䅑兙あ䡁䅍睊桁䍁䅑䅖歁䑁䅕䅏㙁䍁䅑䅖歁䑁䅙免䅁䍁䝍䅁佂䅁䅁兓剂䙁䄸睑䥂䕁䅅杔䡂䕁䅕睘噂䕁䄴杕䙂䕁䅍睔䡂䙁䄸䅖䉂䙁䅧睘䍂䕁䅕杔䙂䕁䅙兓啂䙁䄸免時䙁䅫杕時䕁䄰兓佂䅁䅁杆䅍䝁䅧䅁湁䙁䅳兔䩂䙁䄸睑療䝁䄰䅣桂䝁䄴入時䕁䅳党㕂䙁䅍䅤桂䡁䅑督時䡁䅙免杁䍁䅧睍灁䍁䄴䅥獂䡁䅍兢摂䕁䅳党㕂䙁䄸睕あ䝁䅅䅤穂䍁䅣光歁䕁䅉䅊硁䑁䅁杍䅁䕁䕙䅁浂䅁䅁睊扂䕁䄰兓時䕁䅍睢瑂䡁䅁兙畂䡁䅫睘䱂䝁䅕入呂䡁䅑兙あ䡁䅍睘㉂䑁䅅䅉潁䑁䅍克畁䡁䅧䅢穂䝁䄰兘䱂䝁䅕入時䙁䅍䅤桂䡁䅑督湁䍁䅅䅊䍂䍁䅑杍穁䅁䅁䅎䅑䝁䅉䅁湁䙁䅳兔䩂䙁䄸睑療䝁䄰䅣桂䝁䄴入時䕁䅳党㕂䙁䅍䅤桂䡁䅑督時䡁䅙免畁䡁䅧䅢穂䝁䄰兘兂䝁䅕杢穂䝁䅫睢畂䍁䄰睔兂䕁䅕村湁䍁䅅䅊䑂䍁䅑李䅁䵁䙷䅁浂䅁䅁睊扂䕁䄰兓時䕁䅍睢瑂䡁䅁兙畂䡁䅫睘䱂䝁䅕入呂䡁䅑兙あ䡁䅍睘㉂䑁䅅䅉潁䑁䅍克畁䡁䅧䅢穂䝁䄰兘䱂䝁䅕入時䙁䅍䅤桂䡁䅑督湁䍁䅅䅊䍂䍁䅑兎祁䅁䅁材䅑䙁䅉䅁䵂䝁䅕杤求䡁䅉党歂䍁䅁杒祂䝁䅕党杁䕁䅍兙穂䝁䅧䅉䝂䝁䅷睢㍂䍁䅷䅉硁䍁䅁兗祂䍁䄴䅉䡂䡁䅉睢㍂䡁䅑䅡杁䍁䅧兊灁䅁䅁杋䅉䝁䅁䅁扂䙁䅍䅕䡂䙁䄸睑療䝁䄰䅣桂䝁䄴入時䕁䅳党㕂䙁䅍䅤桂䡁䅑督時䡁䅙免畁䡁䅧䅢穂䝁䄰兘呂䡁䅕䅣睂䝁䅷党瑂䝁䅕杢あ䝁䅅䅢桁䍁䅑睑歁䑁䅙䅁䥁杂䅁杣䅁䍁䅣睗乂䕁䅫睘䑂䝁䄸兢睂䝁䅅杢㕂䙁䄸睓求䡁䅫睕あ䝁䅅䅤穂䙁䄸杤硁䍁䅁䅋穁䍁䅫杌㑂䝁䅷督瑂䙁䄰睓求䡁䅫睘呂䡁䅑兙あ䡁䅍睊桁䍁䅑兒歁䑁䅉睍㙁䍁䅑兓歁䑁䅉睍䅁䑁䕍䅁䭃䅁䅁睊扂䕁䅍睢睂䡁䅫䅉療䝁䅙䅉呂䙁䅁睒時䕁䅍睢瑂䡁䅁兙畂䡁䅫睘䱂䝁䅕入呂䡁䅑兙あ䡁䅍睘㉂䑁䅉睘畂䝁䅕睤畁䡁䅧䅢穂䝁䄰兘䑂䝁䅅䅣灂䡁䅑兙獂䝁䅫来桂䡁䅑兡療䝁䄴睊桁䍁䅑兒歁䑁䅑杏歁䕁䅯䅊ぁ䅁䅁睓䅣䡁䅉䅁湁䙁䅳兔䩂䙁䄸睑療䝁䄰䅣桂䝁䄴入時䕁䅳党㕂䙁䅍䅤桂䡁䅑督時䡁䅙免杁䍁䅧睍灁䍁䄴䅥獂䡁䅍兢摂䕁䅳党㕂䙁䄸睕あ䝁䅅䅤穂䍁䅣光歁䕁䅕䅊祁䑁䅉杏歁䕁䅫䅊祁䑁䅉䅁硁䅂䅁杗䅁䙁䅳睕兂䕁䅣睘䑂䝁䄸兢睂䝁䅅杢㕂䙁䄸睓求䡁䅫睕あ䝁䅅䅤穂䙁䄸杤祁䍁䄴䅥獂䡁䅍兢摂䕁䅳党㕂䙁䄸睕あ䝁䅅䅤穂䍁䅅䅊䝂䍁䅑兏䅁䡁䜸䅁䕃䅁䅁睊扂䕁䅍睢睂䡁䅫䅉療䝁䅙䅉呂䙁䅁睒時䕁䅍睢瑂䡁䅁兙畂䡁䅫睘䱂䝁䅕入呂䡁䅑兙あ䡁䅍睘㉂䑁䅉睘畂䝁䅕睤畁䡁䅧䅢穂䝁䄰兘䱂䝁䅕入時䙁䅍䅤桂䡁䅑督湁䍁䅅䅊呂䍁䅑兎㑁䑁䅯䅊呂䍁䅑李硁䅁䅁睍䅣䩁䅁䅁湁䙁䅳睕兂䕁䅣睘䑂䝁䄸兢睂䝁䅅杢㕂䙁䄸睓求䡁䅫睕あ䝁䅅䅤穂䙁䄸杤祁䍁䅁免畁䡁䅧䅢穂䝁䄰兘䑂䝁䅅䅣灂䡁䅑兙獂䙁䄸睕あ䡁䅉兤橂䡁䅑兤祂䝁䅕睘呂䡁䅕兢瑂䝁䅅杣㕂䍁䅣光歁䕁䅙䅊硁䑁䅁杏歁䙁䅁䅊硁䑁䅁䅁い杂䅁杇䅁䕁䅫兕時䙁䅑睔啂䕁䅅䅔時䙁䅉兒坂䅁䅁兂䅁䝁䅉䅁扂䕁䅳党㕂䙁䅍䅤桂䡁䅑督時䡁䅑党穂䡁䅑杚灂䝁䅷党畁䡁䅧䅢穂䝁䄰兘䑂䝁䅅䅣灂䡁䅑兙獂䝁䅫来桂䡁䅑兡療䝁䄴光歁䕁䅙䅊ぁ䑁䅯䅊剂䍁䅑䅎䅁䵁䅙䅁畂䅁䅁睊扂䕁䄰兓時䕁䅍睢瑂䡁䅁兙畂䡁䅫睘䱂䝁䅕入呂䡁䅑兙あ䡁䅍睘㉂䑁䅅睘畁䡁䅧䅢穂䝁䄰兘兂䝁䅕杢穂䝁䅫睢畂䍁䄰睔兂䕁䅕村湁䍁䅅䅊䕂䍁䅑䅎㙁䍁䅑兓歁䑁䅑䅁䍁兂䅁䅘䅁䙁䅳兔䩂䙁䄸睑療䝁䄰䅣桂䝁䄴入時䕁䅳党㕂䙁䅍䅤桂䡁䅑督時䡁䅙免畁䡁䅧䅢穂䝁䄰兘卂䝁䅅䅤灂䝁䄸督桁䍁䅑䅒歁䑁䅙杏歁䕁䅫䅊㉁䅁䅁典䅕䙁䅙䅁扂䙁䅍䅕䡂䙁䄸睑療䝁䄰䅣桂䝁䄴入時䕁䅳党㕂䙁䅍䅤桂䡁䅑督時䡁䅙杍畁䡁䅧䅢穂䝁䄰兘呂䝁䅧党求䡁䅑免桁䍁䅑村歁䑁䅣兎䅁䱁䝉䅁浂䅁䅁睊扂䕁䄰兓時䕁䅍睢瑂䡁䅁兙畂䡁䅫睘䱂䝁䅕入呂䡁䅑兙あ䡁䅍睘㉂䑁䅅䅉潁䑁䅍克畁䡁䅧䅢穂䝁䄰兘䱂䝁䅕入時䙁䅍䅤桂䡁䅑督湁䍁䅅䅊䍂䍁䅑兎㕁䅁䅁村䅑䝁䄴䅁湁䙁䅳兔䩂䙁䄸睑療䝁䄰䅣桂䝁䄴入時䕁䅳党㕂䙁䅍䅤桂䡁䅑督時䡁䅙免瑁䕁䅍睢睂䡁䅫杌㑂䝁䅷督瑂䙁䄰杕桂䡁䅑兡療䡁䅍睊桁䍁䅑睑歁䑁䅫杏歁䕁䅍䅊硁䑁䅕䅍䅁䥁䙯䅁捃䅁䅁睊扂䕁䅍睢睂䡁䅫䅉療䝁䅙䅉呂䙁䅁睒時䕁䅍睢瑂䡁䅁兙畂䡁䅫睘䱂䝁䅕入呂䡁䅑兙あ䡁䅍睘㉂䑁䅉睘畂䝁䅕睤畁䡁䅧䅢穂䝁䄰兘䑂䝁䅅䅣灂䡁䅑兙獂䙁䄸睕あ䡁䅉兤橂䡁䅑兤祂䝁䅕睘杁䕁䅑党あ䝁䅅兡獂䡁䅍䅉湁䍁䅅䅊䡂䍁䅑免祁䅁䅁䅥䅣䑁䅁䅁䩂䙁䅅睘噂䙁䅍睘䡂䕁䅅兑兂䙁䄸䅖偂䙁䅑兑䵂䙁䄸兒剂䙁䅕兓啂䙁䅫䅁䝄杁䅁杣䅁䍁䅣睗乂䕁䅫睘䑂䝁䄸兢睂䝁䅅杢㕂䙁䄸睓求䡁䅫睕あ䝁䅅䅤穂䙁䄸杤硁䍁䅁䅋穁䍁䅫杌㑂䝁䅷督瑂䙁䄰睓求䡁䅫睘呂䡁䅑兙あ䡁䅍睊桁䍁䅑兒歁䑁䅉杍㙁䍁䅑䅔歁䑁䅉杍䅁䑁䕯䅁浂䅁䅁睊扂䕁䄰兓時䕁䅍睢瑂䡁䅁兙畂䡁䅫睘䱂䝁䅕入呂䡁䅑兙あ䡁䅍睘㉂䑁䅅䅉潁䑁䅍克畁䡁䅧䅢穂䝁䄰兘䱂䝁䅕入時䙁䅍䅤桂䡁䅑督湁䍁䅅䅊䙂䍁䅑李睁䅁䅁兒䅑䕁䅯䅁扂䕁䅳党㕂䙁䅍䅤桂䡁䅑督時䡁䅑党穂䡁䅑杚灂䝁䅷党畁䡁䅧䅢穂䡁䅧兘呂䝁䅧党求䡁䅑免桁䍁䅑兒歁䑁䅉䅍䅁䍁䄴䅁䥃䅁䅁睊扂䙁䅍䅕䡂䙁䄸睑療䝁䄰䅣桂䝁䄴入時䕁䅳党㕂䙁䅍䅤桂䡁䅑督時䡁䅙杍杁䑁䅅杌㑂䝁䅷督瑂䙁䄰睑桂䡁䅁兡あ䝁䅅䅢時䙁䅍䅤祂䡁䅕睙あ䡁䅕杣求䙁䄸䅉䕂䝁䅕䅤桂䝁䅫䅢穂䍁䅁睊桁䍁䅑杒歁䑁䅣李䅁䍁䡅䅁䥃䅁䅁睊扂䙁䅍䅕䡂䙁䄸睑療䝁䄰䅣桂䝁䄴入時䕁䅳党㕂䙁䅍䅤桂䡁䅑督時䡁䅙杍杁䑁䅅杌㑂䝁䅷督瑂䙁䄰睑桂䡁䅁兡あ䝁䅅䅢時䙁䅍䅤祂䡁䅕睙あ䡁䅕杣求䙁䄸䅉䕂䝁䅕䅤桂䝁䅫䅢穂䍁䅁睊桁䍁䅑睒歁䑁䅑䅎䅁䉁䡫䅁祂䅁䅁睊扂䕁䄰兓時䕁䅍睢瑂䡁䅁兙畂䡁䅫睘䱂䝁䅕入呂䡁䅑兙あ䡁䅍睘㉂䑁䅅䅉潁䑁䅍克畁䡁䅧䅢穂䝁䄰兘䱂䝁䅕入時䙁䅍䅤桂䡁䅑督湁䍁䅅䅊䑂䍁䅑兎ぁ䑁䅯䅊䑂䍁䅑兎ㅁ䅁䅁䅑䅑䡁䅉䅁偂䡁䅁䅤灂䝁䄸杢穂䍁䅁睔ㅂ䡁䅑杌杁䝁䅅䅤杁䡁䅑䅡求䍁䅁兒畂䝁䅑䅉療䝁䅙䅉兂䝁䅕杣灂䝁䄸䅚獁䍁䅁睑療䝁䄰兢療䝁䄴䅉呂䡁䅑睢橂䝁䅳䅉潁䝁䅅睙あ䡁䅕兙獂䍁䅫䅁㝁睁䅁杭䅁䕁䄸䅣あ䝁䅫睢畂䡁䅍杏杁䕁䅍兤祂䡁䅉児噂䙁䅍䅒獁䍁䅁兔桂䝁䅣児啂䝁䅧睢ㅂ䡁䅍兙畂䝁䅑督獁䕁䅍睢畂䡁䅙兔求䡁䅑䅡療䝁䅑児乂䕁䅫杣求䝁䅍睢瑂䝁䄰党畂䝁䅑党歂䍁䅷䅉佂䕁䅅児佂䕁䅅䅌杁䙁䅑党祂䝁䄰児求䝁䄴兌噂䙁䅍䅁权䅂䅁䅕䅁䕁䅫兕時䕁䄰兑奂䙁䄸兗卂䙁䄸杒偂䙁䅉睘啂䕁䅅䅗時䕁䅉兒佂䕁䅕杒䩂䙁䅑睘䑂䕁䅅杕卂䙁䅫睘䝂䕁䄸杕塂䕁䅅杕䕂䅁䅁䅁䅍䡁䅉䅁湁䙁䅳兔䩂䙁䄸睑療䝁䄰䅣桂䝁䄴入時䕁䅳党㕂䙁䅍䅤桂䡁䅑督時䡁䅙免杁䍁䅧睍灁䍁䄴䅥獂䡁䅍兢摂䕁䅳党㕂䙁䄸睕あ䝁䅅䅤穂䍁䅣光歁䕁䅍䅊㉁䑁䅅杏歁䕁䅍䅊㉁䑁䅣䅁䕂䅂䅁杌䅁䕁䅫兕時䕁䄴䅕兂䕁䅕睘硁䙁䅫杕時䕁䅅杔佂䙁䄸睒卂䕁䄸睖啂䕁䅧䅁婁杁䅁杓䅁䕁䅙兙灂䡁䅉䅉坂䝁䅅䅢ㅂ䝁䅕䅉療䝁䅙䅉䵂䝁䅫兙楂䝁䅫䅢灂䡁䅑兡求䡁䅍䅉潁䙁䅉党睂䝁䄸杣あ䝁䅕䅚灁䅁䅁睊䅍䥁䅉䅁扂䕁䄰兓時䕁䅍睢瑂䡁䅁兙畂䡁䅫睘䱂䝁䅕入呂䡁䅑兙あ䡁䅍睘㉂䑁䅅杌㑂䝁䅷督瑂䙁䄰睑桂䡁䅁兡あ䝁䅅䅢時䙁䅍䅤祂䡁䅕睙あ䡁䅕杣求䙁䄸睕ㅂ䝁䄰兢桂䡁䅉入桁䍁䅑杒歁䑁䅧杏歁䙁䅁䅊㑁䅁䅁光䅑䡁䅁䅁湁䙁䅳睕兂䕁䅣睘䑂䝁䄸兢睂䝁䅅杢㕂䙁䄸睓求䡁䅫睕あ䝁䅅䅤穂䙁䄸杤硁䍁䅁䅋祁䍁䅫杌㑂䝁䅷督瑂䙁䄰睑桂䡁䅍䅡時䕁䅙䅢療䡁䅣睊桁䍁䅑兒歁䑁䅙杏歁䙁䅁䅊㉁䅁䅁兌䅙䙁䅙䅁扂䙁䅍䅕䡂䙁䄸睑療䝁䄰䅣桂䝁䄴入時䕁䅳党㕂䙁䅍䅤桂䡁䅑督時䡁䅙杍畁䡁䅧䅢穂䝁䄰兘呂䝁䅧党求䡁䅑免桁䍁䅑睒歁䑁䅣兎䅁䱁䝫䅁祂䅁䅁睊扂䕁䄰兓時䕁䅍睢瑂䡁䅁兙畂䡁䅫睘䱂䝁䅕入呂䡁䅑兙あ䡁䅍睘㉂䑁䅅䅉潁䑁䅍克畁䡁䅧䅢穂䝁䄰兘䱂䝁䅕入時䙁䅍䅤桂䡁䅑督湁䍁䅅䅊䕂䍁䅑兎ぁ䑁䅯䅊䕂䍁䅑兎ㅁ䅁䅁兑䅑䡁䅉䅁湁䙁䅳兔䩂䙁䄸睑療䝁䄰䅣桂䝁䄴入時䕁䅳党㕂䙁䅍䅤桂䡁䅑督時䡁䅙免杁䍁䅧睍灁䍁䄴䅥獂䡁䅍兢摂䕁䅳党㕂䙁䄸睕あ䝁䅅䅤穂䍁䅣光歁䕁䅕䅊祁䑁䅍杏歁䕁䅷䅊祁䑁䅍䅁㝁䅂䅁杣䅁䍁䅣睗乂䕁䅫睘䑂䝁䄸兢睂䝁䅅杢㕂䙁䄸睓求䡁䅫睕あ䝁䅅䅤穂䙁䄸杤硁䍁䄰睑療䡁䅁入畁䡁䅧䅢穂䝁䄰兘䑂䝁䅅䅣灂䡁䅑兙獂䝁䅫来桂䡁䅑兡療䝁䄴睊桁䍁䅑睑歁䑁䅕䅍䅁䑁䙉䅁捃䅁䅁睊扂䕁䅍睢睂䡁䅫䅉療䝁䅙䅉呂䙁䅁睒時䕁䅍睢瑂䡁䅁兙畂䡁䅫睘䱂䝁䅕入呂䡁䅑兙あ䡁䅍睘㉂䑁䅉睘畂䝁䅕睤畁䡁䅧䅢穂䝁䄰兘䑂䝁䅅䅣灂䡁䅑兙獂䙁䄸睕あ䡁䅉兤橂䡁䅑兤祂䝁䅕睘杁䕁䅑党あ䝁䅅兡獂䡁䅍䅉湁䍁䅅䅊䍂䍁䅑睎㉁䅁䅁䅨䅣䝁䅙䅁湁䙁䅳兔䩂䙁䄸睑療䝁䄰䅣桂䝁䄴入時䕁䅳党㕂䙁䅍䅤桂䡁䅑督時䡁䅙免杁䍁䅧睍灁䍁䄴䅥獂䡁䅍兢摂䕁䅳党㕂䙁䄸睕あ䝁䅅䅤穂䍁䅣光歁䕁䅕䅊ㅁ䑁䅫䅁䑂䅂䅁杣䅁䍁䅣睗乂䕁䅫睘䑂䝁䄸兢睂䝁䅅杢㕂䙁䄸睓求䡁䅫睕あ䝁䅅䅤穂䙁䄸杤硁䍁䅁䅋穁䍁䅫杌㑂䝁䅷督瑂䙁䄰睓求䡁䅫睘呂䡁䅑兙あ䡁䅍睊桁䍁䅑杓歁䑁䅉杍㙁䍁䅑䅔歁䑁䅉杍䅁䑁䕕䅁潁䅁䅁兓剂䙁䄸杗䙂䙁䅉睔時䕁䅍睔噂䙁䅁睔佂䙁䄸䅒䙂䕁䅉䅖䅁䕁䉷䅁捂䅁䅁睗䱂䝁䅕入呂䡁䅑兙あ䡁䅍睘あ䝁䅕督あ䝁䅙兡獂䝁䅕杌㑂䝁䅷督瑂䙁䄰睓求䡁䅫睘呂䡁䅑兙あ䡁䅍光歁䕁䅍䅊ㅁ䑁䅕杏歁䕁䅍䅊ㅁ䑁䅙䅁楃䅁䅁䅨䅁䍁䅣睗䑂䝁䄸䅣㕂䍁䅁睢浂䍁䅁睕兂䕁䅣睘䑂䝁䄸兢睂䝁䅅杢㕂䙁䄸睓求䡁䅫睕あ䝁䅅䅤穂䙁䄸杤硁䙁䄸杒灂䝁䄴兙獂䍁䄴䅥獂䡁䅍兢摂䙁䅉兙あ䝁䅫睢穂䍁䅣光歁䕁䅍䅊硁䑁䅅杏歁䕁䅍䅊硁䑁䅕睎䅁䝁䤸䅁㑁䅁䅁兓剂䙁䄸兑䑂䕁䅍䅖時䙁䅉兒䑂䙁䅙睘硁䙁䅫杕時䕁䅅杔佂䙁䄸睒卂䕁䄸睖啂䕁䅧䅁晁杁䅁杆䅁䑁䅁睍癁䑁䅉兏癁䑁䅉䅍硁䑁䅫䅁時䅁䅁杣䅁䍁䅣睗乂䕁䅫睘䑂䝁䄸兢睂䝁䅅杢㕂䙁䄸睓求䡁䅫睕あ䝁䅅䅤穂䙁䄸杤硁䍁䅁䅋穁䍁䅫杌㑂䝁䅷督瑂䙁䄰睓求䡁䅫睘呂䡁䅑兙あ䡁䅍睊桁䍁䅑杓歁䑁䅉杍㙁䍁䅑睔歁䑁䅉杍䅁䑁䕧䅁敂䅁䅁睊扂䕁䄰兓時䕁䅍睢瑂䡁䅁兙畂䡁䅫睘䱂䝁䅕入呂䡁䅑兙あ䡁䅍睘㉂䑁䅅䅉潁䑁䅍克畁䡁䅧䅢穂䝁䄰兘卂䝁䅅䅤灂䝁䄸督湁䍁䅅䅊䑂䍁䅑䅎䅁䝁䕯䅁楂䅁䅁睗䱂䝁䅕入呂䡁䅑兙あ䡁䅍睘あ䝁䅕督あ䝁䅙兡獂䝁䅕杌㑂䝁䅷督瑂䙁䄰睑桂䡁䅁兡あ䝁䅅䅢灂䡁䅯兙あ䝁䅫睢畂䍁䅅䅊䝂䍁䅑䅎㙁䍁䅑睓歁䑁䅑䅁偄䅁䅁䅐䅁䕁䅍睢瑂䝁䄰睢畂䍁䅁兒硂䡁䅕兡あ䡁䅫䅌杁䑁䅍䅉婂䡁䅉杌杁䕁䅍兑䡂䙁䅉䅉潁䍁䅕克䅁䡁䌴䅁㑂䅁䅁睊扂䕁䄰兓時䕁䅍睢瑂䡁䅁兙畂䡁䅫睘䱂䝁䅕入呂䡁䅑兙あ䡁䅍睘㉂䑁䅅兌䑂䝁䄸䅣㕂䍁䄴䅥獂䡁䅍兢摂䕁䅳党㕂䙁䄸睕あ䝁䅅䅤穂䍁䅣光歁䕁䅍䅊硁䑁䅅䅍㙁䍁䅑睑歁䑁䅅免ぁ䅁䅁杊䅕䥁䅁䅁湁䙁䅳睑療䡁䅁入杁䝁䄸杚杁䙁䅍䅕䡂䙁䄸睑療䝁䄰䅣桂䝁䄴入時䕁䅳党㕂䙁䅍䅤桂䡁䅑督時䡁䅙免時䕁䅙兡畂䝁䅅䅢畁䡁䅧䅢穂䝁䄰兘兂䝁䅕杢穂䝁䅫睢畂䍁䄰睔兂䕁䅕村湁䍁䅅䅊䑂䍁䅑李䅁䩁䥣䅁獁䅁䅁兓剂䙁䄸䅖䉂䙁䅧睘䍂䕁䅕杔䙂䕁䅙兓啂䙁䄸睑䝂䙁䄸兎婂䙁䅉䅁㡄杁䅁杓䅁䙁䅳兔䩂䙁䄸睓求䡁䅫睕あ䝁䅅䅤穂䙁䄸杤硁䍁䄴䅥獂䡁䅍兢摂䕁䅳党㕂䙁䄸睕あ䝁䅅䅤穂䍁䅅䅊䍂䍁䅑兎㕁䅁䅁兣䅍䡁䅉䅁湁䙁䅳兔䩂䙁䄸睑療䝁䄰䅣桂䝁䄴入時䕁䅳党㕂䙁䅍䅤桂䡁䅑督時䡁䅙免杁䍁䅧睍灁䍁䄴䅥獂䡁䅍兢摂䕁䅳党㕂䙁䄸睕あ䝁䅅䅤穂䍁䅣光歁䕁䅯䅊祁䑁䅍杏歁䕁䅷䅊祁䑁䅍䅁㍁䅂䅁䅙䅁䍁䅣睗呂䙁䅁睒時䕁䅍睢瑂䡁䅁兙畂䡁䅫睘䱂䝁䅕入呂䡁䅑兙あ䡁䅍睘㉂䑁䅅䅉潁䑁䅉克畁䡁䅧䅢穂䝁䄰兘卂䝁䅅䅤灂䝁䄸督湁䍁䅅䅊䑂䍁䅑李䅁䕁䝑䅁祂䅁䅁睊扂䕁䄰兓時䕁䅍睢瑂䡁䅁兙畂䡁䅫睘䱂䝁䅕入呂䡁䅑兙あ䡁䅍睘㉂䑁䅅䅉潁䑁䅍克畁䡁䅧䅢穂䝁䄰兘䱂䝁䅕入時䙁䅍䅤桂䡁䅑督湁䍁䅅䅊䭂䍁䅑杍穁䑁䅯䅊偂䍁䅑杍穁䅁䅁兏䅑䡁䅉䅁湁䙁䅳兔䩂䙁䄸睑療䝁䄰䅣桂䝁䄴入時䕁䅳党㕂䙁䅍䅤桂䡁䅑督時䡁䅙免杁䍁䅧睍灁䍁䄴䅥獂䡁䅍兢摂䕁䅳党㕂䙁䄸睕あ䝁䅅䅤穂䍁䅣光歁䕁䄰䅊祁䑁䅉杏歁䕁䄸䅊祁䑁䅉䅁㡁䅂䅁杄䅁䕁䅫村乂䍁䄰兖呂䅁䅁䅭䅕䕁䅙䅁坂䝁䅅杣灂䝁䅅杙獂䝁䅕䅉卂䝁䅅䅤求䍁䅁䅒求䝁䅉䅤癁䍁䅁䅖療䡁䅑兙獂䍁䅁䅒求䝁䅉䅤杁䍁䅧兊灁䅁䅁睡䅅䡁䅉䅁湁䙁䅳兔䩂䙁䄸睑療䝁䄰䅣桂䝁䄴入時䕁䅳党㕂䙁䅍䅤桂䡁䅑督時䡁䅙免杁䍁䅧睍灁䍁䄴䅥獂䡁䅍兢摂䕁䅳党㕂䙁䄸睕あ䝁䅅䅤穂䍁䅣光歁䕁䄰䅊祁䑁䅍杏歁䕁䄸䅊祁䑁䅍䅁㥁䅂䅁杍䅁䕁䅫兕時䙁䅑睔啂䕁䅅䅔時䙁䅍兖䍂䙁䄸䅒䙂䕁䅉䅖時䕁䅕村䩂䙁䅑䅒䉂䅁䅁兪䅅䙁䄴䅁扂䕁䄰兓時䕁䅳党㕂䙁䅍䅤桂䡁䅑督時䡁䅙免畁䡁䅧䅢穂䝁䄰兘䑂䝁䅅䅣灂䡁䅑兙獂䝁䅫来桂䡁䅑兡療䝁䄴光歁䕁䅍䅊㕁䑁䅯䅊䑂䍁䅑杍ㅁ䅁䅁睮䅍䅁䄴䅁祁䑁䅣免ぁ䑁䅙䅏䅁䉁䄴䅁慂䅁䅁睗乂䕁䅫睘䑂䝁䄸兢睂䝁䅅杢㕂䙁䄸睓求䡁䅫睕あ䝁䅅䅤穂䙁䄸杤硁䍁䄴䅥獂䡁䅍兢摂䕁䅳党㕂䙁䄸睕あ䝁䅅䅤穂䍁䅅䅊䙂䍁䅑兎㕁䅁䅁允䅑䑁䅯䅁偂䡁䅁䅤灂䝁䄸杢穂䑁䅯睕あ䝁䅅䅤灂䡁䅍䅤灂䝁䅍児䥂䕁䅫睒䥂䍁䅷杔䉂䑁䄰杔䉂䅁䅁朰䅣䑁䅉䅁䩂䙁䅅睘䥂䕁䅕䅒䡂䕁䅫杔䡂䙁䄸兑佂䕁䅑睘䕂䕁䅕杕䩂䙁䅙睘䉂䕁䅑杓䅁䕁䈴䅁煂䅁䅁睊扂䕁䄰兓時䕁䅍睢瑂䡁䅁兙畂䡁䅫睘䱂䝁䅕入呂䡁䅑兙あ䡁䅍睘㉂䑁䅅䅉潁䑁䅍克畁䡁䅧䅢穂䝁䄰兘兂䝁䅕杢穂䝁䅫睢畂䍁䄰睔兂䕁䅕村湁䍁䅅䅊䑂䍁䅑䅎䅁䡁䕉䅁㑂䅁䅁睊扂䕁䄰兓時䕁䅍睢瑂䡁䅁兙畂䡁䅫睘䱂䝁䅕入呂䡁䅑兙あ䡁䅍睘㉂䑁䅅䅉潁䑁䅍克畁䡁䅧䅢穂䝁䄰兘兂䝁䅕杢穂䝁䅫睢畂䍁䄰睔兂䕁䅕村湁䍁䅅䅊䑂䍁䅑兏㙁䍁䅑睑歁䑁䅕李㑁䅁䅁䅤䅑䡁䄴䅁湁䙁䅳兔䩂䙁䄸睑療䝁䄰䅣桂䝁䄴入時䕁䅳党㕂䙁䅍䅤桂䡁䅑督時䡁䅙免杁䍁䄰䅢桂䡁䅑党穂䡁䅑杌㑂䝁䅷督瑂䙁䄰睓求䡁䅫睘呂䡁䅑兙あ䡁䅍睊桁䍁䅑兒歁䑁䅅䅍ㅁ䑁䅯䅊䡂䍁䅑免睁䑁䅕䅁晁兂䅁条䅁䙁䅳兔䩂䙁䄸睑療䝁䄰䅣桂䝁䄴入時䕁䅳党㕂䙁䅍䅤桂䡁䅑督時䡁䅙免畁䡁䅧䅢穂䝁䄰兘䱂䝁䅕入時䙁䅍䅤桂䡁䅑督桁䍁䅑睑歁䑁䅅䅍㕁䑁䅯䅊䑂䍁䅑免硁䑁䅑䅁㍂兂䅁䅅䅁䕁䅙兕ぁ䑁䅉䅍祁䑁䅕䅁瑃䅃䅁杉䅁䕁䅫兕時䕁䅕䅗兂䕁䅷睔卂䕁䅕睘䕂䙁䅉兓䵂䕁䅷䅁潃䅁䅁杦䅁䍁䅣睗乂䕁䅫睘䑂䝁䄸兢睂䝁䅅杢㕂䙁䄸睓求䡁䅫睕あ䝁䅅䅤穂䙁䄸杤硁䍁䄰䅉偂䡁䅉兡湂䝁䅫杢桂䝁䅷杌㑂䝁䅷督瑂䙁䄰睓求䡁䅫睘呂䡁䅑兙あ䡁䅍睊桁䍁䅑兒歁䑁䅉杍㙁䍁䅑杓歁䑁䅉杍䅁䝁䙅䅁あ䅁䅁睊扂䕁䄰兓時䕁䅍睢瑂䡁䅁兙畂䡁䅫睘䱂䝁䅕入呂䡁䅑兙あ䡁䅍睘㉂䑁䅅䅉潁䑁䅍克畁䡁䅧䅢穂䝁䄰兘兂䝁䅕杢穂䝁䅫睢畂䍁䄰睔兂䕁䅕村湁䍁䅅䅊䕂䍁䅑䅎㙁䍁䅑兓歁䑁䅑䅁穂䅂䅁䅌䅁䕁䄴党あ䍁䅁兓畂䝁䅍睢瑂䝁䅕䅉乂䝁䅅杣湂䝁䅫杢杁䍁䅧兊灁䅁䅁䅄䅉䝁䅑䅁扂䙁䅍䅕䡂䙁䄸睑療䝁䄰䅣桂䝁䄴入時䕁䅳党㕂䙁䅍䅤桂䡁䅑督時䡁䅙杍畁䡁䅧䅢穂䝁䄰兘卂䝁䅅䅤灂䝁䄸督桁䍁䅑睑歁䑁䅅免㙁䍁䅑睑歁䑁䅅兎㍁䅁䅁䅄䅧䩁䅷䅁湁䙁䅳睑療䡁䅁入杁䝁䄸杚杁䙁䅍䅕䡂䙁䄸睑療䝁䄰䅣桂䝁䄴入時䕁䅳党㕂䙁䅍䅤桂䡁䅑督時䡁䅙杍時䝁䄴党㍂䍁䄴䅥獂䡁䅍兢摂䕁䅍兙睂䝁䅫䅤桂䝁䅷睘呂䡁䅑杣ㅂ䝁䅍䅤ㅂ䡁䅉党時䍁䅁䅒求䡁䅑兙灂䝁䅷督杁䍁䅣光歁䕁䅧䅊㍁䑁䅙䅁䭃睂䅁䅤䅁䍁䅣睗乂䕁䅫睘䑂䝁䄸兢睂䝁䅅杢㕂䙁䄸睓求䡁䅫睕あ䝁䅅䅤穂䙁䄸杤硁䍁䅁䅋穁䍁䅫杌㑂䝁䅷督瑂䙁䄰䅕求䝁䄴督灂䝁䄸杢瑁䕁䄸䅕䙂䕁䅉睊桁䍁䅑䅒歁䑁䅕杏歁䕁䅫䅊ㅁ䅁䅁兤䅑䡁䅧䅁湁䙁䅳兔䩂䙁䄸睑療䝁䄰䅣桂䝁䄴入時䕁䅳党㕂䙁䅍䅤桂䡁䅑督時䡁䅙免瑁䕁䅍睢睂䡁䅫杌㑂䝁䅷督瑂䙁䄰睓求䡁䅫睘呂䡁䅑兙あ䡁䅍睊桁䍁䅑睑歁䑁䅅䅍㕁䑁䅯䅊䑂䍁䅑免硁䑁䅑䅁乂兂䅁䅈䅁䙁䅍䅕瑁䙁䅍䅓䉂䙁䅉兒呂䙁䄸睔噂䙁䅑䅁㍃睂䅁杈䅁䕁䅫兕時䕁䄸䅔時䕁䅍睔乂䕁䄰睘䑂䙁䅫睍䅁䱁䈰䅁㡁䅁䅁兑㉂䝁䅕杣桂䝁䅣党杁䕁䅫杢あ䝁䅕杣求䡁䅍䅤杁䙁䅉兙あ䝁䅕䅉牁䍁䅁免杁䍁䅧兊灁䅁䅁朶䅅䡁䅉䅁扂䕁䄰兓時䕁䅳党㕂䙁䅍䅤桂䡁䅑督時䡁䅙免畁䡁䅧䅢穂䝁䄰兘䑂䝁䅅䅣灂䡁䅑兙獂䙁䄸睕あ䡁䅉兤橂䡁䅑兤祂䝁䅕睘呂䡁䅕兢瑂䝁䅅杣㕂䍁䅅䅊䝂䍁䅑兏㙁䍁䅑䅕歁䑁䅫䅁癄睁䅁䅢䅁䍁䅣睗乂䕁䅫睘䑂䝁䄸兢睂䝁䅅杢㕂䙁䄸睓求䡁䅫睕あ䝁䅅䅤穂䙁䄸杤硁䍁䅁䅋穁䍁䅫杌㑂䝁䅷督瑂䙁䄰杕桂䡁䅑兡療䡁䅍睊桁䍁䅑睑歁䑁䅫杏歁䕁䅍䅊硁䑁䅕䅍䅁䝁䕷䅁潂䅁䅁睊扂䕁䄰兓時䕁䅍睢瑂䡁䅁兙畂䡁䅫睘䱂䝁䅕入呂䡁䅑兙あ䡁䅍睘㉂䑁䅅䅉潁䑁䅍克畁䡁䅧䅢穂䝁䄰兘卂䝁䅅䅤灂䝁䄸督湁䍁䅅䅊䕂䍁䅑䅎㙁䍁䅑兓歁䑁䅑䅁牂䅂䅁䅑䅁䕁䅫兕時䕁䄰兑奂䙁䄸兗卂䙁䄸杒偂䙁䅉睘佂䕁䄸䅔時䕁䅍兑卂䙁䅉兗時䕁䅙睔卂䙁䅣兑卂䕁䅑䅁潄杁䅁䅩䅁䙁䅳睕兂䕁䅣睘䑂䝁䄸兢睂䝁䅅杢㕂䙁䄸睓求䡁䅫睕あ䝁䅅䅤穂䙁䄸杤硁䍁䄴䅥獂䡁䅍兢摂䕁䅍兙睂䝁䅫䅤桂䝁䅷睘呂䡁䅑杣ㅂ䝁䅍䅤ㅂ䡁䅉党時䙁䅍兤瑂䝁䄰兙祂䡁䅫光歁䕁䅙䅊硁䑁䅅杏歁䙁䅁䅊硁䑁䅅䅁䑁杂䅁䅦䅁䍁䅣睗乂䕁䅫睘䑂䝁䄸兢睂䝁䅅杢㕂䙁䄸睓求䡁䅫睕あ䝁䅅䅤穂䙁䄸杤硁䍁䄰䅉偂䡁䅉兡湂䝁䅫杢桂䝁䅷杌㑂䝁䅷督瑂䙁䄰睑桂䡁䅁兡あ䝁䅅䅢灂䡁䅯兙あ䝁䅫睢畂䍁䅣光歁䕁䅍䅊ぁ䑁䅧䅁㡁兂䅁杂䅁䑁䅅䅍䅁䱁䜴䅁睁䅁䅁兓剂䙁䄸䅖偂䙁䅑兑䵂䙁䄸睔兂䙁䅑兓偂䕁䄴睕時䕁䅕杔䕂䙁䄸睔呂䅁䅁䅓䅍䩁䅁䅁湁䙁䅳睑療䡁䅁入杁䝁䄸杚杁䙁䅍䅕䡂䙁䄸睑療䝁䄰䅣桂䝁䄴入時䕁䅳党㕂䙁䅍䅤桂䡁䅑督時䡁䅙免時䕁䅙兡畂䝁䅅䅢畁䡁䅧䅢穂䝁䄰兘兂䝁䅕杢穂䝁䅫睢畂䍁䄰睔兂䕁䅕村湁䍁䅅䅊䑂䍁䅑免祁䑁䅯䅊䑂䍁䅑兎㍁䑁䅙䅁灃䅃䅁䅡䅁䍁䅣睗乂䕁䅫睘䑂䝁䄸兢睂䝁䅅杢㕂䙁䄸睓求䡁䅫睕あ䝁䅅䅤穂䙁䄸杤硁䍁䅁䅋穁䍁䅫杌㑂䝁䅷督瑂䙁䄰杕桂䡁䅑兡療䡁䅍睊桁䍁䅑䅒歁䑁䅕杏歁䕁䅫䅊ㅁ䅁䅁兢䅑䑁䅁䅁䩂䙁䅅睘䕂䕁䅍睕時䕁䅉睔佂䕁䅑睘䑂䕁䄸兖兂䕁䄸杔時䙁䅑兗兂䕁䅕䅁啃杂䅁䅩䅁䍁䅣睗乂䕁䅫睘䑂䝁䄸兢睂䝁䅅杢㕂䙁䄸睓求䡁䅫睕あ䝁䅅䅤穂䙁䄸杤硁䍁䄰䅉偂䡁䅉兡湂䝁䅫杢桂䝁䅷杌㑂䝁䅷督瑂䙁䄰睑桂䡁䅁兡あ䝁䅅䅢灂䡁䅯兙あ䝁䅫睢畂䍁䅣光歁䕁䅕䅊ㅁ䑁䅉杏歁䕁䅯䅊ㅁ䑁䅉䅁䑂兂䅁条䅁䍁䅣睗乂䕁䅫睘䑂䝁䄸兢睂䝁䅅杢㕂䙁䄸睓求䡁䅫睕あ䝁䅅䅤穂䙁䄸杤硁䍁䅁䅋穁䍁䅫杌㑂䝁䅷督瑂䙁䄰睕ㅂ䡁䅁䅣獂䝁䅕兢求䝁䄴䅤桂䝁䅷睊桁䍁䅑睑歁䑁䅑䅁畂䅂䅁䅥䅁䍁䅣睗乂䕁䅫睘䑂䝁䄸兢睂䝁䅅杢㕂䙁䄸睓求䡁䅫睕あ䝁䅅䅤穂䙁䄸杤硁䍁䅁䅋穁䍁䅫杌㑂䝁䅷督瑂䙁䄰睕ㅂ䡁䅁䅣獂䝁䅕兢求䝁䄴䅤桂䝁䅷睊桁䍁䅑睑歁䑁䅫杏歁䕁䅍䅊硁䑁䅙䅎䅁䡁䕁䅁獁䅁䅁兓剂䙁䄸睖䉂䙁䅉杕䉂䕁䄴䅖呂䙁䄸兒奂䕁䅕杕䑂䕁䅫睕䙂䕁䅑䅁佂睁䅁䅈䅁䕁䅫兕時䕁䄸䅖䥂䕁䅕杕時䕁䄸䅕䙂䙁䅉䅁㉃䅁䅁杋䅁䕁䅫兕時䕁䅷䅖䕂䙁䄸䅒噂䕁䅕睘佂䕁䅕䅗啂䙁䄸杒䩂䙁䅙兒䅁䭁䉣䅁あ䅁䅁睊扂䕁䄰兓時䕁䅍睢瑂䡁䅁兙畂䡁䅫睘䱂䝁䅕入呂䡁䅑兙あ䡁䅍睘㉂䑁䅅䅉潁䑁䅍克畁䡁䅧䅢穂䝁䄰兘呂䡁䅕䅣睂䝁䅷党瑂䝁䅕杢あ䝁䅅䅢湁䍁䅅䅊䕂䍁䅑䅎㙁䍁䅑兓歁䑁䅑䅁療䅂䅁䅡䅁䙁䅉党歂䡁䅕睙あ䝁䅫睢畂䡁䅍䅉浂䝁䄸杣杁䙁䅑兙㑂䍁䅁䅕療䡁䅍兡あ䝁䅫睢畂䡁䅍䅉瑁䍁䅁䅕祂䝁䅫睢祂䍁䅁兗祂䡁䅍䅉潁䙁䅉党睂䝁䄸杣あ䝁䅕䅚灁䅁䅁眱䅉䕁䅯䅁扂䕁䅳党㕂䙁䅍䅤桂䡁䅑督時䡁䅑党穂䡁䅑杚灂䝁䅷党畁䡁䅧䅢穂䡁䅧兘呂䝁䅧党求䡁䅑免桁䍁䅑村歁䑁䅉杍䅁䕁䄰䅁⭂䅁䅁睊扂䕁䄰兓時䕁䅍睢瑂䡁䅁兙畂䡁䅫睘䱂䝁䅕入呂䡁䅑兙あ䡁䅍睘㉂䑁䅅兌杁䕁䄸杣灂䝁䅣兡畂䝁䅅䅢畁䡁䅧䅢穂䝁䄰兘䱂䝁䅕入時䙁䅍䅤桂䡁䅑督湁䍁䅅䅊乂䍁䅑杍穁䑁䅯䅊偂䍁䅑杍穁䅁䅁睘䅕䡁䅑䅁湁䙁䅳兔䩂䙁䄸睑療䝁䄰䅣桂䝁䄴入時䕁䅳党㕂䙁䅍䅤桂䡁䅑督時䡁䅙免杁䍁䅧睍灁䍁䄴䅥獂䡁䅍兢摂䙁䅍兤睂䡁䅁䅢求䝁䄰党畂䡁䅑兙獂䍁䅣光歁䕁䅑䅊ㅁ䑁䅯䅊䩂䍁䅑兎䅁䡁䕅䅁あ䅁䅁睊扂䙁䅍䅕䡂䙁䄸睑療䝁䄰䅣桂䝁䄴入時䕁䅳党㕂䙁䅍䅤桂䡁䅑督時䡁䅙杍杁䑁䅅杌㑂䝁䅷督瑂䙁䄰睓求䡁䅫睘呂䡁䅑兙あ䡁䅍睊桁䍁䅑䅒歁䑁䅅䅍㕁䑁䅯䅊䕂䍁䅑免硁䑁䅙䅁䉄杂䅁䅣䅁䍁䅣睗乂䕁䅫睘䑂䝁䄸兢睂䝁䅅杢㕂䙁䄸睓求䡁䅫睕あ䝁䅅䅤穂䙁䄸杤硁䍁䅁兌獂䝁䅅䅤求䡁䅍䅤畁䡁䅧䅢穂䝁䄰兘䱂䝁䅕入時䙁䅍䅤桂䡁䅑督湁䍁䅅䅊䍂䍁䅑免睁䑁䅍䅁捁兂䅁杙䅁䕁䄴党あ䍁䅁䅕祂䝁䄸䅣求䡁䅉䅤㕂䍁䅷䅉兂䝁䅷兙畂䡁䅑䅉桂䝁䄴䅚杁䕁䅕兣ㅂ䝁䅫䅣畁䍁䅷䅉硁䍁䅁兗祂䍁䄴䅉䡂䡁䅉睢㍂䡁䅑䅡杁䍁䅧兊灁䅁䅁杇䅉䙁䅙䅁扂䕁䄰兓時䕁䅳党㕂䙁䅍䅤桂䡁䅑督時䡁䅙免畁䡁䅧䅢穂䝁䄰兘䱂䝁䅕入時䙁䅍䅤桂䡁䅑督桁䍁䅑杓歁䑁䅉杍㙁䍁䅑䅔歁䑁䅉杍䅁䝁䐴䅁畂䅁䅁睊扂䕁䄰兓時䕁䅍睢瑂䡁䅁兙畂䡁䅫睘䱂䝁䅕入呂䡁䅑兙あ䡁䅍睘㉂䑁䅅䅉瑁䝁䅷兙あ䝁䅕督あ䍁䄴䅥獂䡁䅍兢摂䕁䅳党㕂䙁䄸睕あ䝁䅅䅤穂䍁䅣光歁䕁䅉䅊祁䑁䅉䅁䥁兂䅁杗䅁䕁䄸䅣求䡁䅉兙あ䝁䅫杢湂䍁䅁䅔求䝁䅅督求䍁䅁睑療䝁䄰兢灂䡁䅑兢求䝁䄴䅤杁䕁䅑兤求䍁䅁睋穁䍁䅁䅋卂䝁䅕䅣療䡁䅉䅤求䝁䅑克䅁䱁䉷䅁慂䅁䅁睗乂䕁䅫睘䑂䝁䄸兢睂䝁䅅杢㕂䙁䄸睓求䡁䅫睕あ䝁䅅䅤穂䙁䄸杤硁䍁䄴䅥獂䡁䅍兢摂䕁䅳党㕂䙁䄸睕あ䝁䅅䅤穂䍁䅅䅊䍂䍁䅑李硁䅁䅁䅫䅑䡁䅷䅁湁䙁䅳睑療䡁䅁入杁䝁䄸杚杁䙁䅍䅕䡂䙁䄸睑療䝁䄰䅣桂䝁䄴入時䕁䅳党㕂䙁䅍䅤桂䡁䅑督時䡁䅙杍時䝁䄴党㍂䍁䄴䅥獂䡁䅍兢摂䙁䅁党畂䡁䅍兡療䝁䄴兌偂䙁䅁兒䍂䍁䅣光歁䕁䅍䅊㉁䅁䅁杚䅣䥁䅧䅁湁䙁䅳睕兂䕁䅣睘䑂䝁䄸兢睂䝁䅅杢㕂䙁䄸睓求䡁䅫睕あ䝁䅅䅤穂䙁䄸杤祁䍁䅁免畁䡁䅧䅢穂䝁䄰兘䑂䝁䅅䅣灂䡁䅑兙獂䙁䄸睕あ䡁䅉兤橂䡁䅑兤祂䝁䅕睘杁䕁䅑党あ䝁䅅兡獂䡁䅍䅉湁䍁䅅䅊䭂䍁䅑睎㉁䅁䅁䅊䅣䝁䄴䅁湁䙁䅳兔䩂䙁䄸睑療䝁䄰䅣桂䝁䄴入時䕁䅳党㕂䙁䅍䅤桂䡁䅑督時䡁䅙免杁䍁䄰䅢桂䡁䅑党穂䡁䅑杌㑂䝁䅷督瑂䙁䄰睓求䡁䅫睘呂䡁䅑兙あ䡁䅍睊桁䍁䅑村歁䑁䅉睍䅁䉁䙑䅁䥁䅁䅁杔啂䕁䄰䅁剂杂䅁杖䅁䙁䅳兔䩂䙁䄸睓求䡁䅫睕あ䝁䅅䅤穂䙁䄸杤硁䍁䄴䅥獂䡁䅍兢摂䕁䅳党㕂䙁䄸睕あ䝁䅅䅤穂䍁䅅䅊䙂䍁䅑兏㕁䑁䅯䅊䡂䍁䅑兏㕁䅁䅁来䅍䥁䅧䅁湁䙁䅳睑療䡁䅁入杁䝁䄸杚杁䙁䅍䅕䡂䙁䄸睑療䝁䄰䅣桂䝁䄴入時䕁䅳党㕂䙁䅍䅤桂䡁䅑督時䡁䅙杍時䝁䄴党㍂䍁䄴䅥獂䡁䅍兢摂䕁䅳党㕂䙁䄸睕あ䝁䅅䅤穂䍁䅣光歁䕁䅑䅊硁䑁䅁兏㙁䍁䅑䅒歁䑁䅅免㉁䅁䅁䅐䅣䝁䄴䅁湁䙁䅳兔䩂䙁䄸睑療䝁䄰䅣桂䝁䄴入時䕁䅳党㕂䙁䅍䅤桂䡁䅑督時䡁䅙免杁䍁䄰䅢桂䡁䅑党穂䡁䅑杌㑂䝁䅷督瑂䙁䄰睓求䡁䅫睘呂䡁䅑兙あ䡁䅍睊桁䍁䅑村歁䑁䅕兏䅁䅁䙷䅁⭂䅁䅁睊扂䕁䄰兓時䕁䅍睢瑂䡁䅁兙畂䡁䅫睘䱂䝁䅕入呂䡁䅑兙あ䡁䅍睘㉂䑁䅅䅉瑁䝁䅷兙あ䝁䅕督あ䍁䄴䅥獂䡁䅍兢摂䕁䅳党㕂䙁䄸睕あ䝁䅅䅤穂䍁䅣光歁䕁䅍䅊硁䑁䅁睎㙁䍁䅑睑歁䑁䅅免硁䅁䅁杈䅕䡁䅯䅁湁䙁䅳兔䩂䙁䄸睑療䝁䄰䅣桂䝁䄴入時䕁䅳党㕂䙁䅍䅤桂䡁䅑督時䡁䅙免杁䍁䄰䅢桂䡁䅑党穂䡁䅑杌㑂䝁䅷督瑂䙁䄰睓求䡁䅫睘呂䡁䅑兙あ䡁䅍睊桁䍁䅑睑歁䑁䅉兎㙁䍁䅑睑歁䑁䅑兏䅁䅁䙯䅁捂䅁䅁睗乂䕁䅫睘䑂䝁䄸兢睂䝁䅅杢㕂䙁䄸睓求䡁䅫睕あ䝁䅅䅤穂䙁䄸杤硁䍁䄴䅥獂䡁䅍兢摂䕁䅳党㕂䙁䄸睕あ䝁䅅䅤穂䍁䅅䅊䍂䍁䅑免睁䑁䅕䅁奃䅂䅁䅢䅁䍁䅣睗乂䕁䅫睘䑂䝁䄸兢睂䝁䅅杢㕂䙁䄸睓求䡁䅫睕あ䝁䅅䅤穂䙁䄸杤硁䍁䄰睑療䡁䅁入畁䡁䅧䅢穂䝁䄰兘呂䡁䅕䅣睂䝁䅷党瑂䝁䅕杢あ䝁䅅䅢湁䍁䅅䅊䑂䍁䅑䅎䅁䥁䙷䅁㙂䅁䅁睊扂䕁䄰兓時䕁䅍睢瑂䡁䅁兙畂䡁䅫睘䱂䝁䅕入呂䡁䅑兙あ䡁䅍睘㉂䑁䅅䅉瑁䝁䅷兙あ䝁䅕督あ䍁䄴䅥獂䡁䅍兢摂䕁䅳党㕂䙁䄸睕あ䝁䅅䅤穂䍁䅣光歁䕁䅍䅊ㅁ䑁䅑杏歁䕁䅍䅊ㅁ䑁䅕䅁慁兂䅁来䅁䍁䅣睗乂䕁䅫睘䑂䝁䄸兢睂䝁䅅杢㕂䙁䄸睓求䡁䅫睕あ䝁䅅䅤穂䙁䄸杤硁䍁䅁兌獂䝁䅅䅤求䡁䅍䅤畁䡁䅧䅢穂䝁䄰兘䱂䝁䅕入時䙁䅍䅤桂䡁䅑督湁䍁䅅䅊䑂䍁䅑李祁䑁䅯䅊䑂䍁䅑李㑁䅁䅁杄䅕䕁䅧䅁䉂䝁䅍睙療䡁䅕杢あ䡁䅍䅉卂䝁䅕睙求䝁䅫杤桂䝁䅉䅢求䍁䅷䅉ㅁ䍁䅁兗祂䍁䄴䅉䑂䕁䅅睒卂䍁䅁䅋汁䍁䅫䅁䵃杁䅁来䅁䍁䅣睗乂䕁䅫睘䑂䝁䄸兢睂䝁䅅杢㕂䙁䄸睓求䡁䅫睕あ䝁䅅䅤穂䙁䄸杤硁䍁䅁兌獂䝁䅅䅤求䡁䅍䅤畁䡁䅧䅢穂䝁䄰兘䱂䝁䅕入時䙁䅍䅤桂䡁䅑督湁䍁䅅䅊䕂䍁䅑杍ㅁ䑁䅯䅊䕂䍁䅑䅎㕁䅁䅁杆䅕䡁䄴䅁湁䙁䅳兔䩂䙁䄸睑療䝁䄰䅣桂䝁䄴入時䕁䅳党㕂䙁䅍䅤桂䡁䅑督時䡁䅙免杁䍁䄰䅢桂䡁䅑党穂䡁䅑杌㑂䝁䅷督瑂䙁䄰睓求䡁䅫睘呂䡁䅑兙あ䡁䅍睊桁䍁䅑兒歁䑁䅅䅍ぁ䑁䅯䅊䡂䍁䅑免睁䑁䅑䅁摁兂䅁䅊䅁䕁䅫兕時䕁䅑兒䍂䙁䅑睘啂䕁䄸睘䙂䕁䅉兓啂䕁䅑兑䅁䡁䉳䅁㙁䅁䅁睔睂䡁䅑兡療䝁䄴督㙁䍁䅁睕あ䝁䅅䅤灂䡁䅍䅤灂䝁䅍児䵂䕁䄸睖獁䕁䄴兑㥁䕁䄴兑䅁䝁䜰䅁慁䅁䅁兒畂䡁䅑兡あ䡁䅫䅉佂䝁䅅兢求䍁䅁䅁歁䅁䅁来䅁䍁䅣睗乂䕁䅫睘䑂䝁䄸兢睂䝁䅅杢㕂䙁䄸睓求䡁䅫睕あ䝁䅅䅤穂䙁䄸杤硁䍁䅁兌獂䝁䅅䅤求䡁䅍䅤畁䡁䅧䅢穂䝁䄰兘䱂䝁䅕入時䙁䅍䅤桂䡁䅑督湁䍁䅅䅊䙂䍁䅑杍祁䑁䅯䅊䭂䍁䅑杍祁䅁䅁元䅕䝁䅙䅁扂䕁䄰兓時䙁䅉兒䩂䙁䅑睘呂䝁䅅兢求䙁䅍䅤療䡁䅉党啂䝁䅕兢睂䝁䅷兙あ䝁䅕睘㉂䑁䅅杌㑂䝁䅷督摂䕁䅑兙あ䝁䅅光歁䕁䅑䅊硁䑁䅍杏歁䕁䅑䅊祁䑁䅍䅁晄睁䅁来䅁䍁䅣睗乂䕁䅫睘䑂䝁䄸兢睂䝁䅅杢㕂䙁䄸睓求䡁䅫睕あ䝁䅅䅤穂䙁䄸杤硁䍁䅁兌獂䝁䅅䅤求䡁䅍䅤畁䡁䅧䅢穂䝁䄰兘䱂䝁䅕入時䙁䅍䅤桂䡁䅑督湁䍁䅅䅊䙂䍁䅑杍穁䑁䅯䅊䭂䍁䅑杍穁䅁䅁睃䅕䥁䅧䅁湁䙁䅳兔䩂䙁䄸睑療䝁䄰䅣桂䝁䄴入時䕁䅳党㕂䙁䅍䅤桂䡁䅑督時䡁䅙免瑁䍁䅁睔祂䝁䅫睚灂䝁䄴兙獂䍁䄴䅥獂䡁䅍兢摂䕁䅫杢橂䝁䄸兢求䙁䄸睕あ䝁䅅䅤求䝁䄰党畂䡁䅑睊桁䍁䅑兒歁䑁䅕杏歁䙁䅁䅊ㅁ䅁䅁兤䅕䝁䄴䅁湁䙁䅳兔䩂䙁䄸睑療䝁䄰䅣桂䝁䄴入時䕁䅳党㕂䙁䅍䅤桂䡁䅑督時䡁䅙免杁䍁䄰䅢桂䡁䅑党穂䡁䅑杌㑂䝁䅷督瑂䙁䄰睓求䡁䅫睘呂䡁䅑兙あ䡁䅍睊桁䍁䅑兒歁䑁䅕免䅁䉁䙫䅁畂䅁䅁睊扂䕁䄰兓時䕁䅍睢瑂䡁䅁兙畂䡁䅫睘䱂䝁䅕入呂䡁䅑兙あ䡁䅍睘㉂䑁䅅䅉瑁䝁䅷兙あ䝁䅕督あ䍁䄴䅥獂䡁䅍兢摂䕁䅳党㕂䙁䄸睕あ䝁䅅䅤穂䍁䅣光歁䕁䅕䅊ㅁ䑁䅫䅁乁兂䅁䅌䅁䕁䅫兕時䕁䅫杔坂䙁䄸杍婂䙁䅉睘䉂䕁䄴杔時䕁䅣杕偂䙁䅣䅖䥂䅁䅁兕䅉䝁䄴䅁湁䙁䅳兔䩂䙁䄸睑療䝁䄰䅣桂䝁䄴入時䕁䅳党㕂䙁䅍䅤桂䡁䅑督時䡁䅙免杁䍁䄰䅢桂䡁䅑党穂䡁䅑杌㑂䝁䅷督瑂䙁䄰睓求䡁䅫睘呂䡁䅑兙あ䡁䅍睊桁䍁䅑兒歁䑁䅙䅍䅁䅁䘸䅁㑁䅁䅁兓剂䙁䄸睑䉂䙁䅁兓啂䕁䅅䅔時䕁䅷兒䉂䙁䅍兒呂䙁䄸䅖偂䙁䅑兑䵂䙁䄸䅕䑂䙁䅑䅁㙄䅁䅁䅈䅁䙁䅍兤楂䍁䄴䅉䕂䝁䅕杙あ䍁䅁䅋汁䍁䅫䅁灁允䅁材䅁䕁䅣杣療䡁䅍督杁䙁䅁杣療䝁䅙兡あ䍁䅷䅉硁䍁䅁兗祂䍁䄴䅉䡂䡁䅉睢㍂䡁䅑䅡杁䍁䅧兊灁䅁䅁䅈䅉䡁䅯䅁湁䙁䅳兔䩂䙁䄸睑療䝁䄰䅣桂䝁䄴入時䕁䅳党㕂䙁䅍䅤桂䡁䅑督時䡁䅙免杁䍁䄰䅢桂䡁䅑党穂䡁䅑杌㑂䝁䅷督瑂䙁䄰睓求䡁䅫睘呂䡁䅑兙あ䡁䅍睊桁䍁䅑兔歁䑁䅉杍㙁䍁䅑睔歁䑁䅉杍䅁䉁䙕䅁楁䅁䅁兓剂䙁䄸兒䍂䕁䅫䅖䕂䕁䅅睘乂䕁䅅杕䡂䕁䅫杔䅁䅁䍅䅁祁䅁䅁兓剂䙁䄸兒䍂䕁䅫䅖䕂䕁䅅睘ㅁ䙁䅫杕時䕁䅅杔佂䙁䄸睒卂䕁䄸睖啂䕁䅧䅁偃杁䅁杔䅁䙁䅳睓求䡁䅫睕あ䝁䅅䅤穂䙁䄸䅤求䡁䅍䅤浂䝁䅫䅢求䍁䄴䅥獂䡁䅍兢摂䕁䅍兙穂䝁䅧睘䝂䝁䅷睢㍂䍁䅅䅊䑂䍁䅑䅎䅁䱁䄰䅁捂䅁䅁杔偂䕁䅷䅉䑂䝁䅅杣祂䡁䅫杚療䡁䅉睤桂䡁䅉䅚獁䍁䅁睑ㅂ䡁䅉杣求䝁䄴䅤杁䙁䅫党桂䡁䅉䅉牁䍁䅁睍杁䍁䅧杕求䡁䅁睢祂䡁䅑党歂䍁䅫䅁噄杁䅁来䅁䍁䅣睗乂䕁䅫睘䑂䝁䄸兢睂䝁䅅杢㕂䙁䄸睓求䡁䅫睕あ䝁䅅䅤穂䙁䄸杤硁䍁䅁兌獂䝁䅅䅤求䡁䅍䅤畁䡁䅧䅢穂䝁䄰兘䱂䝁䅕入時䙁䅍䅤桂䡁䅑督湁䍁䅅䅊乂䍁䅑杍穁䑁䅯䅊偂䍁䅑杍穁䅁䅁睆䅕䑁䅁䅁䑂䝁䄸兢睂䝁䄸杢求䝁䄴䅤杁䙁䅍党橂䡁䅕杣灂䡁䅑入杁䙁䅑入睂䝁䅕䅁䱃杂䅁䅍䅁䕁䅫兕時䕁䅍兑兂䕁䅕䅗時䑁䅕兗卂䙁䄸兑佂䕁䄴睘䡂䙁䅉睔塂䙁䅑䅓䅁䭁䍣䅁䥂䅁䅁兒桂䡁䅉杢灂䝁䄴睚穂䍁䅁杚祂䝁䄸兢杁䕁䅍睢畂䡁䅑杌杁䕁䄸䅣穂䍁䄴䅉潁䙁䅉党睂䝁䄸杣あ䝁䅕䅚灁䅁䅁兄䅁䝁䅧䅁湁䙁䅳兔䩂䙁䄸睑療䝁䄰䅣桂䝁䄴入時䕁䅳党㕂䙁䅍䅤桂䡁䅑督時䡁䅙免瑁䕁䅍睢睂䡁䅫杌㑂䝁䅷督瑂䙁䄰睓求䡁䅫睘呂䡁䅑兙あ䡁䅍睊桁䍁䅑村歁䑁䅉李䅁䍁䙁䅁䵂䅁䅁杔求䡁䅑䅉䩂䝁䄴睙畁䍁䅁兑㉂䝁䅅兡獂䍁䄴䅉浂䝁䄸杣杁䕁䅍睢瑂䝁䄰睢畂䍁䅁兔桂䡁䅉睚灂䝁䄴䅉潁䍁䅕克䅁䅁䌴䅁浂䅁䅁睗乂䕁䅫睘䑂䝁䄸兢睂䝁䅅杢㕂䙁䄸睓求䡁䅫睕あ䝁䅅䅤穂䙁䄸杤硁䍁䄴䅥獂䡁䅍兢摂䕁䅳党㕂䙁䄸睕あ䝁䅅䅤穂䍁䅅䅊啂䍁䅑兎㑁䑁䅯䅊啂䍁䅑李祁䅁䅁睮䅕䝁䄴䅁湁䙁䅳兔䩂䙁䄸睑療䝁䄰䅣桂䝁䄴入時䕁䅳党㕂䙁䅍䅤桂䡁䅑督時䡁䅙免杁䍁䄰䅢桂䡁䅑党穂䡁䅑杌㑂䝁䅷督瑂䙁䄰睓求䡁䅫睘呂䡁䅑兙あ䡁䅍睊桁䍁䅑兖歁䑁䅉杍䅁䉁䙁䅁㉁䅁䅁兓剂䙁䄸睔兂䙁䅑兓偂䕁䄴睕時䙁䅍䅖卂䕁䅫睓䙂䙁䄸䅕卂䕁䅫睑䙂䙁䄸睔呂䅁䅁䅐䅍䝁䄴䅁湁䙁䅳兔䩂䙁䄸睑療䝁䄰䅣桂䝁䄴入時䕁䅳党㕂䙁䅍䅤桂䡁䅑督時䡁䅙免杁䍁䄰䅢桂䡁䅑党穂䡁䅑杌㑂䝁䅷督瑂䙁䄰睓求䡁䅫睘呂䡁䅑兙あ䡁䅍睊桁䍁䅑兖歁䑁䅉兎䅁䉁䙉䅁卂䅁䅁睑桂䡁䅍䅡杁䍁䅙䅉呂䝁䅧睢祂䡁䅑䅉啂䝁䅕杣瑂䍁䅁兓畂䡁䅙党穂䡁䅑兢求䝁䄴䅤穂䍁䅁䅋卂䝁䅕䅣療䡁䅉䅤求䝁䅑克䅁䉁䅕䅁獂䅁䅁睊扂䙁䅍䅕䡂䙁䄸睑療䝁䄰䅣桂䝁䄴入時䕁䅳党㕂䙁䅍䅤桂䡁䅑督時䡁䅙杍杁䑁䅅杌㑂䝁䅷督瑂䙁䄰睑桂䡁䅍䅡時䕁䅙䅢療䡁䅣睊桁䍁䅑兒歁䑁䅣杏歁䙁䅁䅊㍁䅁䅁朴䅙䝁䄴䅁湁䙁䅳兔䩂䙁䄸睑療䝁䄰䅣桂䝁䄴入時䕁䅳党㕂䙁䅍䅤桂䡁䅑督時䡁䅙免杁䍁䄰䅢桂䡁䅑党穂䡁䅑杌㑂䝁䅷督瑂䙁䄰睓求䡁䅫睘呂䡁䅑兙あ䡁䅍睊桁䍁䅑杖歁䑁䅉杍䅁䉁䙅䅁杂䅁䅁睗乂䕁䅫睘䱂䝁䅕入呂䡁䅑兙あ䡁䅍睘㉂䑁䅅杌㑂䝁䅷督瑂䙁䄰睑桂䡁䅁兡あ䝁䅅䅢灂䡁䅯兙あ䝁䅫睢畂䍁䅅䅊䙂䍁䅑兎祁䑁䅯䅊䭂䍁䅑兎祁䅁䅁䅱䅍䡁䅉䅁扂䙁䅍䅕䡂䙁䄸睑療䝁䄰䅣桂䝁䄴入時䕁䅳党㕂䙁䅍䅤桂䡁䅑督時䡁䅙免畁䡁䅧䅢穂䝁䄰兘䑂䝁䅅䅣灂䡁䅑兙獂䝁䅫来桂䡁䅑兡療䝁䄴光歁䕁䅕䅊ぁ䑁䅣杏歁䕁䅯䅊ぁ䑁䅣䅁㕄兂䅁䅍䅁䕁䅫兕時䙁䅑睔啂䕁䅅䅔時䕁䄸䅕啂䕁䅫睔佂䙁䅍睘䍂䕁䅕睒時䕁䄸睕䅁䑁䐴䅁畂䅁䅁睊扂䕁䄰兓時䕁䅍睢瑂䡁䅁兙畂䡁䅫睘䱂䝁䅕入呂䡁䅑兙あ䡁䅍睘㉂䑁䅅䅉瑁䝁䅷兙あ䝁䅕督あ䍁䄴䅥獂䡁䅍兢摂䕁䅳党㕂䙁䄸睕あ䝁䅅䅤穂䍁䅣光歁䙁䅙䅊祁䑁䅍䅁呁兂䅁䅕䅁䙁䅳睓求䡁䅫睕あ䝁䅅䅤穂䙁䄸䅤求䡁䅍䅤浂䝁䅫䅢求䍁䄴䅥獂䡁䅍兢摂䕁䅳党㕂䙁䄸睕あ䝁䅅䅤穂䍁䅅䅊䍂䍁䅑兎祁䅁䅁兮䅁䑁䅑䅁䩂䙁䅅睘佂䕁䅫睘佂䕁䄸杕乂䙁䄸睍婂䙁䅉睘䉂䕁䄴杔時䕁䅣杕偂䙁䅣䅖䥂䅁䅁睙䅉䑁䅯䅁佂䝁䅕䅤杁䕁䅫杢橂䝁䄸兢求䍁䅷䅉硁䍁䅁兗祂䍁䄴䅉䡂䡁䅉睢㍂䡁䅑䅡杁䍁䅧兊灁䅁䅁杈䅉䡁䅑䅁湁䙁䅳睕兂䕁䅣睘䑂䝁䄸兢睂䝁䅅杢㕂䙁䄸睓求䡁䅫睕あ䝁䅅䅤穂䙁䄸杤祁䍁䅁免畁䡁䅧䅢穂䝁䄰兘䱂䝁䅕入時䙁䅍䅤桂䡁䅑督湁䍁䅅䅊䝂䍁䅑免睁䑁䅣杏歁䕁䅧䅊硁䑁䅁睎䅁乁䝙䅁㙂䅁䅁睊扂䕁䄰兓時䕁䅍睢瑂䡁䅁兙畂䡁䅫睘䱂䝁䅕入呂䡁䅑兙あ䡁䅍睘㉂䑁䅅兌杁䕁䄸杣灂䝁䅣兡畂䝁䅅䅢畁䡁䅧䅢穂䝁䄰兘䑂䝁䅅䅣灂䡁䅑兙獂䝁䅫来桂䡁䅑兡療䝁䄴睊桁䍁䅑睑歁䑁䅑䅁㑁兂䅁杏䅁䕁䅫兕時䕁䅕兑卂䕁䄴兓佂䕁䅣睘䑂䕁䄸睘硁䙁䅫杕時䕁䅅杔佂䙁䄸睒卂䕁䄸睖啂䕁䅧䅁桁杁䅁杚䅁䕁䅅䅚歂䝁䅫䅤灂䝁䄸杢穂䍁䅁杚療䡁䅉䅉啂䝁䅅䅥杁䙁䅁睢穂䝁䅫䅤灂䝁䄸杢穂䍁䅁兌杁䙁䅁杣灂䝁䄸杣杁䙁䅫杣穂䍁䅁䅋卂䝁䅕䅣療䡁䅉䅤求䝁䅑克䅁䅁䑳䅁元䅁䅁睊扂䙁䅍䅕䡂䙁䄸睑療䝁䄰䅣桂䝁䄴入時䕁䅳党㕂䙁䅍䅤桂䡁䅑督時䡁䅙免杁䍁䅧杍灁䍁䄴䅥獂䡁䅍兢摂䕁䅍兙睂䝁䅫䅤桂䝁䅷睘呂䡁䅑杣ㅂ䝁䅍䅤ㅂ䡁䅉党時䙁䅍兤瑂䝁䄰兙祂䡁䅫睊桁䍁䅑兒歁䑁䅣杏歁䕁䄸䅊㍁䅁䅁睐䅙䡁䅷䅁湁䙁䅳兔䩂䙁䄸睑療䝁䄰䅣桂䝁䄴入時䕁䅳党㕂䙁䅍䅤桂䡁䅑督時䡁䅙免瑁䍁䅁睔祂䝁䅫睚灂䝁䄴兙獂䍁䄴䅥獂䡁䅍兢摂䕁䅍兙睂䝁䅫䅤桂䝁䅷兡㙂䝁䅅䅤灂䝁䄸杢湁䍁䅅䅊䑂䍁䅑䅎㍁䅁䅁䅑䅕䡁䅉䅁湁䙁䅳兔䩂䙁䄸睑療䝁䄰䅣桂䝁䄴入時䕁䅳党㕂䙁䅍䅤桂䡁䅑督時䡁䅙免瑁䍁䅁睔祂䝁䅫睚灂䝁䄴兙獂䍁䄴䅥獂䡁䅍兢摂䕁䅳党㕂䙁䄸睕あ䝁䅅䅤穂䍁䅣光歁䕁䅉䅊ㅁ䑁䅉䅁煂兂䅁䅌䅁䕁䅫兕時䕁䅍杒偂䙁䄸免婂䙁䅉睘䉂䕁䄴杔時䕁䅣杕偂䙁䅣䅖䥂䅁䅁免䅉䡁䅷䅁湁䙁䅳兔䩂䙁䄸睑療䝁䄰䅣桂䝁䄴入時䕁䅳党㕂䙁䅍䅤桂䡁䅑督時䡁䅙免瑁䍁䅁睔祂䝁䅫睚灂䝁䄴兙獂䍁䄴䅥獂䡁䅍兢摂䕁䅍兙睂䝁䅫䅤桂䝁䅷兡㙂䝁䅅䅤灂䝁䄸杢湁䍁䅅䅊䑂䍁䅑兎睁䅁䅁材䅕䝁䅑䅁䝂䝁䅅兡祂䍁䅁杖桂䝁䅷兤求䍁䅁睑潂䝁䅅杢湂䝁䅕䅉䩂䝁䄴睙獂䡁䅕䅚求䝁䅑䅉灂䝁䄴䅉䙂䝁䅅杣畂䝁䅫杢湂䡁䅍䅉潁䙁䅉党睂䝁䄸杣あ䝁䅕䅚灁䅁䅁克䅍䥁䅙䅁湁䙁䅳兔䩂䙁䄸睑療䝁䄰䅣桂䝁䄴入時䕁䅳党㕂䙁䅍䅤桂䡁䅑督時䡁䅙免瑁䕁䅍睢睂䡁䅫杌㑂䝁䅷督瑂䙁䄰睑桂䡁䅁兡あ䝁䅅䅢時䙁䅍䅤祂䡁䅕睙あ䡁䅕杣求䙁䄸睕ㅂ䝁䄰兢桂䡁䅉入湁䍁䅅䅊䑂䍁䅑兎䅁䥁䙑䅁浂䅁䅁睗乂䕁䅫睘䑂䝁䄸兢睂䝁䅅杢㕂䙁䄸睓求䡁䅫睕あ䝁䅅䅤穂䙁䄸杤硁䍁䄴䅥獂䡁䅍兢摂䕁䅳党㕂䙁䄸睕あ䝁䅅䅤穂䍁䅅䅊䑂䍁䅑李硁䑁䅯䅊䑂䍁䅑李㍁䅁䅁杁䅑䍁䄴䅁䩂䙁䅅睘佂䙁䅁䅕䙂䙁䄸睍婂䙁䅉睘䉂䕁䄴杔時䕁䅣杕偂䙁䅣䅖䥂䅁䅁党䅉䥁䅧䅁湁䙁䅳兔䩂䙁䄸睑療䝁䄰䅣桂䝁䄴入時䕁䅳党㕂䙁䅍䅤桂䡁䅑督時䡁䅙免瑁䍁䅁睔祂䝁䅫睚灂䝁䄴兙獂䍁䄴䅥獂䡁䅍兢摂䕁䅍兙睂䝁䅫䅤桂䝁䅷兡㙂䝁䅅䅤灂䝁䄸杢湁䍁䅅䅊䑂䍁䅑兎穁䑁䅯䅊䑂䍁䅑兎ぁ䅁䅁村䅕䥁䅙䅁湁䙁䅳兔䩂䙁䄸睑療䝁䄰䅣桂䝁䄴入時䕁䅳党㕂䙁䅍䅤桂䡁䅑督時䡁䅙免瑁䍁䅁睔祂䝁䅫睚灂䝁䄴兙獂䍁䄴䅥獂䡁䅍兢摂䕁䅍兙睂䝁䅫䅤桂䝁䅷兡㙂䝁䅅䅤灂䝁䄸杢湁䍁䅅䅊䑂䍁䅑兏㙁䍁䅑睑歁䑁䅉兎䅁䑁䙯䅁楁䅁䅁睑ㅂ䡁䅉杣求䝁䄴䅤癁䙁䅉党穂䡁䅑兙あ䝁䅕䅚䅁䅁䅉䅁䥃䅁䅁睊扂䕁䄰兓時䕁䅍睢瑂䡁䅁兙畂䡁䅫睘䱂䝁䅕入呂䡁䅑兙あ䡁䅍睘㉂䑁䅅兌杁䕁䄸杣灂䝁䅣兡畂䝁䅅䅢畁䡁䅧䅢穂䝁䄰兘䑂䝁䅅䅣灂䡁䅑兙獂䝁䅫来桂䡁䅑兡療䝁䄴睊桁䍁䅑兒歁䑁䅑睎㙁䍁䅑䅕歁䑁䅑睎䅁䑁䘰䅁䥃䅁䅁睊扂䕁䄰兓時䕁䅍睢瑂䡁䅁兙畂䡁䅫睘䱂䝁䅕入呂䡁䅑兙あ䡁䅍睘㉂䑁䅅兌杁䕁䄸杣灂䝁䅣兡畂䝁䅅䅢畁䡁䅧䅢穂䝁䄰兘䑂䝁䅅䅣灂䡁䅑兙獂䝁䅫来桂䡁䅑兡療䝁䄴睊桁䍁䅑兒歁䑁䅑䅏㙁䍁䅑䅕歁䑁䅑䅏䅁䑁䘸䅁㉁䅁䅁䅒桂䡁䅫䅉䑂䝁䅷睢穂䝁䅕䅉兂䡁䅉兡橂䝁䅕䅉潁䙁䅉党睂䝁䄸杣あ䝁䅕䅚灁䅁䅁睅䅁䙁䅙䅁䑂䝁䄸杢あ䡁䅉兙橂䡁䅑兤桂䝁䅷䅉偂䝁䅉䅢灂䝁䅣兙あ䝁䅫睢畂䡁䅍䅉䕂䡁䅕党杁䍁䅳䅉穁䍁䅁䅋卂䝁䅕䅣療䡁䅉䅤求䝁䅑克䅁乁䉧䅁䕃䅁䅁睊扂䕁䄰兓時䕁䅍睢瑂䡁䅁兙畂䡁䅫睘䱂䝁䅕入呂䡁䅑兙あ䡁䅍睘㉂䑁䅅兌杁䕁䄸杣灂䝁䅣兡畂䝁䅅䅢畁䡁䅧䅢穂䝁䄰兘䑂䝁䅅䅣灂䡁䅑兙獂䝁䅫来桂䡁䅑兡療䝁䄴睊桁䍁䅑兒歁䑁䅑杏歁䕁䅯䅊ぁ䅁䅁兏䅕䡁䄴䅁湁䙁䅳睕兂䕁䅣睘䑂䝁䄸兢睂䝁䅅杢㕂䙁䄸睓求䡁䅫睕あ䝁䅅䅤穂䙁䄸杤硁䍁䅁䅋祁䍁䅫杌㑂䝁䅷督瑂䙁䄰兓畂䝁䅍睢瑂䝁䅕睘呂䡁䅑兙あ䝁䅕兢求䝁䄴䅤湁䍁䅅䅊䙂䍁䅑睎㙁䍁䅑䅕歁䑁䅣䅁湁杂䅁杩䅁䍁䅣睗䑂䝁䄸䅣㕂䍁䅁睢浂䍁䅁睕兂䕁䅣睘䑂䝁䄸兢睂䝁䅅杢㕂䙁䄸睓求䡁䅫睕あ䝁䅅䅤穂䙁䄸杤祁䙁䄸杢求䡁䅣杌㑂䝁䅷督瑂䙁䄰睑桂䡁䅁兡あ䝁䅅䅢灂䡁䅯兙あ䝁䅫睢畂䍁䅣光歁䕁䅕䅊ㅁ䑁䅯䅊䭂䍁䅑兎䅁䕁䠰䅁楂䅁䅁睗䱂䝁䅕入呂䡁䅑兙あ䡁䅍睘あ䝁䅕督あ䝁䅙兡獂䝁䅕杌㑂䝁䅷督瑂䙁䄰睑桂䡁䅁兡あ䝁䅅䅢灂䡁䅯兙あ䝁䅫睢畂䍁䅅䅊䝂䍁䅑兎㙁䍁䅑兕歁䑁䅕䅁䥄䅁䅁䅐䅁䕁䅅杤求䡁䅉兙湂䝁䅕䅉䩂䝁䄴䅤求䡁䅉党穂䡁䅑䅉卂䝁䅅䅤求䍁䅁睋杁䑁䅍䅉潁䍁䅕克䅁佁䉷䅁啂䅁䅁睑療䝁䄴䅤祂䝁䅅睙あ䡁䅕兙獂䍁䅁睔楂䝁䅷兡湂䝁䅅䅤灂䝁䄸杢穂䍁䅁䅒ㅂ䝁䅕䅉牁䑁䅅䅉潁䙁䅉党睂䝁䄸杣あ䝁䅕䅚灁䅁䅁䄱䅅䥁䅧䅁湁䙁䅳睕兂䕁䅣睘䑂䝁䄸兢睂䝁䅅杢㕂䙁䄸睓求䡁䅫睕あ䝁䅅䅤穂䙁䄸杤祁䍁䅁免畁䡁䅧䅢穂䝁䄰兘䑂䝁䅅䅣灂䡁䅑兙獂䙁䄸睕あ䡁䅉兤橂䡁䅑兤祂䝁䅕睘杁䕁䅑党あ䝁䅅兡獂䡁䅍䅉湁䍁䅅䅊䭂䍁䅑䅎ぁ䅁䅁䅈䅣䥁䅧䅁湁䙁䅳兔䩂䙁䄸睑療䝁䄰䅣桂䝁䄴入時䕁䅳党㕂䙁䅍䅤桂䡁䅑督時䡁䅙免瑁䍁䅁睔祂䝁䅫睚灂䝁䄴兙獂䍁䄴䅥獂䡁䅍兢摂䕁䅍兙睂䝁䅫䅤桂䝁䅷兡㙂䝁䅅䅤灂䝁䄸杢湁䍁䅅䅊䙂䍁䅑兎硁䑁䅯䅊䭂䍁䅑兎硁䅁䅁兑䅕䝁䅯䅁湁䙁䅳兔䩂䙁䄸睑療䝁䄰䅣桂䝁䄴入時䕁䅳党㕂䙁䅍䅤桂䡁䅑督時䡁䅙免瑁䕁䅍睢睂䡁䅫杌㑂䝁䅷督瑂䙁䄰杕桂䡁䅑兡療䡁䅍睊桁䍁䅑䅒歁䑁䅑杏歁䕁䅫䅊ぁ䅁䅁兩䅕䥁䅑䅁湁䙁䅳睑療䡁䅁入杁䝁䄸杚杁䙁䅍䅕䡂䙁䄸睑療䝁䄰䅣桂䝁䄴入時䕁䅳党㕂䙁䅍䅤桂䡁䅑督時䡁䅙杍時䝁䄴党㍂䍁䄴䅥獂䡁䅍兢摂䕁䅳党㕂䙁䄸睕あ䝁䅅䅤穂䍁䅣光歁䙁䅕䅊ㅁ䑁䅧杏歁䙁䅕䅊㉁䑁䅅䅁呃睂䅁䅩䅁䍁䅣睗呂䙁䅁睒時䕁䅍睢瑂䡁䅁兙畂䡁䅫睘䱂䝁䅕入呂䡁䅑兙あ䡁䅍睘㉂䑁䅉䅉硁䍁䄴䅥獂䡁䅍兢摂䕁䅍兙睂䝁䅫䅤桂䝁䅷睘呂䡁䅑杣ㅂ䝁䅍䅤ㅂ䡁䅉党時䍁䅁䅒求䡁䅑兙灂䝁䅷督杁䍁䅣光歁䕁䅉䅊ぁ䑁䅑䅁十睂䅁䅨䅁䍁䅣睗乂䕁䅫睘䑂䝁䄸兢睂䝁䅅杢㕂䙁䄸睓求䡁䅫睕あ䝁䅅䅤穂䙁䄸杤硁䍁䄰䅉偂䡁䅉兡湂䝁䅫杢桂䝁䅷杌㑂䝁䅷督瑂䙁䄰睑桂䡁䅁兡あ䝁䅅䅢灂䡁䅯兙あ䝁䅫睢畂䍁䅣光歁䕁䅕䅊ㅁ䑁䅯䅊䭂䍁䅑兎䅁䑁䙳䅁捂䅁䅁睗䱂䝁䅕入呂䡁䅑兙あ䡁䅍睘あ䝁䅕督あ䝁䅙兡獂䝁䅕杌㑂䝁䅷督瑂䙁䄰睓求䡁䅫睘呂䡁䅑兙あ䡁䅍光歁䕁䅕䅊㕁䑁䅧杏歁䕁䅣䅊㕁䑁䅧䅁呃䅁䅁䅮䅁䍁䅣睗䑂䝁䄸䅣㕂䍁䅁睢浂䍁䅁睕兂䕁䅣睘䑂䝁䄸兢睂䝁䅅杢㕂䙁䄸睓求䡁䅫睕あ䝁䅅䅤穂䙁䄸杤祁䙁䄸杢求䡁䅣杌㑂䝁䅷督瑂䙁䄰睑桂䡁䅁兡あ䝁䅅䅢時䙁䅍䅤祂䡁䅕睙あ䡁䅕杣求䙁䄸䅉䕂䝁䅕䅤桂䝁䅫䅢穂䍁䅁睊桁䍁䅑兒歁䑁䅣李䅁䥁䡣䅁䍃䅁䅁睊扂䕁䄰兓時䕁䅍睢瑂䡁䅁兙畂䡁䅫睘䱂䝁䅕入呂䡁䅑兙あ䡁䅍睘㉂䑁䅅兌杁䕁䄸杣灂䝁䅣兡畂䝁䅅䅢畁䡁䅧䅢穂䝁䄰兘䱂䝁䅕入時䙁䅍䅤桂䡁䅑督湁䍁䅅䅊䙂䍁䅑免睁䑁䅕杏歁䕁䅣䅊硁䑁䅁兎䅁䝁䙣䅁⭂䅁䅁睊扂䕁䄰兓時䕁䅍睢瑂䡁䅁兙畂䡁䅫睘䱂䝁䅕入呂䡁䅑兙あ䡁䅍睘㉂䑁䅅兌杁䕁䄸杣灂䝁䅣兡畂䝁䅅䅢畁䡁䅧䅢穂䝁䄰兘䩂䝁䄴睙療䝁䄰党時䙁䅍䅤桂䡁䅑党瑂䝁䅕杢あ䍁䅣光歁䕁䅍䅊ぁ䅁䅁杣䅕䡁䅧䅁湁䙁䅳睕兂䕁䅣睘䑂䝁䄸兢睂䝁䅅杢㕂䙁䄸睓求䡁䅫睕あ䝁䅅䅤穂䙁䄸杤硁䍁䅁䅋祁䍁䅫杌㑂䝁䅷督瑂䙁䄰睓求䡁䅫睘呂䡁䅑兙あ䡁䅍睊桁䍁䅑兒歁䑁䅅䅍㉁䑁䅯䅊䡂䍁䅑免睁䑁䅙䅁婁杂䅁材䅁䙁䅍兤楂䍁䄰䅔求䝁䅅督求䍁䅁兓畂䝁䅍睢瑂䝁䅕䅉牁䑁䅕䅉潁䙁䅉党睂䝁䄸杣あ䝁䅕䅚灁䅁䅁杺䅅䑁䅑䅁䩂䙁䅅睘坂䕁䅅杕䩂䕁䅅村䵂䕁䅕睘卂䕁䅅䅖䙂䙁䄸䅒䙂䕁䅉䅖時䙁䅁睑啂䅁䅁条䅅䡁䅑䅁湁䙁䅳兔䩂䙁䄸睑療䝁䄰䅣桂䝁䄴入時䕁䅳党㕂䙁䅍䅤桂䡁䅑督時䡁䅙免瑁䕁䅍睢睂䡁䅫杌㑂䝁䅷督瑂䙁䄰睓求䡁䅫睘呂䡁䅑兙あ䡁䅍睊桁䍁䅑兒歁䑁䅉兎㙁䍁䅑䅔歁䑁䅉兎䅁䙁䙉䅁祂䅁䅁睊扂䕁䄰兓時䕁䅍睢瑂䡁䅁兙畂䡁䅫睘䱂䝁䅕入呂䡁䅑兙あ䡁䅍睘㉂䑁䅅兌䑂䝁䄸䅣㕂䍁䄴䅥獂䡁䅍兢摂䕁䅍兙睂䝁䅫䅤桂䝁䅷兡㙂䝁䅅䅤灂䝁䄸杢湁䍁䅅䅊䑂䍁䅑兎㑁䅁䅁䅒䅕䍁䅁䅁䩂䙁䅅睘呂䕁䅕睑噂䙁䅉兒䕂䙁䄸䅒䙂䕁䅉䅖䅁䑁䉧䅁䵃䅁䅁睊扂䕁䄰兓時䕁䅍睢瑂䡁䅁兙畂䡁䅫睘䱂䝁䅕入呂䡁䅑兙あ䡁䅍睘㉂䑁䅅兌杁䕁䄸杣灂䝁䅣兡畂䝁䅅䅢畁䡁䅧䅢穂䝁䄰兘䩂䝁䄴睙療䝁䄰党時䙁䅍䅤桂䡁䅑党瑂䝁䅕杢あ䍁䅣光歁䕁䅍䅊㕁䑁䅯䅊䑂䍁䅑免㍁䑁䅍䅁あ兂䅁䅓䅁䙁䅑兙畂䝁䅣兡楂䝁䅷党杁䕁䅉睢療䝁䅳䅉坂䝁䅅䅢ㅂ䝁䅕䅌杁䑁䅍䅉婂䡁䅉杌杁䕁䅍兑䡂䙁䅉䅉潁䍁䅕克䅁䡁䍷䅁坂䅁䅁睗䱂䝁䅕入呂䡁䅑兙あ䡁䅍睘あ䝁䅕督あ䝁䅙兡獂䝁䅕杌㑂䝁䅷督㑂䙁䄰睕潂䝁䅕党あ䑁䅅光歁䕁䅍䅊祁䑁䅕杏歁䕁䅍䅊ぁ䑁䅕䅁偂䅁䅁䅩䅁䍁䅣睗乂䕁䅫睘䑂䝁䄸兢睂䝁䅅杢㕂䙁䄸睓求䡁䅫睕あ䝁䅅䅤穂䙁䄸杤硁䍁䄰䅉偂䡁䅉兡湂䝁䅫杢桂䝁䅷杌㑂䝁䅷督瑂䙁䄰兓畂䝁䅍睢瑂䝁䅕睘呂䡁䅑兙あ䝁䅕兢求䝁䄴䅤湁䍁䅅䅊䙂䍁䅑䅎㙁䍁䅑䅕歁䑁䅑䅁穂兂䅁条䅁䙁䅳睓求䡁䅫睕あ䝁䅅䅤穂䙁䄸䅤求䡁䅍䅤浂䝁䅫䅢求䍁䄴䅥獂䡁䅍兢摂䕁䅫杢橂䝁䄸兢求䙁䄸睕あ䝁䅅䅤求䝁䄰党畂䡁䅑光歁䕁䅑䅊㕁䑁䅯䅊䕂䍁䅑免ㅁ䑁䅣䅁㡃䅁䅁䅕䅁䙁䅳兔䩂䙁䄸睓求䡁䅫睕あ䝁䅅䅤穂䙁䄸杤硁䍁䄴䅥獂䡁䅍兢摂䙁䅉兙あ䝁䅫睢穂䍁䅅䅊䑂䍁䅑兏㙁䍁䅑睑歁䑁䅅兎睁䅁䅁典䅍䍁䅙䅁橁䕁䄴睔杁䕁䅑兑啂䕁䅅䅉䉂䙁䅙兑䩂䕁䅷兑䍂䕁䅷兒䅁䵁䡷䅁䭃䅁䅁睊扂䕁䅍睢睂䡁䅫䅉療䝁䅙䅉呂䙁䅁睒時䕁䅍睢瑂䡁䅁兙畂䡁䅫睘䱂䝁䅕入呂䡁䅑兙あ䡁䅍睘㉂䑁䅅睘䝂䝁䅫杢桂䝁䅷杌㑂䝁䅷督瑂䙁䄰䅕求䝁䄴督灂䝁䄸杢瑁䕁䄸䅕䙂䕁䅉睊桁䍁䅑䅒歁䑁䅧杏歁䕁䅫䅊㑁䅁䅁東䅧䡁䄴䅁湁䙁䅳兔䩂䙁䄸睑療䝁䄰䅣桂䝁䄴入時䕁䅳党㕂䙁䅍䅤桂䡁䅑督時䡁䅙免瑁䍁䅁睔祂䝁䅫睚灂䝁䄴兙獂䍁䄴䅥獂䡁䅍兢摂䕁䅳党㕂䙁䄸睕あ䝁䅅䅤穂䍁䅣光歁䕁䅑䅊祁䑁䅕杏歁䕁䅑䅊ぁ䑁䅫䅁敂兂䅁䅆䅁䙁䅍䅕時䙁䅁兒時䕁䅙睖䕂䅁䅁䅡䅙䡁䅑䅁湁䙁䅳兔䩂䙁䄸睑療䝁䄰䅣桂䝁䄴入時䕁䅳党㕂䙁䅍䅤桂䡁䅑督時䡁䅙免瑁䍁䅁睔祂䝁䅫睚灂䝁䄴兙獂䍁䄴䅥獂䡁䅍兢摂䕁䅳党㕂䙁䄸睕あ䝁䅅䅤穂䍁䅣光歁䕁䅉䅊硁䑁䅁睍䅁䝁䙑䅁䥁䅁䅁䅔啂䕁䄰䅁䉁䅁䅁䅊䅁䕁䅫兕時䙁䅣䅖䕂䙁䄸兑坂䕁䅣睘䩂䙁䅉睘䑂䙁䅫睍䅁佁䉕䅁祂䅁䅁睊扂䕁䄰兓時䕁䅍睢瑂䡁䅁兙畂䡁䅫睘䱂䝁䅕入呂䡁䅑兙あ䡁䅍睘㉂䑁䅅兌杁䕁䄸杣灂䝁䅣兡畂䝁䅅䅢畁䡁䅧䅢穂䝁䄰兘䱂䝁䅕入時䙁䅍䅤桂䡁䅑督湁䍁䅅䅊䍂䍁䅑兎㕁䅁䅁杢䅕䙁䅉䅁扂䕁䄰兓時䕁䅳党㕂䙁䅍䅤桂䡁䅑督時䡁䅙免畁䡁䅧䅢穂䝁䄰兘䑂䝁䅅䅣灂䡁䅑兙獂䝁䅫来桂䡁䅑兡療䝁䄴光歁䕁䅍䅊ぁ䅁䅁兮䅍䥁䅉䅁湁䙁䅳兔䩂䙁䄸睑療䝁䄰䅣桂䝁䄴入時䕁䅳党㕂䙁䅍䅤桂䡁䅑督時䡁䅙免瑁䍁䅁睔祂䝁䅫睚灂䝁䄴兙獂䍁䄴䅥獂䡁䅍兢摂䕁䅳党㕂䙁䄸睕あ䝁䅅䅤穂䍁䅣光歁䕁䅍䅊硁䑁䅁睎㙁䍁䅑睑歁䑁䅅免硁䅁䅁杚䅕䙁䅷䅁扂䕁䅳党㕂䙁䅍䅤桂䡁䅑督時䡁䅑党穂䡁䅑杚灂䝁䅷党畁䡁䅧䅢穂䝁䄰兘䱂䝁䅕入時䙁䅍䅤桂䡁䅑督桁䍁䅑兒歁䑁䅫兏㙁䍁䅑睒歁䑁䅫兏䅁䭁䅍䅁⭂䅁䅁睊扂䕁䄰兓時䕁䅍睢瑂䡁䅁兙畂䡁䅫睘䱂䝁䅕入呂䡁䅑兙あ䡁䅍睘㉂䑁䅅兌杁䕁䄸杣灂䝁䅣兡畂䝁䅅䅢畁䡁䅧䅢穂䝁䄰兘䱂䝁䅕入時䙁䅍䅤桂䡁䅑督湁䍁䅅䅊䑂䍁䅑杍ㅁ䑁䅯䅊䑂䍁䅑䅎㕁䅁䅁杙䅕䥁䅧䅁扂䙁䅍䅕䡂䙁䄸睑療䝁䄰䅣桂䝁䄴入時䕁䅳党㕂䙁䅍䅤桂䡁䅑督時䡁䅙杍畁䡁䅧䅢穂䝁䄰兘䑂䝁䅅䅣灂䡁䅑兙獂䙁䄸睕あ䡁䅉兤橂䡁䅑兤祂䝁䅕睘呂䡁䅕兢瑂䝁䅅杣㕂䍁䅅䅊䝂䍁䅑免硁䑁䅯䅊卂䍁䅑免硁䅁䅁元䅧䉁䄴䅁呂䙁䅁睘兂䙁䅉兓䑂䕁䅕睘䑂䕁䅷睔呂䕁䅕䅁十䅁䅁杨䅁䍁䅣睗䑂䝁䄸䅣㕂䍁䅁睢浂䍁䅁睕兂䕁䅣睘䑂䝁䄸兢睂䝁䅅杢㕂䙁䄸睓求䡁䅫睕あ䝁䅅䅤穂䙁䄸杤祁䙁䄸杢求䡁䅣杌㑂䝁䅷督瑂䙁䄰䅕求䝁䄴督灂䝁䄸杢瑁䕁䄸䅕䙂䕁䅉睊桁䍁䅑䅒歁䑁䅣杏歁䕁䅫䅊㍁䅁䅁兡䅣䑁䅉䅁䩂䙁䅅睘佂䕁䅕䅖時䕁䅑兒䍂䙁䅑睘䙂䕁䅉兓啂䕁䅑兑時䕁䅍兑兂䕁䅕䅗䅁䥁䉣䅁䍂䅁䅁兑瑂䝁䅅来療䝁䄴杌橂䝁䄸兢獁䍁䅁兓畂䝁䅍杌杁䍁䅧杔䉂䙁䅍䅒䉂䙁䅅睒呂䑁䅯兑乂䙁䅯杔灁䅁䅁儳䅣䍁䅁䅁䩂䙁䅅睘䕂䕁䅕村啂䙁䄸兑䕂䕁䅯睘兂䕁䅍䅖䅁䅁䉉䅁⭂䅁䅁睊扂䕁䄰兓時䕁䅍睢瑂䡁䅁兙畂䡁䅫睘䱂䝁䅕入呂䡁䅑兙あ䡁䅍睘㉂䑁䅅兌杁䕁䄸杣灂䝁䅣兡畂䝁䅅䅢畁䡁䅧䅢穂䝁䄰兘䱂䝁䅕入時䙁䅍䅤桂䡁䅑督湁䍁䅅䅊䑂䍁䅑兎ぁ䑁䅯䅊䑂䍁䅑兎ㅁ䅁䅁䅢䅕䡁䅑䅁湁䙁䅳兔䩂䙁䄸睑療䝁䄰䅣桂䝁䄴入時䕁䅳党㕂䙁䅍䅤桂䡁䅑督時䡁䅙免瑁䕁䅍睢睂䡁䅫杌㑂䝁䅷督瑂䙁䄰兓畂䝁䅍睢瑂䝁䅕睘呂䡁䅑兙あ䝁䅕兢求䝁䄴䅤湁䍁䅅䅊䑂䍁䅑䅎䅁䕁䘴䅁⭂䅁䅁睊扂䕁䄰兓時䕁䅍睢瑂䡁䅁兙畂䡁䅫睘䱂䝁䅕入呂䡁䅑兙あ䡁䅍睘㉂䑁䅅兌杁䕁䄸杣灂䝁䅣兡畂䝁䅅䅢畁䡁䅧䅢穂䝁䄰兘䱂䝁䅕入時䙁䅍䅤桂䡁䅑督湁䍁䅅䅊䑂䍁䅑李祁䑁䅯䅊䑂䍁䅑李㑁䅁䅁䅣䅕䡁䅧䅁扂䕁䅳党㕂䙁䅍䅤桂䡁䅑督時䡁䅑党穂䡁䅑杚灂䝁䅷党畁䡁䅧䅢穂䝁䄰兘䑂䝁䅅䅣灂䡁䅑兙獂䙁䄸睕あ䡁䅉兤橂䡁䅑兤祂䝁䅕睘呂䡁䅕兢瑂䝁䅅杣㕂䍁䅅䅊䡂䍁䅑䅏㙁䍁䅑睔歁䑁䅧䅁㍂允䅁杦䅁䍁䅣睗乂䕁䅫睘䑂䝁䄸兢睂䝁䅅杢㕂䙁䄸睓求䡁䅫睕あ䝁䅅䅤穂䙁䄸杤硁䍁䄰䅉偂䡁䅉兡湂䝁䅫杢桂䝁䅷杌㑂䝁䅷督瑂䙁䄰睓求䡁䅫睘呂䡁䅑兙あ䡁䅍睊桁䍁䅑䅒歁䑁䅕䅎㙁䍁䅑䅒歁䑁䅕兎䅁䝁䘰䅁㡂䅁䅁睊扂䙁䅍䅕䡂䙁䄸睑療䝁䄰䅣桂䝁䄴入時䕁䅳党㕂䙁䅍䅤桂䡁䅑督時䡁䅙免杁䍁䅧杍灁䍁䄴䅥獂䡁䅍兢摂䙁䅍兤睂䡁䅁䅢求䝁䄰党畂䡁䅑兙獂䍁䅣光歁䕁䅍䅊硁䑁䅅杏歁䕁䅍䅊硁䑁䅙䅏䅁䕁䝯䅁潂䅁䅁兖畂䡁䅉党橂䝁䄸睚畁䍁䅁䅖桂䡁䅧䅉䍂䝁䅕杢求䝁䅙兡あ䡁䅍䅌杁䕁䅕杢歂䍁䅁睢浂䍁䅁䅤潂䝁䅕䅉兂䝁䅕杣灂䝁䄸䅚杁䍁䅧杕求䡁䅁睢祂䡁䅑党歂䍁䅫䅁剁睁䅁杂䅁䕁䄴兔䅁䝁䝕䅁䍃䅁䅁睊扂䕁䄰兓時䕁䅍睢瑂䡁䅁兙畂䡁䅫睘䱂䝁䅕入呂䡁䅑兙あ䡁䅍睘㉂䑁䅅兌杁䕁䄸杣灂䝁䅣兡畂䝁䅅䅢畁䡁䅧䅢穂䝁䄰兘䱂䝁䅕入時䙁䅍䅤桂䡁䅑督湁䍁䅅䅊䙂䍁䅑免睁䑁䅑杏歁䕁䅣䅊硁䑁䅁䅎䅁䝁䙕䅁㙂䅁䅁睊扂䕁䅍睢睂䡁䅫䅉療䝁䅙䅉呂䙁䅁睒時䕁䅍睢瑂䡁䅁兙畂䡁䅫睘䱂䝁䅕入呂䡁䅑兙あ䡁䅍睘㉂䑁䅉睘畂䝁䅕睤畁䡁䅧䅢穂䝁䄰兘䱂䝁䅕入時䙁䅍䅤桂䡁䅑督湁䍁䅅䅊䝂䍁䅑免睁䑁䅣䅁楃睂䅁杋䅁䕁䅫兕時䙁䅍兖䍂䙁䄸䅔䙂䕁䅅睕䙂䙁䄸兓佂䕁䅍睘䑂䙁䅫杍䅁䵁䉫䅁坂䅁䅁睑療䝁䄴䅤祂䝁䅅睙あ䡁䅕兙獂䍁䅁睔楂䝁䅷兡湂䝁䅅䅤灂䝁䄸杢穂䍁䅁䅒ㅂ䝁䅕䅉牁䍁䅁䅎杁䍁䅧杕求䡁䅁睢祂䡁䅑党歂䍁䅫䅁慄允䅁杦䅁䍁䅣睗乂䕁䅫睘䑂䝁䄸兢睂䝁䅅杢㕂䙁䄸睓求䡁䅫睕あ䝁䅅䅤穂䙁䄸杤硁䍁䄰䅉偂䡁䅉兡湂䝁䅫杢桂䝁䅷杌㑂䝁䅷督瑂䙁䄰睓求䡁䅫睘呂䡁䅑兙あ䡁䅍睊桁䍁䅑兒歁䑁䅉睍㙁䍁䅑杓歁䑁䅉睍䅁䝁䙍䅁浂䅁䅁睊扂䙁䅍䅕䡂䙁䄸睑療䝁䄰䅣桂䝁䄴入時䕁䅳党㕂䙁䅍䅤桂䡁䅑督時䡁䅙杍杁䑁䅅杌㑂䝁䅷督瑂䙁䄰睓求䡁䅫睘呂䡁䅑兙あ䡁䅍睊桁䍁䅑村歁䑁䅅䅍㉁䅁䅁眰䅙䕁䅁䅁䩂䙁䅅睘偂䙁䅁䅖䩂䕁䄸杔呂䙁䄸睕啂䙁䅉兓䱂䕁䅕睘兂䙁䅉兓䑂䕁䅕睘䡂䙁䅉兑佂䙁䅑兒䕂䅁䅁杍䅍䝁䅑䅁扂䕁䄰兓時䕁䅍睢瑂䡁䅁兙畂䡁䅫睘䱂䝁䅕入呂䡁䅑兙あ䡁䅍睘㉂䑁䅅杌㑂䝁䅷督瑂䙁䄰睑桂䡁䅍䅡時䕁䅙䅢療䡁䅣光歁䕁䅍䅊㕁䑁䅯䅊䑂䍁䅑兏睁䅁䅁杄䅑䡁䄴䅁湁䙁䅳兔䩂䙁䄸睑療䝁䄰䅣桂䝁䄴入時䕁䅳党㕂䙁䅍䅤桂䡁䅑督時䡁䅙免瑁䍁䅁睔祂䝁䅫睚灂䝁䄴兙獂䍁䄴䅥獂䡁䅍兢摂䕁䅳党㕂䙁䄸睕あ䝁䅅䅤穂䍁䅣光歁䕁䅕䅊祁䑁䅍杏歁䕁䅷䅊祁䑁䅍䅁灂兂䅁杚䅁䍁䅣睗呂䙁䅁睒時䕁䅍睢瑂䡁䅁兙畂䡁䅫睘䱂䝁䅕入呂䡁䅑兙あ䡁䅍睘㉂䑁䅉䅉硁䍁䄴䅥獂䡁䅍兢摂䙁䅉兙あ䝁䅫睢穂䍁䅣光歁䕁䅑䅊㍁䑁䅯䅊䩂䍁䅑睎䅁偁䝯䅁獁䅁䅁睑療䝁䄰䅣療䝁䄴党畂䡁䅑䅉䕂䝁䅕督橂䡁䅉兡睂䡁䅑兡療䝁䄴䅁䝃杂䅁杓䅁䙁䅳睓求䡁䅫睕あ䝁䅅䅤穂䙁䄸䅤求䡁䅍䅤浂䝁䅫䅢求䍁䄴䅥獂䡁䅍䅥摂䙁䅍䅡求䝁䅕䅤硁䍁䅅䅊䍂䍁䅑杍睁䅁䅁兌䅁䡁䅉䅁湁䙁䅳兔䩂䙁䄸睑療䝁䄰䅣桂䝁䄴入時䕁䅳党㕂䙁䅍䅤桂䡁䅑督時䡁䅙免瑁䍁䅁睔祂䝁䅫睚灂䝁䄴兙獂䍁䄴䅥獂䡁䅍兢摂䕁䅳党㕂䙁䄸睕あ䝁䅅䅤穂䍁䅣光歁䕁䅕䅊ㅁ䑁䅉䅁牂兂䅁䅡䅁䍁䅣睗乂䕁䅫睘䑂䝁䄸兢睂䝁䅅杢㕂䙁䄸睓求䡁䅫睕あ䝁䅅䅤穂䙁䄸杤硁䍁䄰睑療䡁䅁入畁䡁䅧䅢穂䝁䄰兘䱂䝁䅕入時䙁䅍䅤桂䡁䅑督湁䍁䅅䅊䙂䍁䅑兎ㅁ䅁䅁兖䅕䡁䅯䅁湁䙁䅳睑療䡁䅁入杁䝁䄸杚杁䙁䅍䅕䡂䙁䄸睑療䝁䄰䅣桂䝁䄴入時䕁䅳党㕂䙁䅍䅤桂䡁䅑督時䡁䅙杍時䝁䄴党㍂䍁䄴䅥獂䡁䅍兢摂䕁䅳党㕂䙁䄸睕あ䝁䅅䅤穂䍁䅣光歁䕁䅙䅊硁䑁䅁李䅁䭁䡁䅁祂䅁䅁睊扂䕁䄰兓時䕁䅍睢瑂䡁䅁兙畂䡁䅫睘䱂䝁䅕入呂䡁䅑兙あ䡁䅍睘㉂䑁䅅兌杁䕁䄸杣灂䝁䅣兡畂䝁䅅䅢畁䡁䅧䅢穂䝁䄰兘䱂䝁䅕入時䙁䅍䅤桂䡁䅑督湁䍁䅅䅊䙂䍁䅑兎㕁䅁䅁睢䅕䥁䅧䅁湁䙁䅳睕兂䕁䅣睘䑂䝁䄸兢睂䝁䅅杢㕂䙁䄸睓求䡁䅫睕あ䝁䅅䅤穂䙁䄸杤祁䍁䅁免畁䡁䅧䅢穂䝁䄰兘䑂䝁䅅䅣灂䡁䅑兙獂䙁䄸睕あ䡁䅉兤橂䡁䅑兤祂䝁䅕睘杁䕁䅑党あ䝁䅅兡獂䡁䅍䅉湁䍁䅅䅊䑂䍁䅑䅎ぁ䅁䅁䅆䅣䡁䅉䅁湁䙁䅳兔䩂䙁䄸睑療䝁䄰䅣桂䝁䄴入時䕁䅳党㕂䙁䅍䅤桂䡁䅑督時䡁䅙免瑁䍁䅁睔祂䝁䅫睚灂䝁䄴兙獂䍁䄴䅥獂䡁䅍兢摂䕁䅳党㕂䙁䄸睕あ䝁䅅䅤穂䍁䅣光歁䕁䅕䅊㉁䑁䅁䅁硂兂䅁杦䅁䍁䅣睗乂䕁䅫睘䑂䝁䄸兢睂䝁䅅杢㕂䙁䄸睓求䡁䅫睕あ䝁䅅䅤穂䙁䄸杤硁䍁䄰䅉偂䡁䅉兡湂䝁䅫杢桂䝁䅷杌㑂䝁䅷督瑂䙁䄰睓求䡁䅫睘呂䡁䅑兙あ䡁䅍睊桁䍁䅑兔歁䑁䅉杍㙁䍁䅑睔歁䑁䅉杍䅁䙁䘰䅁畂䅁䅁睊扂䕁䄰兓時䕁䅍睢瑂䡁䅁兙畂䡁䅫睘䱂䝁䅕入呂䡁䅑兙あ䡁䅍睘㉂䑁䅅兌䑂䝁䄸䅣㕂䍁䄴䅥獂䡁䅍兢摂䕁䅉兙獂䝁䅅杢橂䝁䅕睘呂䝁䅧党求䡁䅑睊桁䍁䅑睑歁䑁䅑䅁㑂兂䅁䅩䅁䍁䅣睗呂䙁䅁睒時䕁䅍睢瑂䡁䅁兙畂䡁䅫睘䱂䝁䅕入呂䡁䅑兙あ䡁䅍睘㉂䑁䅉䅉硁䍁䄴䅥獂䡁䅍兢摂䕁䅍兙睂䝁䅫䅤桂䝁䅷睘呂䡁䅑杣ㅂ䝁䅍䅤ㅂ䡁䅉党時䍁䅁䅒求䡁䅑兙灂䝁䅷督杁䍁䅣光歁䕁䅕䅊硁䑁䅉䅁䭁睂䅁䅊䅁䕁䅫兕時䙁䅕杔呂䕁䅕睑噂䙁䅉兒䕂䙁䄸䅒䙂䕁䅉䅖䅁䑁䉙䅁䅂䅁䅁兓剂䙁䄸睑偂䕁䄰兔偂䕁䄴睘䙂䙁䅅兖䩂䙁䅑兗時䑁䅍兗卂䙁䄸兑佂䕁䄴睘䡂䙁䅉睔塂䙁䅑䅓䅁䡁䌰䅁㑂䅁䅁睊扂䕁䄰兓時䕁䅍睢瑂䡁䅁兙畂䡁䅫睘䱂䝁䅕入呂䡁䅑兙あ䡁䅍睘㉂䑁䅅兌䑂䝁䄸䅣㕂䍁䄴䅥獂䡁䅍兢摂䕁䅉兙獂䝁䅅杢橂䝁䅕睘呂䝁䅧党求䡁䅑睊桁䍁䅑兒歁䑁䅑杏歁䙁䅁䅊ぁ䅁䅁入䅕䙁䅷䅁扂䕁䅳党㕂䙁䅍䅤桂䡁䅑督時䡁䅑党穂䡁䅑杚灂䝁䅷党畁䡁䅧䅢穂䝁䄰兘䱂䝁䅕入時䙁䅍䅤桂䡁䅑督桁䍁䅑睑歁䑁䅙䅍㙁䍁䅑睑歁䑁䅙李䅁䩁䄸䅁祂䅁䅁睗乂䕁䅫睘䑂䝁䄸兢睂䝁䅅杢㕂䙁䄸睓求䡁䅫睕あ䝁䅅䅤穂䙁䄸杤硁䙁䄸杌㑂䝁䅷督瑂䙁䄰兓畂䝁䅍睢瑂䝁䅕睘呂䡁䅑兙あ䝁䅕兢求䝁䄴䅤桁䍁䅑兒歁䑁䅕杏歁䙁䅁䅊ㅁ䅁䅁䄱䅑䡁䄴䅁湁䙁䅳兔䩂䙁䄸睑療䝁䄰䅣桂䝁䄴入時䕁䅳党㕂䙁䅍䅤桂䡁䅑督時䡁䅙免瑁䕁䅍睢睂䡁䅫杌㑂䝁䅷督瑂䙁䄰睑桂䡁䅁兡あ䝁䅅䅢灂䡁䅯兙あ䝁䅫睢畂䍁䅣光歁䕁䅍䅊ㅁ䑁䅍杏歁䕁䅍䅊ㅁ䑁䅑䅁畁兂䅁䅌䅁䕁䅫兕時䕁䄸䅔時䕁䅍睔乂䕁䄰睘䉂䕁䅙䅖䙂䙁䅉睘䝂䕁䅫杖䙂䅁䅁睷䅅䝁䅯䅁扂䕁䄰兓時䕁䅍睢瑂䡁䅁兙畂䡁䅫睘䱂䝁䅕入呂䡁䅑兙あ䡁䅍睘㉂䑁䅅杌㑂䝁䅷督瑂䙁䄰村桂䝁䅷兙畂䝁䅍党時䙁䅍䅡求䝁䅕䅤桁䍁䅑兒歁䑁䅣杏歁䙁䅁䅊㍁䅁䅁睴䅕䡁䅧䅁湁䙁䅳兔䩂䙁䄸睑療䝁䄰䅣桂䝁䄴入時䕁䅳党㕂䙁䅍䅤桂䡁䅑督時䡁䅙免瑁䕁䅍睢睂䡁䅫杌㑂䝁䅷督瑂䙁䄰村桂䝁䅷兙畂䝁䅍党時䙁䅍䅡求䝁䅕䅤湁䍁䅅䅊䙂䍁䅑兎㙁䍁䅑䅕歁䑁䅕䅁㝂兂䅁杚䅁䍁䅣睗呂䙁䅁睒時䕁䅍睢瑂䡁䅁兙畂䡁䅫睘䱂䝁䅕入呂䡁䅑兙あ䡁䅍睘㉂䑁䅉䅉硁䍁䄴䅥獂䡁䅍兢摂䕁䅳党㕂䙁䄸睕あ䝁䅅䅤穂䍁䅣光歁䕁䅕䅊硁䑁䅁李䅁䵁䝁䅁敁䅁䅁兓剂䙁䄸䅒䑂䙁䅍睘呂䕁䅕睑噂䙁䅉兒䕂䅁䅁杮䅙䩁䅙䅁湁䙁䅳兔䩂䙁䄸睑療䝁䄰䅣桂䝁䄴入時䕁䅳党㕂䙁䅍䅤桂䡁䅑督時䡁䅙免瑁䕁䅍睢睂䡁䅫杌㑂䝁䅷督瑂䙁䄰睑桂䡁䅁兡あ䝁䅅䅢時䙁䅍䅤祂䡁䅕睙あ䡁䅕杣求䙁䄸睕ㅂ䝁䄰兢桂䡁䅉入湁䍁䅅䅊䑂䍁䅑免穁䑁䅯䅊䑂䍁䅑免ㅁ䑁䅁䅁䍃兂䅁杈䅁䕁䅍兤祂䡁䅉党畂䡁䅑䅉䑂䝁䄸兤睂䝁䄸杢䅁䩁䝉䅁䭂䅁䅁睑桂䡁䅍䅡杁䕁䅙杣療䝁䄰䅉偂䡁䅁党祂䝁䅅䅤灂䝁䄸杢穂䍁䅷䅉祁䍁䅁兗祂䍁䄴䅉䑂䕁䅅睒卂䍁䅁䅋汁䍁䅫䅁捂杁䅁杨䅁䍁䅣睗乂䕁䅫睘䑂䝁䄸兢睂䝁䅅杢㕂䙁䄸睓求䡁䅫睕あ䝁䅅䅤穂䙁䄸杤硁䍁䄰睑療䡁䅁入畁䡁䅧䅢穂䝁䄰兘䑂䝁䅅䅣灂䡁䅑兙獂䙁䄸睕あ䡁䅉兤橂䡁䅑兤祂䝁䅕睘呂䡁䅕兢瑂䝁䅅杣㕂䍁䅣光歁䕁䅍䅊ぁ䅁䅁䅧䅕䝁䅑䅁扂䙁䅍䅕䡂䙁䄸睑療䝁䄰䅣桂䝁䄴入時䕁䅳党㕂䙁䅍䅤桂䡁䅑督時䡁䅙免畁䡁䅧䅢穂䝁䄰兘䑂䝁䅅督潂䙁䄸杒獂䝁䄸睤桁䍁䅑兒歁䑁䅙杏歁䙁䅁䅊㉁䅁䅁儷䅕䡁䅯䅁湁䙁䅳睕兂䕁䅣睘䑂䝁䄸兢睂䝁䅅杢㕂䙁䄸睓求䡁䅫睕あ䝁䅅䅤穂䙁䄸杤祁䍁䅁免畁䡁䅧䅢穂䝁䄰兘䑂䝁䅅䅣灂䡁䅑兙獂䝁䅫来桂䡁䅑兡療䝁䄴睊桁䍁䅑兒歁䑁䅑睎㙁䍁䅑杓歁䑁䅑睎䅁佁䜴䅁䕂䅁䅁兒桂䡁䅉杢灂䝁䄴睚穂䍁䅁杚祂䝁䄸兢杁䕁䅍睢畂䡁䅑䅉偂䡁䅁督杁䕁䄰兙祂䝁䅣兡畂䍁䅁䅋汁䍁䅫䅁䭁杁䅁杖䅁䙁䅑睢あ䝁䅅䅢杁䕁䅍兙睂䝁䅫䅤桂䝁䅷䅉䵂䝁䄸督穂䍁䅁睑桂䡁䅉杣㕂䝁䅙睢祂䡁䅣兙祂䝁䅑䅉潁䙁䅉党睂䝁䄸杣あ䝁䅕䅚灁䅁䅁眷䅉䩁䅑䅁湁䙁䅳兔䩂䙁䄸睑療䝁䄰䅣桂䝁䄴入時䕁䅳党㕂䙁䅍䅤桂䡁䅑督時䡁䅙免瑁䕁䅍睢睂䡁䅫杌㑂䝁䅷督瑂䙁䄰睑桂䡁䅁兡あ䝁䅅䅢時䙁䅍䅤祂䡁䅕睙あ䡁䅕杣求䙁䄸睕ㅂ䝁䄰兢桂䡁䅉入湁䍁䅅䅊䕂䍁䅑杍㍁䑁䅯䅊䕂䍁䅑睎㑁䅁䅁杨䅕䍁䅁䅁呂䙁䅁睘䝂䕁䅫睕䑂䕁䅅䅔時䙁䅅睘䙂䙁䅍䅖䅁䱁䥫䅁元䅁䅁睊扂䕁䄰兓時䕁䅍睢瑂䡁䅁兙畂䡁䅫睘䱂䝁䅕入呂䡁䅑兙あ䡁䅍睘㉂䑁䅅兌䑂䝁䄸䅣㕂䍁䄴䅥獂䡁䅍兢摂䕁䅍兙睂䝁䅫䅤桂䝁䅷睘呂䡁䅑杣ㅂ䝁䅍䅤ㅂ䡁䅉党時䙁䅍兤瑂䝁䄰兙祂䡁䅫睊桁䍁䅑兒歁䑁䅑杏歁䕁䄸䅊ぁ䅁䅁內䅕䉁䅯䅁㡁䑁䄴䅍㕁䍁䄸免㍁䍁䄸杍睁䑁䅉䅍䅁䭁䙙䅁元䅁䅁睊扂䕁䄰兓時䕁䅍睢瑂䡁䅁兙畂䡁䅫睘䱂䝁䅕入呂䡁䅑兙あ䡁䅍睘㉂䑁䅅兌䑂䝁䄸䅣㕂䍁䄴䅥獂䡁䅍兢摂䕁䅍兙睂䝁䅫䅤桂䝁䅷睘呂䡁䅑杣ㅂ䝁䅍䅤ㅂ䡁䅉党時䙁䅍兤瑂䝁䄰兙祂䡁䅫睊桁䍁䅑兒歁䑁䅕杏歁䕁䄸䅊ㅁ䅁䅁睧䅕䩁䅁䅁湁䙁䅳兔䩂䙁䄸睑療䝁䄰䅣桂䝁䄴入時䕁䅳党㕂䙁䅍䅤桂䡁䅑督時䡁䅙免瑁䕁䅍睢睂䡁䅫杌㑂䝁䅷督瑂䙁䄰睑桂䡁䅁兡あ䝁䅅䅢時䙁䅍䅤祂䡁䅕睙あ䡁䅕杣求䙁䄸睕ㅂ䝁䄰兢桂䡁䅉入湁䍁䅅䅊䝂䍁䅑䅏㙁䍁䅑䅕歁䑁䅧䅁䙃兂䅁䅫䅁䍁䅣睗乂䕁䅫睘䑂䝁䄸兢睂䝁䅅杢㕂䙁䄸睓求䡁䅫睕あ䝁䅅䅤穂䙁䄸杤硁䍁䄰睑療䡁䅁入畁䡁䅧䅢穂䝁䄰兘䑂䝁䅅䅣灂䡁䅑兙獂䙁䄸睕あ䡁䅉兤橂䡁䅑兤祂䝁䅕睘呂䡁䅕兢瑂䝁䅅杣㕂䍁䅣光歁䕁䅙䅊㕁䑁䅯䅊兂䍁䅑兏䅁䥁䙣䅁䅂䅁䅁兓剂䙁䄸睑偂䕁䄰兔偂䕁䄴睘䙂䙁䅅兖䩂䙁䅑兗時䑁䅅兗卂䙁䄸兑佂䕁䄴睘䡂䙁䅉睔塂䙁䅑䅓䅁䍁䌸䅁獁䅁䅁兓剂䙁䄸睕卂䙁䄸睕噂䕁䅉睘䕂䕁䅕村啂䙁䄸兒䍂䕁䅫䅖䕂䕁䅅䅁呃允䅁杖䅁䙁䅳睕兂䕁䅣睘䑂䝁䄸兢睂䝁䅅杢㕂䙁䄸睓求䡁䅫睕あ䝁䅅䅤穂䙁䄸杤祁䍁䄴䅥獂䡁䅍兢摂䙁䅍䅡求
